Workbook

Sheet Summary
A1: Parts List v0.9 — USB-C DAC + balanced headphone amplifier
A2: Diego Yang · 26 Sep 2026 · tenth review round · companion to Design Specification v1.1 and Schematic Design Notes v1.0; release calculations in DAC_HPA_Calculation_Package_v1.1.zip (one verification command) · JLCPCB Standard PCBA, top side, 5 boards + owner-fitted parts · Parts List v0.8 is kept unchanged as history
A4: Stage readiness (26 Sep 2026)
A5: Stage | B5: Verdict | C5: Gate / condition
A6: Schematic capture | B6: GO | C6: Capture v1.0 uses the old J702 map (tip on pin 1, sleeve on pin 4, 'Mount' on 5/6). Recapture sheet 7 to the J702 map from the maker drawing (Notes sheet), and sheet 6 to Parts List v0.9 (the protection sheet)
A7: Provisional placement | B7: GO (100 × 80 mm) | C7: top side; zone fills Z4 52 %, Z7 59.0 % against the 60 % zone rule (59.6 % overall)
A8: Schematic freeze | B8: HOLD | C8: for G-1…G-4. J701 and J702 contact maps are documented from the maker drawings and confirmed on two samples at G-2 (including J701 pads 11/12 and the J702 break contacts); J101 at G-1.
A9: Routing | B9: HOLD | C9: no manufacturing data from the provisional connector assignments
A10: Fabrication/assembly order | B10: HOLD | C10: for the layout review and G-5/G-6, including JLCPCB's written confirmation of how the J101 shell stakes S1–S4 and the J702 pads 1/2 are soldered (or the owner fallback), and the 2416 film-capacitor reflow
A12: Board and parts (live from the lists)
A13: Item | B13: Value | C13: Details
A14: BOM lines | B14: =Checks!C11 -> 179 | C14: ="incl. "&COUNTIF('Parts list'!$M$4:$M$185,"Pads")&" copper-pad lines and "&COUNTIF('Parts list'!$M$4:$M$185,"No")&" DNF lines; plus 3 layout lines (test pads, mounting holes/fiducials, bare PCB)" -> incl. 3 copper-pad lines and 8 DNF lines; plus 3 layout lines (test pads, mounting holes/fiducials, bare PCB)
A15: Fitted component lines | B15: =Cost!B26 -> 168 | C15: ="placed by JLCPCB "&TEXT(Cost!B26-Cost!B27,"0")&"; owner-fitted "&TEXT(Cost!B27,"0")&" (K601–K604, J701, D102, R509)" -> placed by JLCPCB 164; owner-fitted 4 (K601–K604, J701, D102, R509)
A16: Fitted parts per board | B16: =Cost!B28 -> 462 | C16: ="placed by JLCPCB "&TEXT(Cost!B29,"0")&"; owner-fitted "&TEXT(Cost!B28-Cost!B29,"0") -> placed by JLCPCB 455; owner-fitted 7
A17: Unique part numbers (fitted) | B17: ='Parts list'!$AB$187 -> 115 | C17: ="JLCPCB-placed part types "&TEXT(Cost!B32,"0")&" (Basic "&TEXT(Cost!B33,"0")&", Extended or to confirm "&TEXT(Cost!B34,"0")&")" -> JLCPCB-placed part types 111 (Basic 34, Extended or to confirm 77)
A18: SMT joints per board | B18: ='Parts list'!$O$187 -> 1339 | C18: ="through-hole "&TEXT('Parts list'!$P$187,"0")&" (J101 shell stakes 4, J701 12 owner-fitted, J702 slot terminals 2); leadless (X-ray) parts "&TEXT(Cost!B35,"0") -> through-hole 18 (J101 shell stakes 4, J701 12 owner-fitted, J702 slot terminals 2); leadless (X-ray) parts 10
A19: Netlist pin rows | B19: =Checks!C27 -> 1445 | C19: ="component pins "&TEXT(Checks!C28,"#,##0")&" + 52 test pads; nets "&TEXT(Checks!C32,"0")&"; design check 0 issues" -> component pins 1,393 + 52 test pads; nets 247; design check 0 issues
A20: Value decodes from the part number (lines) | B20: ='Parts list'!$AC$187 -> 118 | C20: ="mismatches with the Value column: "&TEXT('Parts list'!$AG$187,"0")&"; parts cross-check: "&TEXT(Checks!C7,"0")&" lines, "&TEXT(Checks!C8,"0")&" mismatches" -> mismatches with the Value column: 0; parts cross-check: 80 lines, 0 mismatches
A21: Stress check, current rows | B21: ='Stress check'!B192 -> 181 | C21: ="OK "&'Stress check'!B187&", THIN "&'Stress check'!B188&", AVAIL "&'Stress check'!B189&", DATA-GAP "&'Stress check'!B190&", FAIL "&'Stress check'!B191 -> OK 146, THIN 17, AVAIL 14, DATA-GAP 4, FAIL 0
A22: Evidence register rows | B22: ='Evidence register'!C130 -> 120 | C22: ="G "&'Evidence register'!C126&", E "&'Evidence register'!C127&", Q "&'Evidence register'!C128&" (open; none has passed, no board exists), retired or process rows "&'Evidence register'!C129 -> G 13, E 80, Q 22 (open; none has passed, no board exists), retired or process rows 5
A23: Designators added against v0.8 | B23: ='Changes vs v0.8'!C30 -> 65 | C23: ="removed "&'Changes vs v0.8'!C31&", changed "&'Changes vs v0.8'!C32&" ("&'Changes vs v0.8'!C34&" change lines)" -> removed 22, changed 4 (24 change lines)
A24: Buy-now part numbers | B24: ='Purchasing list'!$T$116 -> 18 | C24: ="pre-order "&COUNTIF('Purchasing list'!$T$4:$T$114,"Pre-order")&"; new buy-now line TLV3402IDGKR; TLV1704 only if ≥ 31 are in LCSC stock at order time (Ordering plan, section A)" -> pre-order 8; new buy-now line TLV3402IDGKR; TLV1704 only if ≥ 31 are in LCSC stock at order time (Ordering plan, section A)
A25: Owner LCSC order: order-rule flags | B25: ='Purchasing list'!$Q$152 -> 0 | C25: ="every owner LCSC quantity meets the LCSC minimum and multiple (Purchasing list column Q)" -> every owner LCSC quantity meets the LCSC minimum and multiple (Purchasing list column Q)
A28: Cost for information — 5 assembled boards (no cost limit; an estimate until the supplier orders and the JLCPCB quote exist)
A29: Item | B29: US$ | C29: NTD | D29: Details
A30: JLCPCB order (Standard PCBA) | B30: =Cost!E95 -> 787.82652 | C30: =Cost!F95 -> 24997.735 | D30: ="parts "&TEXT(Cost!E90,"0.00")&", fees "&TEXT(Cost!E91,"0.00")&", global sourcing "&TEXT(Cost!E92,"0.00")&", PCB "&TEXT(Cost!E93,"0.00")&", shipping "&TEXT(Cost!E94,"0.00") -> parts 397.33, fees 312.97, global sourcing 29.52, PCB 23.00, shipping 25.00
A31: Owner purchase (DigiKey + LCSC) | B31: =Cost!E96 -> 161.6 | C31: =Cost!F96 -> 5127.568 | D31: ="DigiKey "&TEXT(Cost!E82,"0.00")&" + LCSC "&TEXT(Cost!E86,"0.00")&" (owner-fitted parts and gate samples, shipping and tax)" -> DigiKey 105.63 + LCSC 55.97 (owner-fitted parts and gate samples, shipping and tax)
A32: Total per 5-board order | B32: =Cost!E97 -> 949.42652 | C32: =Cost!F97 -> 30125.303 | D32: ="at "&TEXT(Cost!B5,"0.00")&" NTD per US$; an estimate until the supplier orders and the JLCPCB quote exist" -> at 31.73 NTD per US$; an estimate until the supplier orders and the JLCPCB quote exist
A33: Equivalent per assembled board | B33: =Cost!E98 -> 189.8853 | C33: =Cost!F98 -> 6025.0607 | D33: ="JLCPCB "&TEXT(Cost!E99,"0.00")&" + owner "&TEXT(Cost!E100,"0.00") -> JLCPCB 157.57 + owner 32.32
A34: (information) Total with Economic PCBA | B34: =Cost!E101 -> 934.49652 | C34: =Cost!F101 -> 29651.575 | D34: Economic is not chosen (CPLD pitch limit, connector reflow)
A35: Change vs the v1.0 set (Parts List v0.8) | B35: =Cost!E104 -> 93.28652 | D35: ="v1.0 set: US$ "&TEXT(Cost!B24,"#,##0.00")&"; earlier record: the v1.0 set was +"&TEXT(Cost!E105,"0.00")&" against the v0.9 set (US$ "&TEXT(Cost!D105,"#,##0.00")&")" -> v1.0 set: US$ 856.14; earlier record: the v1.0 set was +97.32 against the v0.9 set (US$ 758.82)
A36: Earlier round's comparison: saving vs US$ 1,072.87 | B36: =Cost!E102 -> 123.44348 | C36: =Cost!F102 -> 3916.8616 | D36: =TEXT(Cost!E102/Cost!B21,"0.0%")&" of US$ "&TEXT(Cost!B21,"#,##0.00")&"; "&TEXT(Cost!E103,"0.00")&" per board" -> 11.5% of US$ 1,072.87; 24.69 per board
A37: Line items rounded to the cent; totals computed from unrounded values. Prices, stock and JLCPCB classes are those of the web-page copies read on 26 Sep 2026.
A38: Checks
A39: All checks | B39: =Checks!F77 -> 2 to check | D39: =Checks!G77 -> 63 of 65 checks OK
A40: Cost reconciliation with the cost report | B40: =Cost!F176 -> ALL OK | D40: =Cost!G176 -> 51 of 51 figures match the cost report
A41: Open item: no JLCPCB-placed part at a process limit | B41: OPEN | D41: until JLCPCB's written answer on how the J101 shell stakes S1–S4 and the J702 slot pads 1/2 are soldered (G-6); not counted as a pass
A42: Open point for the owner: slot-pad copper ring of J701 / J702 (decide before the G-3 overlay) | B42: OPEN | D42: J702 0.20 mm (0.60 mm slots in 1.00 mm pads), J701 0.25 mm (0.50 mm slots in 1.00 mm pads; 0.20 mm at the +0.10 mm slot tolerance) — above JLCPCB's 0.18 mm minimum, at or below its 0.25 mm recommendation, below this design's 0.30 mm rule; the pads stay as the maker drawings give them until the owner decides (Notes sheet); not counted as a pass
A43: What changed in v0.9 (details on the Notes sheet)
A44: 1 | B44: History-robust hardware protection: per-leg over-range stages U611/U612 (TLV1704) and low-level persistence stages U613–U620 (TLV3402IDGKR) replace the per-leg RC window stage; the pair persistence detector and the re-arm latch are unchanged. From any reachable pre-fault state (rail-bounded, E): DC ±2 V on a leg removed ≤ 27.2 ms, ±1 V ≤ 102.7 ms; rail-stuck leg 26.48 / 13.24 mJ at 16 / 32 Ω on the 4.049 V R501-fallback rail.
...

Sheet Parts list
A1: Parts list — every BOM line, grouped by block
A2: One part per line, grouped by block. Fit: Yes = placed by JLCPCB; Owner = owner-fitted (bought by the owner, hand-soldered after delivery, not in the JLCPCB order); No = DNF; Pads = copper only; No part = layout items; Board = bare PCB. Unit prices in US$ (LCSC/JLCPCB sample tier; distributor prices for global-sourced and owner-bought parts). No spare-parts stock: JLCPCB lines buy the exact 5-board quantity plus attrition (Cost sheet inputs); a pre-ordered LCSC line buys at least its LCSC order quantity. Helper columns Z–AG feed the Checks sheet (AC–AG: the value decoded from the part number against the Value column).
A3: Block | B3: Designators | C3: Qty per board | D3: Description | E3: Value | F3: Package | G3: Rating / tolerance | H3: Part number (MPN) | I3: LCSC no. | J3: JLCPCB class | K3: Source | L3: Stock and sourcing | M3: Fit (Yes = JLCPCB, Owner = owner-fitted) | N3: Leadless (X-ray) | O3: SMT joints per part | P3: Through-hole joints per part | Q3: Unit price US$ | R3: Qty for 5 boards | S3: Line cost US$, 5 boards (exact) | T3: Attrition rule | U3: LCSC order quantity (input) | V3: Qty to buy (5 boards + attrition) | W3: Line cost US$ (qty to buy) | X3: Datasheet | Y3: Notes | Z3: Designator list (helper) | AA3: Designators on line (helper) | AB3: New MPN (helper) | AC3: Value-code family (helper) | AD3: Value code (helper) | AE3: Value from part number, Ω or F (helper) | AF3: Value as entered, Ω or F (helper) | AG3: Value check (helper)
A4: 1 USB-C input, OVP and sensing | B4: C101 | C4: 1 | D4: DNF: shell-to-GND RF capacitor (only if R107 becomes a bleed resistor) | E4: 4.7 nF | F4: 0402 | G4: 50 V X7R | H4: FH 0402B472K500NT | I4: C1538 | J4: Basic | K4: — (DNF) | L4: As in Parts List v0.6 | M4: No | O4: 2 | P4: 0 | Q4: 0.002 | R4: =IF(OR($M4="Yes",$M4="Owner"),$C4*Cost!$B$6,0) -> 0 | S4: =$R4*$Q4 -> 0 | T4: — | V4: =IF($M4="Owner",$R4,IF($M4<>"Yes",0,MAX(IF(LEFT($T4,7)="Passive",$R4+MAX(Cost!$B$8,ROUNDUP(Cost!$B$7*$R4,0)),$R4+Cost!$B$9),N($U4)))) -> 0 | W4: =$V4*$Q4 -> 0 | X4: https://www.lcsc.com/product-detail/C1538.html | Y4: Unchanged | Z4: ,C101, | AA4: =IF($Z4="",0,LEN($Z4)-LEN(SUBSTITUTE($Z4,",",""))-1) -> 1 | AB4: =IF(OR($M4="Yes",$M4="Owner"),IF(COUNTIFS($H$4:$H4,$H4,$M$4:$M4,"Yes")+COUNTIFS($H$4:$H4,$H4,$M$4:$M4,"Owner")=1,1,0),0) -> 0 | AC4: FH | AD4: =IF(ISNUMBER(FIND("CG",$H4)),MID($H4,FIND("CG",$H4)+2,3),MID($H4,FIND(" 0",$H4)+6,3)) -> 472 | AE4: =IF(ISNUMBER(FIND("R",$AD4)),SUBSTITUTE($AD4,"R",".")*1,LEFT($AD4,2)*10^RIGHT($AD4,1))*10^-12 -> 4.7e-09 | AF4: {=LEFT($E4,FIND(" ",$E4)-1)*IFERROR(INDEX({1000,1000000,0.000000000001,0.000000001,0.000001},MATCH(MID($E4,FIND(" ",$E4)+1,1),{"k","M","p","n","µ"},0)),1)} -> 4.7e-09 | AG4: =IF(AND(RIGHT($E4,1)="F",ABS($AF4-$AE4)<=Checks!$C$6*$AE4),"OK","CHECK") -> OK
A5: 1 USB-C input, OVP and sensing | B5: C102 | C5: 1 | D5: VBUS input capacitor at J101 / U102 IN, also the U502 input capacitor (attach region A ≤ 29.6 µC with the 3V3M charge; hard-short kick with D102: U102 IN ≤ 17.08 V) | E5: 2.2 µF | F5: 0805 | G5: 25 V X5R ±10 % | H5: Samsung CL21A225KAFNNNE | I5: C87994 | J5: Extended | K5: JLCPCB library | L5: LCSC C87994; DigiKey 80,862 (23 Sep 2026) — confirm the stock in the JLCPCB BOM tool at order | M5: Yes | O5: 2 | P5: 0 | Q5: 0.02 | R5: =IF(OR($M5="Yes",$M5="Owner"),$C5*Cost!$B$6,0) -> 5 | S5: =$R5*$Q5 -> 0.1 | T5: Passive: +5 %, min +2 | V5: =IF($M5="Owner",$R5,IF($M5<>"Yes",0,MAX(IF(LEFT($T5,7)="Passive",$R5+MAX(Cost!$B$8,ROUNDUP(Cost!$B$7*$R5,0)),$R5+Cost!$B$9),N($U5)))) -> 7 | W5: =$V5*$Q5 -> 0.14 | Y5: Changed 4.7 µF → 2.2 µF (suspend power cut: the 3V3M capacitors now charge at plug-in through U502) | Z5: ,C102, | AA5: =IF($Z5="",0,LEN($Z5)-LEN(SUBSTITUTE($Z5,",",""))-1) -> 1 | AB5: =IF(OR($M5="Yes",$M5="Owner"),IF(COUNTIFS($H$4:$H5,$H5,$M$4:$M5,"Yes")+COUNTIFS($H$4:$H5,$H5,$M$4:$M5,"Owner")=1,1,0),0) -> 1 | AC5: Samsung CL | AD5: =MID($H5,FIND("CL",$H5)+5,3) -> 225 | AE5: =IF(ISNUMBER(FIND("R",$AD5)),SUBSTITUTE($AD5,"R",".")*1,LEFT($AD5,2)*10^RIGHT($AD5,1))*10^-12 -> 2.2e-06 | AF5: {=LEFT($E5,FIND(" ",$E5)-1)*IFERROR(INDEX({1000,1000000,0.000000000001,0.000000001,0.000001},MATCH(MID($E5,FIND(" ",$E5)+1,1),{"k","M","p","n","µ"},0)),1)} -> 2.2e-06 | AG5: =IF(AND(RIGHT($E5,1)="F",ABS($AF5-$AE5)<=Checks!$C$6*$AE5),"OK","CHECK") -> OK
A6: 1 USB-C input, OVP and sensing | B6: C103 | C6: 1 | D6: VBUS_SENSE ADC input capacitor at PA1 (tau 3.6 µs with R105/R106; brown-out watchdog acts before the MCU reset) | E6: 100 pF | F6: 0402 | G6: 50 V C0G ±5 % | H6: Samsung CL05C101JB5NNNC | I6: C1546 | J6: Basic | K6: JLCPCB library | L6: JLCPCB Basic | M6: Yes | O6: 2 | P6: 0 | Q6: 0.002 | R6: =IF(OR($M6="Yes",$M6="Owner"),$C6*Cost!$B$6,0) -> 5 | S6: =$R6*$Q6 -> 0.01 | T6: Passive: +5 %, min +2 | V6: =IF($M6="Owner",$R6,IF($M6<>"Yes",0,MAX(IF(LEFT($T6,7)="Passive",$R6+MAX(Cost!$B$8,ROUNDUP(Cost!$B$7*$R6,0)),$R6+Cost!$B$9),N($U6)))) -> 7 | W6: =$V6*$Q6 -> 0.014 | X6: https://www.lcsc.com/product-detail/C1546.html | Y6: Changed from 10 nF X7R to 100 pF C0G (fast brown-out detection) | Z6: ,C103, | AA6: =IF($Z6="",0,LEN($Z6)-LEN(SUBSTITUTE($Z6,",",""))-1) -> 1 | AB6: =IF(OR($M6="Yes",$M6="Owner"),IF(COUNTIFS($H$4:$H6,$H6,$M$4:$M6,"Yes")+COUNTIFS($H$4:$H6,$H6,$M$4:$M6,"Owner")=1,1,0),0) -> 1 | AC6: Samsung CL | AD6: =MID($H6,FIND("CL",$H6)+5,3) -> 101 | AE6: =IF(ISNUMBER(FIND("R",$AD6)),SUBSTITUTE($AD6,"R",".")*1,LEFT($AD6,2)*10^RIGHT($AD6,1))*10^-12 -> 1e-10 | AF6: {=LEFT($E6,FIND(" ",$E6)-1)*IFERROR(INDEX({1000,1000000,0.000000000001,0.000000001,0.000001},MATCH(MID($E6,FIND(" ",$E6)+1,1),{"k","M","p","n","µ"},0)),1)} -> 1e-10 | AG6: =IF(AND(RIGHT($E6,1)="F",ABS($AF6-$AE6)<=Checks!$C$6*$AE6),"OK","CHECK") -> OK
A7: 1 USB-C input, OVP and sensing | B7: C104 | C7: 1 | D7: U102 EN delay capacitor (EN to GND, with R109 470 k): U102 switches on 3.31–55.3 ms after plug-in at every corner | E7: 100 nF | F7: 0402 | G7: 16 V X7R ±10 % | H7: Samsung CL05B104KO5NNNC | I7: C1525 | J7: Basic | K7: JLCPCB library | L7: JLCPCB Basic | M7: Yes | O7: 2 | P7: 0 | Q7: 0.0045 | R7: =IF(OR($M7="Yes",$M7="Owner"),$C7*Cost!$B$6,0) -> 5 | S7: =$R7*$Q7 -> 0.0225 | T7: Passive: +5 %, min +2 | V7: =IF($M7="Owner",$R7,IF($M7<>"Yes",0,MAX(IF(LEFT($T7,7)="Passive",$R7+MAX(Cost!$B$8,ROUNDUP(Cost!$B$7*$R7,0)),$R7+Cost!$B$9),N($U7)))) -> 7 | W7: =$V7*$Q7 -> 0.0315 | X7: https://www.lcsc.com/product-detail/C1525.html | Y7: New; the two plug-in charge regions stay ≥ 1.96 ms apart | Z7: ,C104, | AA7: =IF($Z7="",0,LEN($Z7)-LEN(SUBSTITUTE($Z7,",",""))-1) -> 1 | AB7: =IF(OR($M7="Yes",$M7="Owner"),IF(COUNTIFS($H$4:$H7,$H7,$M$4:$M7,"Yes")+COUNTIFS($H$4:$H7,$H7,$M$4:$M7,"Owner")=1,1,0),0) -> 1 | AC7: Samsung CL | AD7: =MID($H7,FIND("CL",$H7)+5,3) -> 104 | AE7: =IF(ISNUMBER(FIND("R",$AD7)),SUBSTITUTE($AD7,"R",".")*1,LEFT($AD7,2)*10^RIGHT($AD7,1))*10^-12 -> 1e-07 | AF7: {=LEFT($E7,FIND(" ",$E7)-1)*IFERROR(INDEX({1000,1000000,0.000000000001,0.000000001,0.000001},MATCH(MID($E7,FIND(" ",$E7)+1,1),{"k","M","p","n","µ"},0)),1)} -> 1e-07 | AG7: =IF(AND(RIGHT($E7,1)="F",ABS($AF7-$AE7)<=Checks!$C$6*$AE7),"OK","CHECK") -> OK
A8: 1 USB-C input, OVP and sensing | B8: D102 | C8: 1 | D8: VBUS TVS at J101 (VBUS-GND, unidirectional, cathode to VBUS): U102 IN ≤ 17.08 V at a 5V_SYS hard short with no tIOS credit (20 V absolute maximum); VRWM 12 V so a mis-set 9 V source is below stand-off | E8: 12 V | F8: DO-214AB (SMC) | G8: VRWM 12 V, VBR 13.3-14.7 V, VC 19.9 V at 150.8 A, IR ≤ 2 µA at 12 V (25 °C), 3000 W | H8: Littelfuse SMDJ12A | I8: — | J8: — | K8: Owner purchase (DigiKey) | L8: Owner purchase (DigiKey): 5,498 in stock (Sep 2026), US$ 1.01 at 10+; LCSC SMDJ12A (MDD C2994091, TSC C3717799) out of stock; LGE C5806873 not adopted (IR/VBR maximum not verifiable) | M8: Owner | O8: 2 | P8: 0 | Q8: 1.01 | R8: =IF(OR($M8="Yes",$M8="Owner"),$C8*Cost!$B$6,0) -> 5 | S8: =$R8*$Q8 -> 5.05 | T8: Owner purchase: 5 × qty | V8: =IF($M8="Owner",$R8,IF($M8<>"Yes",0,MAX(IF(LEFT($T8,7)="Passive",$R8+MAX(Cost!$B$8,ROUNDUP(Cost!$B$7*$R8,0)),$R8+Cost!$B$9),N($U8)))) -> 5 | W8: =$V8*$Q8 -> 5.05 | X8: https://www.littelfuse.com/products/overvoltage-protection/tvs-diodes/surface-mount/smdj/smdj12a | Y8: Owner-fitted: hand-soldered after delivery, not placed by JLCPCB; fitted first, before the first USB plug-in; SMC lands with toes +0.3 mm, ≥ 1.5 mm iron clearance, ≤ 5 mm from J101; polarity gate G-4 (band = cathode = VBUS) | Z8: ,D102, | AA8: =IF($Z8="",0,LEN($Z8)-LEN(SUBSTITUTE($Z8,",",""))-1) -> 1 | AB8: =IF(OR($M8="Yes",$M8="Owner"),IF(COUNTIFS($H$4:$H8,$H8,$M$4:$M8,"Yes")+COUNTIFS($H$4:$H8,$H8,$M$4:$M8,"Owner")=1,1,0),0) -> 1
A9: 1 USB-C input, OVP and sensing | B9: J101 | C9: 1 | D9: USB-C receptacle, USB 2.0: 16 contacts on the 12 composite GCT solder lands (shared A1/B12, A4/B9, B4/A9, B1/A12; single A5, A6, A7, A8, B5, B6, B7, B8) plus the plated shell stakes S1–S4; the provisional footprint uses the 16 JLCPCB pad IDs (each shared land is two touching pads on one net), plus two Ø0.65 mm non-plated locating holes; pin-in-paste on S1–S4 only after JLCPCB confirms the process and the aperture geometry (G-6); fallback: the owner hand-solders S1–S4 from the bottom side before the first plug-in (the stakes carry the shell and the mechanical retention); shell to GND via R107 | E9: — | F9: SMD horizontal top mount, 0.95 mm shell stakes | G9: 48 V DC (GCT page; drawing 20 V), VBUS 5 A, GND 6.25 A, others 0.25 A, 40 mΩ max; solder peak 255 °C (-0/+5) max 5 s | H9: GCT USB4105-GF-A | I9: C3020560 | J9: Extended | K9: Global sourcing | L9: LCSC out of stock (14 Sep 2026); DigiKey 127,933 (24 Sep 2026) → JLCPCB global sourcing; JLCPCB lists it as Economic and Standard, assembly difficulty high | M9: Yes | O9: 12 | P9: 4 | Q9: 1.09 | R9: =IF(OR($M9="Yes",$M9="Owner"),$C9*Cost!$B$6,0) -> 5 | S9: =$R9*$Q9 -> 5.45 | T9: Other: +1 | V9: =IF($M9="Owner",$R9,IF($M9<>"Yes",0,MAX(IF(LEFT($T9,7)="Passive",$R9+MAX(Cost!$B$8,ROUNDUP(Cost!$B$7*$R9,0)),$R9+Cost!$B$9),N($U9)))) -> 6 | W9: =$V9*$Q9 -> 6.54 | X9: https://gct.co/connector/usb4105 (drawing text: https://www.mouser.com/datasheet/2/837/USB4105-1948910.pdf) | Y9: Changed from the SHOU HAN receptacle; pads named by contact per the GCT drawing; Standard PCBA reflow 240 °C (JLCPCB to confirm the dwell, order remark); provisional footprint J101_USB4105-GF-A_12lands_4stakes (label ↔ JLCPCB pad-ID mapping on the Notes sheet); gates G-1 continuity (2 samples) and G-3 1:1 overlay; the S1–S4 soldering process is a G-6 order-release item | Z9: ,J101, | AA9: =IF($Z9="",0,LEN($Z9)-LEN(SUBSTITUTE($Z9,",",""))-1) -> 1 | AB9: =IF(OR($M9="Yes",$M9="Owner"),IF(COUNTIFS($H$4:$H9,$H9,$M$4:$M9,"Yes")+COUNTIFS($H$4:$H9,$H9,$M$4:$M9,"Owner")=1,1,0),0) -> 1
A10: 1 USB-C input, OVP and sensing | B10: R101, R102 | C10: 2 | D10: CC1/CC2 Rd pull-down (USB-C sink) | E10: 5.1 kΩ | F10: 0402 | G10: 1 % | H10: UNI-ROYAL 0402WGF5101TCE | I10: C25905 | J10: Basic | K10: JLCPCB library | L10: As in Parts List v0.6 | M10: Yes | O10: 2 | P10: 0 | Q10: 0.002 | R10: =IF(OR($M10="Yes",$M10="Owner"),$C10*Cost!$B$6,0) -> 10 | S10: =$R10*$Q10 -> 0.02 | T10: Passive: +5 %, min +2 | V10: =IF($M10="Owner",$R10,IF($M10<>"Yes",0,MAX(IF(LEFT($T10,7)="Passive",$R10+MAX(Cost!$B$8,ROUNDUP(Cost!$B$7*$R10,0)),$R10+Cost!$B$9),N($U10)))) -> 12 | W10: =$V10*$Q10 -> 0.024 | X10: https://www.lcsc.com/product-detail/C25905.html | Y10: Unchanged | Z10: ,R101,R102, | AA10: =IF($Z10="",0,LEN($Z10)-LEN(SUBSTITUTE($Z10,",",""))-1) -> 2 | AB10: =IF(OR($M10="Yes",$M10="Owner"),IF(COUNTIFS($H$4:$H10,$H10,$M$4:$M10,"Yes")+COUNTIFS($H$4:$H10,$H10,$M$4:$M10,"Owner")=1,1,0),0) -> 1 | AC10: UNI-ROYAL | AD10: =MID($H10,18,4) -> 5101 | AE10: =LEFT($AD10,3)*IF(ISNUMBER(--RIGHT($AD10,1)),10^RIGHT($AD10,1),10^(0-FIND(RIGHT($AD10,1),"JKLM"))) -> 5100 | AF10: {=LEFT($E10,FIND(" ",$E10)-1)*IFERROR(INDEX({1000,1000000,0.000000000001,0.000000001,0.000001},MATCH(MID($E10,FIND(" ",$E10)+1,1),{"k","M","p","n","µ"},0)),1)} -> 5100 | AG10: =IF(AND(RIGHT($E10,1)="Ω",ABS($AF10-$AE10)<=Checks!$C$6*$AE10),"OK","CHECK") -> OK
A11: 1 USB-C input, OVP and sensing | B11: R103, R104 | C11: 2 | D11: CC1/CC2 series resistor to MCU ADC (CC1_ADC, CC2_ADC) | E11: 10 kΩ | F11: 0402 | G11: 1 % | H11: UNI-ROYAL 0402WGF1002TCE | I11: C25744 | J11: Basic | K11: JLCPCB library | L11: As in Parts List v0.6 | M11: Yes | O11: 2 | P11: 0 | Q11: 0.002 | R11: =IF(OR($M11="Yes",$M11="Owner"),$C11*Cost!$B$6,0) -> 10 | S11: =$R11*$Q11 -> 0.02 | T11: Passive: +5 %, min +2 | V11: =IF($M11="Owner",$R11,IF($M11<>"Yes",0,MAX(IF(LEFT($T11,7)="Passive",$R11+MAX(Cost!$B$8,ROUNDUP(Cost!$B$7*$R11,0)),$R11+Cost!$B$9),N($U11)))) -> 12 | W11: =$V11*$Q11 -> 0.024 | X11: https://www.lcsc.com/product-detail/C25744.html | Y11: Unchanged | Z11: ,R103,R104, | AA11: =IF($Z11="",0,LEN($Z11)-LEN(SUBSTITUTE($Z11,",",""))-1) -> 2 | AB11: =IF(OR($M11="Yes",$M11="Owner"),IF(COUNTIFS($H$4:$H11,$H11,$M$4:$M11,"Yes")+COUNTIFS($H$4:$H11,$H11,$M$4:$M11,"Owner")=1,1,0),0) -> 1 | AC11: UNI-ROYAL | AD11: =MID($H11,18,4) -> 1002 | AE11: =LEFT($AD11,3)*IF(ISNUMBER(--RIGHT($AD11,1)),10^RIGHT($AD11,1),10^(0-FIND(RIGHT($AD11,1),"JKLM"))) -> 10000 | AF11: {=LEFT($E11,FIND(" ",$E11)-1)*IFERROR(INDEX({1000,1000000,0.000000000001,0.000000001,0.000001},MATCH(MID($E11,FIND(" ",$E11)+1,1),{"k","M","p","n","µ"},0)),1)} -> 10000 | AG11: =IF(AND(RIGHT($E11,1)="Ω",ABS($AF11-$AE11)<=Checks!$C$6*$AE11),"OK","CHECK") -> OK
A12: 1 USB-C input, OVP and sensing | B12: R105 | C12: 1 | D12: VBUS_SENSE divider top, from 5V_SYS | E12: 100 kΩ | F12: 0402 | G12: 1 % | H12: UNI-ROYAL 0402WGF1003TCE | I12: C25741 | J12: Basic | K12: JLCPCB library | L12: As in Parts List v0.6 | M12: Yes | O12: 2 | P12: 0 | Q12: 0.0033 | R12: =IF(OR($M12="Yes",$M12="Owner"),$C12*Cost!$B$6,0) -> 5 | S12: =$R12*$Q12 -> 0.0165 | T12: Passive: +5 %, min +2 | V12: =IF($M12="Owner",$R12,IF($M12<>"Yes",0,MAX(IF(LEFT($T12,7)="Passive",$R12+MAX(Cost!$B$8,ROUNDUP(Cost!$B$7*$R12,0)),$R12+Cost!$B$9),N($U12)))) -> 7 | W12: =$V12*$Q12 -> 0.0231 | X12: https://www.lcsc.com/product-detail/C25741.html | Y12: Now on 5V_SYS (after the OVP) | Z12: ,R105, | AA12: =IF($Z12="",0,LEN($Z12)-LEN(SUBSTITUTE($Z12,",",""))-1) -> 1 | AB12: =IF(OR($M12="Yes",$M12="Owner"),IF(COUNTIFS($H$4:$H12,$H12,$M$4:$M12,"Yes")+COUNTIFS($H$4:$H12,$H12,$M$4:$M12,"Owner")=1,1,0),0) -> 1 | AC12: UNI-ROYAL | AD12: =MID($H12,18,4) -> 1003 | AE12: =LEFT($AD12,3)*IF(ISNUMBER(--RIGHT($AD12,1)),10^RIGHT($AD12,1),10^(0-FIND(RIGHT($AD12,1),"JKLM"))) -> 100000 | AF12: {=LEFT($E12,FIND(" ",$E12)-1)*IFERROR(INDEX({1000,1000000,0.000000000001,0.000000001,0.000001},MATCH(MID($E12,FIND(" ",$E12)+1,1),{"k","M","p","n","µ"},0)),1)} -> 100000 | AG12: =IF(AND(RIGHT($E12,1)="Ω",ABS($AF12-$AE12)<=Checks!$C$6*$AE12),"OK","CHECK") -> OK
A13: 1 USB-C input, OVP and sensing | B13: R106 | C13: 1 | D13: VBUS_SENSE divider bottom (k = 0.3197; 5.55 V → 1.77 V) | E13: 47 kΩ | F13: 0402 | G13: 1 % | H13: UNI-ROYAL 0402WGF4702TCE | I13: C25792 | J13: Basic | K13: JLCPCB library | L13: As in Parts List v0.6 | M13: Yes | O13: 2 | P13: 0 | Q13: 0.002 | R13: =IF(OR($M13="Yes",$M13="Owner"),$C13*Cost!$B$6,0) -> 5 | S13: =$R13*$Q13 -> 0.01 | T13: Passive: +5 %, min +2 | V13: =IF($M13="Owner",$R13,IF($M13<>"Yes",0,MAX(IF(LEFT($T13,7)="Passive",$R13+MAX(Cost!$B$8,ROUNDUP(Cost!$B$7*$R13,0)),$R13+Cost!$B$9),N($U13)))) -> 7 | W13: =$V13*$Q13 -> 0.014 | X13: https://www.lcsc.com/product-detail/C25792.html | Y13: Unchanged value | Z13: ,R106, | AA13: =IF($Z13="",0,LEN($Z13)-LEN(SUBSTITUTE($Z13,",",""))-1) -> 1 | AB13: =IF(OR($M13="Yes",$M13="Owner"),IF(COUNTIFS($H$4:$H13,$H13,$M$4:$M13,"Yes")+COUNTIFS($H$4:$H13,$H13,$M$4:$M13,"Owner")=1,1,0),0) -> 1 | AC13: UNI-ROYAL | AD13: =MID($H13,18,4) -> 4702 | AE13: =LEFT($AD13,3)*IF(ISNUMBER(--RIGHT($AD13,1)),10^RIGHT($AD13,1),10^(0-FIND(RIGHT($AD13,1),"JKLM"))) -> 47000 | AF13: {=LEFT($E13,FIND(" ",$E13)-1)*IFERROR(INDEX({1000,1000000,0.000000000001,0.000000001,0.000001},MATCH(MID($E13,FIND(" ",$E13)+1,1),{"k","M","p","n","µ"},0)),1)} -> 47000 | AG13: =IF(AND(RIGHT($E13,1)="Ω",ABS($AF13-$AE13)<=Checks!$C$6*$AE13),"OK","CHECK") -> OK
A14: 1 USB-C input, OVP and sensing | B14: R107 | C14: 1 | D14: USB-C shell to GND (0 Ω) | E14: 0 Ω | F14: 0402 | G14: jumper | H14: UNI-ROYAL 0402WGF0000TCE | I14: C17168 | J14: Basic | K14: JLCPCB library | L14: As in Parts List v0.6 | M14: Yes | O14: 2 | P14: 0 | Q14: 0.002 | R14: =IF(OR($M14="Yes",$M14="Owner"),$C14*Cost!$B$6,0) -> 5 | S14: =$R14*$Q14 -> 0.01 | T14: Passive: +5 %, min +2 | V14: =IF($M14="Owner",$R14,IF($M14<>"Yes",0,MAX(IF(LEFT($T14,7)="Passive",$R14+MAX(Cost!$B$8,ROUNDUP(Cost!$B$7*$R14,0)),$R14+Cost!$B$9),N($U14)))) -> 7 | W14: =$V14*$Q14 -> 0.014 | X14: https://www.lcsc.com/product-detail/C17168.html | Y14: Unchanged | Z14: ,R107, | AA14: =IF($Z14="",0,LEN($Z14)-LEN(SUBSTITUTE($Z14,",",""))-1) -> 1 | AB14: =IF(OR($M14="Yes",$M14="Owner"),IF(COUNTIFS($H$4:$H14,$H14,$M$4:$M14,"Yes")+COUNTIFS($H$4:$H14,$H14,$M$4:$M14,"Owner")=1,1,0),0) -> 1 | AC14: UNI-ROYAL | AD14: =MID($H14,18,4) -> 0000 | AE14: =LEFT($AD14,3)*IF(ISNUMBER(--RIGHT($AD14,1)),10^RIGHT($AD14,1),10^(0-FIND(RIGHT($AD14,1),"JKLM"))) -> 0 | AF14: {=LEFT($E14,FIND(" ",$E14)-1)*IFERROR(INDEX({1000,1000000,0.000000000001,0.000000001,0.000001},MATCH(MID($E14,FIND(" ",$E14)+1,1),{"k","M","p","n","µ"},0)),1)} -> 0 | AG14: =IF(AND(RIGHT($E14,1)="Ω",ABS($AF14-$AE14)<=Checks!$C$6*$AE14),"OK","CHECK") -> OK
A15: 1 USB-C input, OVP and sensing | B15: R108 | C15: 1 | D15: U102 current-limit resistor (IOS 870/970/1077 mA ≥ the 760.77 mA of state S4: +109 mA to the minimum; 765.27 mA with the NDK X201 second source) | E15: 100 kΩ | F15: 0402 | G15: 1 %, 62.5 mW | H15: UNI-ROYAL 0402WGF1003TCE | I15: C25741 | J15: Basic | K15: JLCPCB library | L15: JLCPCB Basic (same type as R105, R303, R511–R513) | M15: Yes | O15: 2 | P15: 0 | Q15: 0.0033 | R15: =IF(OR($M15="Yes",$M15="Owner"),$C15*Cost!$B$6,0) -> 5 | S15: =$R15*$Q15 -> 0.0165 | T15: Passive: +5 %, min +2 | V15: =IF($M15="Owner",$R15,IF($M15<>"Yes",0,MAX(IF(LEFT($T15,7)="Passive",$R15+MAX(Cost!$B$8,ROUNDUP(Cost!$B$7*$R15,0)),$R15+Cost!$B$9),N($U15)))) -> 7 | W15: =$V15*$Q15 -> 0.0231 | X15: https://www.lcsc.com/product-detail/C19709.html | Y15: Cost patch: changed 86.6 k (Extended) → 100 k (Basic) | Z15: ,R108, | AA15: =IF($Z15="",0,LEN($Z15)-LEN(SUBSTITUTE($Z15,",",""))-1) -> 1 | AB15: =IF(OR($M15="Yes",$M15="Owner"),IF(COUNTIFS($H$4:$H15,$H15,$M$4:$M15,"Yes")+COUNTIFS($H$4:$H15,$H15,$M$4:$M15,"Owner")=1,1,0),0) -> 0 | AC15: UNI-ROYAL | AD15: =MID($H15,18,4) -> 1003 | AE15: =LEFT($AD15,3)*IF(ISNUMBER(--RIGHT($AD15,1)),10^RIGHT($AD15,1),10^(0-FIND(RIGHT($AD15,1),"JKLM"))) -> 100000 | AF15: {=LEFT($E15,FIND(" ",$E15)-1)*IFERROR(INDEX({1000,1000000,0.000000000001,0.000000001,0.000001},MATCH(MID($E15,FIND(" ",$E15)+1,1),{"k","M","p","n","µ"},0)),1)} -> 100000 | AG15: =IF(AND(RIGHT($E15,1)="Ω",ABS($AF15-$AE15)<=Checks!$C$6*$AE15),"OK","CHECK") -> OK
A16: 1 USB-C input, OVP and sensing | B16: R109 | C16: 1 | D16: U102 EN pull-up to VBUS (TI: ≥ 300 k; with C104, U102 switches on 3.3–55 ms after plug-in) | E16: 470 kΩ | F16: 0402 | G16: 1 %, 62.5 mW | H16: UNI-ROYAL 0402WGF4703TCE | I16: C25790 | J16: Basic (not verified) | K16: JLCPCB library | L16: Same type as R532 | M16: Yes | O16: 2 | P16: 0 | Q16: 0.002 | R16: =IF(OR($M16="Yes",$M16="Owner"),$C16*Cost!$B$6,0) -> 5 | S16: =$R16*$Q16 -> 0.01 | T16: Passive: +5 %, min +2 | V16: =IF($M16="Owner",$R16,IF($M16<>"Yes",0,MAX(IF(LEFT($T16,7)="Passive",$R16+MAX(Cost!$B$8,ROUNDUP(Cost!$B$7*$R16,0)),$R16+Cost!$B$9),N($U16)))) -> 7 | W16: =$V16*$Q16 -> 0.014 | X16: https://www.lcsc.com/product-detail/C25774.html | Y16: Cost patch: changed 300 k → 470 k (one part type less); USB D+ attach ≤ 79.2 ms against the 100 ms USB limit | Z16: ,R109, | AA16: =IF($Z16="",0,LEN($Z16)-LEN(SUBSTITUTE($Z16,",",""))-1) -> 1 | AB16: =IF(OR($M16="Yes",$M16="Owner"),IF(COUNTIFS($H$4:$H16,$H16,$M$4:$M16,"Yes")+COUNTIFS($H$4:$H16,$H16,$M$4:$M16,"Owner")=1,1,0),0) -> 1 | AC16: UNI-ROYAL | AD16: =MID($H16,18,4) -> 4703 | AE16: =LEFT($AD16,3)*IF(ISNUMBER(--RIGHT($AD16,1)),10^RIGHT($AD16,1),10^(0-FIND(RIGHT($AD16,1),"JKLM"))) -> 470000 | AF16: {=LEFT($E16,FIND(" ",$E16)-1)*IFERROR(INDEX({1000,1000000,0.000000000001,0.000000001,0.000001},MATCH(MID($E16,FIND(" ",$E16)+1,1),{"k","M","p","n","µ"},0)),1)} -> 470000 | AG16: =IF(AND(RIGHT($E16,1)="Ω",ABS($AF16-$AE16)<=Checks!$C$6*$AE16),"OK","CHECK") -> OK
A17: 1 USB-C input, OVP and sensing | B17: U101 | C17: 1 | D17: ESD array D+/D−; VBUS pin (5) tied to 3V3M (5V_SYS is off in suspend; on 5V_SYS the D+ pull-up would back-feed it through the upper diode) | E17: — | F17: SOT-23-6 | G17: IRM ≤ 150 nA at 5.25 V, 3.5 pF | H17: ST USBLC6-2SC6 | I17: C7519 | J17: Extended | K17: JLCPCB library | L17: As in Parts List v0.6 | M17: Yes | O17: 6 | P17: 0 | Q17: 0.1844 | R17: =IF(OR($M17="Yes",$M17="Owner"),$C17*Cost!$B$6,0) -> 5 | S17: =$R17*$Q17 -> 0.922 | T17: Other: +1 | V17: =IF($M17="Owner",$R17,IF($M17<>"Yes",0,MAX(IF(LEFT($T17,7)="Passive",$R17+MAX(Cost!$B$8,ROUNDUP(Cost!$B$7*$R17,0)),$R17+Cost!$B$9),N($U17)))) -> 6 | W17: =$V17*$Q17 -> 1.1064 | X17: https://www.st.com/resource/en/datasheet/usblc6-2.pdf | Y17: Pin 5 moved from 5V_SYS to 3V3M (suspend power cut) | Z17: ,U101, | AA17: =IF($Z17="",0,LEN($Z17)-LEN(SUBSTITUTE($Z17,",",""))-1) -> 1 | AB17: =IF(OR($M17="Yes",$M17="Owner"),IF(COUNTIFS($H$4:$H17,$H17,$M$4:$M17,"Yes")+COUNTIFS($H$4:$H17,$H17,$M$4:$M17,"Owner")=1,1,0),0) -> 1
A18: 1 USB-C input, OVP and sensing | B18: U102 | C18: 1 | D18: Input OVP eFuse: 5.25-5.55 V output clamp, OVLO 6.8-8.45 V, 20 V abs max IN, 99 mΩ max, built-in soft start | E18: — | F18: WSON-6 2 × 2 (DRV) + pad | G18: IOS 0.87–1.08 A with R108 100 k | H18: TI TPS25200DRVR | I18: C128401 | J18: Extended | K18: JLCPCB library | L18: JLCPCB 19,166 available (Aug 2026) | M18: Yes | N18: Yes | O18: 7 | P18: 0 | Q18: 0.44 | R18: =IF(OR($M18="Yes",$M18="Owner"),$C18*Cost!$B$6,0) -> 5 | S18: =$R18*$Q18 -> 2.2 | T18: Other: +1 | V18: =IF($M18="Owner",$R18,IF($M18<>"Yes",0,MAX(IF(LEFT($T18,7)="Passive",$R18+MAX(Cost!$B$8,ROUNDUP(Cost!$B$7*$R18,0)),$R18+Cost!$B$9),N($U18)))) -> 6 | W18: =$V18*$Q18 -> 2.64 | X18: https://www.ti.com/lit/ds/symlink/tps25200.pdf | Y18: New: VBUS → 5V_SYS; FAULT (pin 3) not connected; pad to GND | Z18: ,U102, | AA18: =IF($Z18="",0,LEN($Z18)-LEN(SUBSTITUTE($Z18,",",""))-1) -> 1 | AB18: =IF(OR($M18="Yes",$M18="Owner"),IF(COUNTIFS($H$4:$H18,$H18,$M$4:$M18,"Yes")+COUNTIFS($H$4:$H18,$H18,$M$4:$M18,"Owner")=1,1,0),0) -> 1
A19: 1 USB-C input, OVP and sensing | B19: U103 | C19: 1 | D19: CC1/CC2 ESD, 2 channels, low capacitance, at J101 | E19: — | F19: SOT-5X3 (DRL) 5-pin | G19: VRWM 5.5 V, VBR ≥ 6.5 V, 10 nA at 2.5 V, 1.5 pF, IEC ±25 kV | H19: TI TPD2E2U06DRLR | I19: C1972959 | J19: Extended (not verified) | K19: JLCPCB library | L19: JLCPCB 4,257 (Apr 2025); DigiKey 87,628 | M19: Yes | O19: 5 | P19: 0 | Q19: 0.22 | R19: =IF(OR($M19="Yes",$M19="Owner"),$C19*Cost!$B$6,0) -> 5 | S19: =$R19*$Q19 -> 1.1 | T19: Other: +1 | V19: =IF($M19="Owner",$R19,IF($M19<>"Yes",0,MAX(IF(LEFT($T19,7)="Passive",$R19+MAX(Cost!$B$8,ROUNDUP(Cost!$B$7*$R19,0)),$R19+Cost!$B$9),N($U19)))) -> 6 | W19: =$V19*$Q19 -> 1.32 | X19: https://www.ti.com/lit/ds/symlink/tpd2e2u06.pdf | Y19: New; pin 1/2 NC, 3 CC1, 4 GND, 5 CC2 | Z19: ,U103, | AA19: =IF($Z19="",0,LEN($Z19)-LEN(SUBSTITUTE($Z19,",",""))-1) -> 1 | AB19: =IF(OR($M19="Yes",$M19="Owner"),IF(COUNTIFS($H$4:$H19,$H19,$M$4:$M19,"Yes")+COUNTIFS($H$4:$H19,$H19,$M$4:$M19,"Owner")=1,1,0),0) -> 1
A20: 2 USB audio bridge (CH32V307 + AGRV2K CPLD + clocks) | B20: C201, C202 | C20: 2 | D20: Crystal load capacitors | E20: 33 pF | F20: 0402 | G20: 50 V C0G | H20: FH 0402CG330J500NT | I20: C1562 | J20: Basic | K20: JLCPCB library | L20: JLCPCB Basic | M20: Yes | O20: 2 | P20: 0 | Q20: 0.002 | R20: =IF(OR($M20="Yes",$M20="Owner"),$C20*Cost!$B$6,0) -> 10 | S20: =$R20*$Q20 -> 0.02 | T20: Passive: +5 %, min +2 | V20: =IF($M20="Owner",$R20,IF($M20<>"Yes",0,MAX(IF(LEFT($T20,7)="Passive",$R20+MAX(Cost!$B$8,ROUNDUP(Cost!$B$7*$R20,0)),$R20+Cost!$B$9),N($U20)))) -> 12 | W20: =$V20*$Q20 -> 0.024 | X20: https://www.lcsc.com/product-detail/C1562.html | Y20: 2 × (20 − 3.5) pF | Z20: ,C201,C202, | AA20: =IF($Z20="",0,LEN($Z20)-LEN(SUBSTITUTE($Z20,",",""))-1) -> 2 | AB20: =IF(OR($M20="Yes",$M20="Owner"),IF(COUNTIFS($H$4:$H20,$H20,$M$4:$M20,"Yes")+COUNTIFS($H$4:$H20,$H20,$M$4:$M20,"Owner")=1,1,0),0) -> 1 | AC20: FH | AD20: =IF(ISNUMBER(FIND("CG",$H20)),MID($H20,FIND("CG",$H20)+2,3),MID($H20,FIND(" 0",$H20)+6,3)) -> 330 | AE20: =IF(ISNUMBER(FIND("R",$AD20)),SUBSTITUTE($AD20,"R",".")*1,LEFT($AD20,2)*10^RIGHT($AD20,1))*10^-12 -> 3.3e-11 | AF20: {=LEFT($E20,FIND(" ",$E20)-1)*IFERROR(INDEX({1000,1000000,0.000000000001,0.000000001,0.000001},MATCH(MID($E20,FIND(" ",$E20)+1,1),{"k","M","p","n","µ"},0)),1)} -> 3.3e-11 | AG20: =IF(AND(RIGHT($E20,1)="F",ABS($AF20-$AE20)<=Checks!$C$6*$AE20),"OK","CHECK") -> OK
A21: 2 USB audio bridge (CH32V307 + AGRV2K CPLD + clocks) | B21: C203-C210, C212-C215, C218, C219, C222-C224 | C21: 17 | D21: 100 nF: decoupling (MCU ×8, CPLD ×3, X202/X203, U205, U206, U208) and NRST filter C212 | E21: 100 nF | F21: 0402 | G21: 16 V X7R | H21: Samsung CL05B104KO5NNNC | I21: C1525 | J21: Basic | K21: JLCPCB library | L21: JLCPCB Basic | M21: Yes | O21: 2 | P21: 0 | Q21: 0.0045 | R21: =IF(OR($M21="Yes",$M21="Owner"),$C21*Cost!$B$6,0) -> 85 | S21: =$R21*$Q21 -> 0.3825 | T21: Passive: +5 %, min +2 | V21: =IF($M21="Owner",$R21,IF($M21<>"Yes",0,MAX(IF(LEFT($T21,7)="Passive",$R21+MAX(Cost!$B$8,ROUNDUP(Cost!$B$7*$R21,0)),$R21+Cost!$B$9),N($U21)))) -> 90 | W21: =$V21*$Q21 -> 0.405 | X21: https://www.lcsc.com/product-detail/C1525.html | Y21: C216 retired; C213–C215 at CPLD pins 6/16/32; C212 = NRST filter; C217 now its own 10 nF line; C224 new (U208) | Z21: ,C203,C204,C205,C206,C207,C208,C209,C210,C212,C213,C214,C215,C218,C219,C222,C223,C224, | AA21: =IF($Z21="",0,LEN($Z21)-LEN(SUBSTITUTE($Z21,",",""))-1) -> 17 | AB21: =IF(OR($M21="Yes",$M21="Owner"),IF(COUNTIFS($H$4:$H21,$H21,$M$4:$M21,"Yes")+COUNTIFS($H$4:$H21,$H21,$M$4:$M21,"Owner")=1,1,0),0) -> 0 | AC21: Samsung CL | AD21: =MID($H21,FIND("CL",$H21)+5,3) -> 104 | AE21: =IF(ISNUMBER(FIND("R",$AD21)),SUBSTITUTE($AD21,"R",".")*1,LEFT($AD21,2)*10^RIGHT($AD21,1))*10^-12 -> 1e-07 | AF21: {=LEFT($E21,FIND(" ",$E21)-1)*IFERROR(INDEX({1000,1000000,0.000000000001,0.000000001,0.000001},MATCH(MID($E21,FIND(" ",$E21)+1,1),{"k","M","p","n","µ"},0)),1)} -> 1e-07 | AG21: =IF(AND(RIGHT($E21,1)="F",ABS($AF21-$AE21)<=Checks!$C$6*$AE21),"OK","CHECK") -> OK
A22: 2 USB audio bridge (CH32V307 + AGRV2K CPLD + clocks) | B22: C211 | C22: 1 | D22: MCU 3V3M bulk | E22: 2.2 µF | F22: 0402 | G22: 6.3 V X5R (≈ 1.1 µF at 3.3 V DC bias) | H22: Samsung CL05A225MQ5NSNC | I22: C12530 | J22: Basic | K22: JLCPCB library | L22: JLCPCB Basic | M22: Yes | O22: 2 | P22: 0 | Q22: 0.005 | R22: =IF(OR($M22="Yes",$M22="Owner"),$C22*Cost!$B$6,0) -> 5 | S22: =$R22*$Q22 -> 0.025 | T22: Passive: +5 %, min +2 | V22: =IF($M22="Owner",$R22,IF($M22<>"Yes",0,MAX(IF(LEFT($T22,7)="Passive",$R22+MAX(Cost!$B$8,ROUNDUP(Cost!$B$7*$R22,0)),$R22+Cost!$B$9),N($U22)))) -> 7 | W22: =$V22*$Q22 -> 0.035 | X22: https://www.lcsc.com/product-detail/C12530.html | Y22: Kept (counted in the attach-charge budget) | Z22: ,C211, | AA22: =IF($Z22="",0,LEN($Z22)-LEN(SUBSTITUTE($Z22,",",""))-1) -> 1 | AB22: =IF(OR($M22="Yes",$M22="Owner"),IF(COUNTIFS($H$4:$H22,$H22,$M$4:$M22,"Yes")+COUNTIFS($H$4:$H22,$H22,$M$4:$M22,"Owner")=1,1,0),0) -> 1 | AC22: Samsung CL | AD22: =MID($H22,FIND("CL",$H22)+5,3) -> 225 | AE22: =IF(ISNUMBER(FIND("R",$AD22)),SUBSTITUTE($AD22,"R",".")*1,LEFT($AD22,2)*10^RIGHT($AD22,1))*10^-12 -> 2.2e-06 | AF22: {=LEFT($E22,FIND(" ",$E22)-1)*IFERROR(INDEX({1000,1000000,0.000000000001,0.000000001,0.000001},MATCH(MID($E22,FIND(" ",$E22)+1,1),{"k","M","p","n","µ"},0)),1)} -> 2.2e-06 | AG22: =IF(AND(RIGHT($E22,1)="F",ABS($AF22-$AE22)<=Checks!$C$6*$AE22),"OK","CHECK") -> OK
A23: 2 USB audio bridge (CH32V307 + AGRV2K CPLD + clocks) | B23: C217 | C23: 1 | D23: X201 high-frequency bypass at the VCC pad | E23: 10 nF | F23: 0402 | G23: 50 V X7R | H23: Samsung CL05B103KB5NNNC | I23: C15195 | J23: Basic | K23: JLCPCB library | L23: JLCPCB Basic | M23: Yes | O23: 2 | P23: 0 | Q23: 0.002 | R23: =IF(OR($M23="Yes",$M23="Owner"),$C23*Cost!$B$6,0) -> 5 | S23: =$R23*$Q23 -> 0.01 | T23: Passive: +5 %, min +2 | V23: =IF($M23="Owner",$R23,IF($M23<>"Yes",0,MAX(IF(LEFT($T23,7)="Passive",$R23+MAX(Cost!$B$8,ROUNDUP(Cost!$B$7*$R23,0)),$R23+Cost!$B$9),N($U23)))) -> 7 | W23: =$V23*$Q23 -> 0.014 | X23: https://www.lcsc.com/product-detail/C15195.html | Y23: Changed 100 nF → 10 nF; Kyocera: "mount high frequency type capacitor 0.01 µF to the nearest position of oscillator" | Z23: ,C217, | AA23: =IF($Z23="",0,LEN($Z23)-LEN(SUBSTITUTE($Z23,",",""))-1) -> 1 | AB23: =IF(OR($M23="Yes",$M23="Owner"),IF(COUNTIFS($H$4:$H23,$H23,$M$4:$M23,"Yes")+COUNTIFS($H$4:$H23,$H23,$M$4:$M23,"Owner")=1,1,0),0) -> 1 | AC23: Samsung CL | AD23: =MID($H23,FIND("CL",$H23)+5,3) -> 103 | AE23: =IF(ISNUMBER(FIND("R",$AD23)),SUBSTITUTE($AD23,"R",".")*1,LEFT($AD23,2)*10^RIGHT($AD23,1))*10^-12 -> 1e-08 | AF23: {=LEFT($E23,FIND(" ",$E23)-1)*IFERROR(INDEX({1000,1000000,0.000000000001,0.000000001,0.000001},MATCH(MID($E23,FIND(" ",$E23)+1,1),{"k","M","p","n","µ"},0)),1)} -> 1e-08 | AG23: =IF(AND(RIGHT($E23,1)="F",ABS($AF23-$AE23)<=Checks!$C$6*$AE23),"OK","CHECK") -> OK
A24: 2 USB audio bridge (CH32V307 + AGRV2K CPLD + clocks) | B24: C220, C221 | C24: 2 | D24: Bulk: CPLD FB202 branch; MCU VDDA | E24: 1 µF | F24: 0603 | G24: 50 V X5R | H24: Samsung CL10A105KB8NNNC | I24: C15849 | J24: Basic | K24: JLCPCB library | L24: JLCPCB Basic | M24: Yes | O24: 2 | P24: 0 | Q24: 0.006 | R24: =IF(OR($M24="Yes",$M24="Owner"),$C24*Cost!$B$6,0) -> 10 | S24: =$R24*$Q24 -> 0.06 | T24: Passive: +5 %, min +2 | V24: =IF($M24="Owner",$R24,IF($M24<>"Yes",0,MAX(IF(LEFT($T24,7)="Passive",$R24+MAX(Cost!$B$8,ROUNDUP(Cost!$B$7*$R24,0)),$R24+Cost!$B$9),N($U24)))) -> 12 | W24: =$V24*$Q24 -> 0.072 | X24: https://www.lcsc.com/product-detail/C15849.html | Z24: ,C220,C221, | AA24: =IF($Z24="",0,LEN($Z24)-LEN(SUBSTITUTE($Z24,",",""))-1) -> 2 | AB24: =IF(OR($M24="Yes",$M24="Owner"),IF(COUNTIFS($H$4:$H24,$H24,$M$4:$M24,"Yes")+COUNTIFS($H$4:$H24,$H24,$M$4:$M24,"Owner")=1,1,0),0) -> 1 | AC24: Samsung CL | AD24: =MID($H24,FIND("CL",$H24)+5,3) -> 105 | AE24: =IF(ISNUMBER(FIND("R",$AD24)),SUBSTITUTE($AD24,"R",".")*1,LEFT($AD24,2)*10^RIGHT($AD24,1))*10^-12 -> 1e-06 | AF24: {=LEFT($E24,FIND(" ",$E24)-1)*IFERROR(INDEX({1000,1000000,0.000000000001,0.000000001,0.000001},MATCH(MID($E24,FIND(" ",$E24)+1,1),{"k","M","p","n","µ"},0)),1)} -> 1e-06 | AG24: =IF(AND(RIGHT($E24,1)="F",ABS($AF24-$AE24)<=Checks!$C$6*$AE24),"OK","CHECK") -> OK
A25: 2 USB audio bridge (CH32V307 + AGRV2K CPLD + clocks) | B25: FB202 | C25: 1 | D25: Ferrite bead 3V3D → CPLD VDD33/VDDA33 (AGM: bead-isolated feed) | E25: 600 Ω @ 100 MHz | F25: 0603 | G25: 200 mA, 0.45 Ω | H25: Sunlord GZ1608D601TF | I25: C1002 | J25: Basic | K25: JLCPCB library | L25: JLCPCB Basic | M25: Yes | O25: 2 | P25: 0 | Q25: 0.0127 | R25: =IF(OR($M25="Yes",$M25="Owner"),$C25*Cost!$B$6,0) -> 5 | S25: =$R25*$Q25 -> 0.0635 | T25: Passive: +5 %, min +2 | V25: =IF($M25="Owner",$R25,IF($M25<>"Yes",0,MAX(IF(LEFT($T25,7)="Passive",$R25+MAX(Cost!$B$8,ROUNDUP(Cost!$B$7*$R25,0)),$R25+Cost!$B$9),N($U25)))) -> 7 | W25: =$V25*$Q25 -> 0.0889 | X25: https://www.lcsc.com/product-detail/C1002.html | Y25: ≤ 40 mA CPLD budget → 18 mV drop | Z25: ,FB202, | AA25: =IF($Z25="",0,LEN($Z25)-LEN(SUBSTITUTE($Z25,",",""))-1) -> 1 | AB25: =IF(OR($M25="Yes",$M25="Owner"),IF(COUNTIFS($H$4:$H25,$H25,$M$4:$M25,"Yes")+COUNTIFS($H$4:$H25,$H25,$M$4:$M25,"Owner")=1,1,0),0) -> 1
A26: 2 USB audio bridge (CH32V307 + AGRV2K CPLD + clocks) | B26: J201 | C26: 1 | D26: Pads: MCU 2-wire SDI debug (WCH-LinkE) + BOOT0 + USART1 | E26: — | F26: 8 SMD pads | G26: — | H26: PCB pads (no component) | I26: — | J26: — | K26: PCB copper | L26: — | M26: Pads | O26: 0 | P26: 0 | Q26: 0 | R26: =IF(OR($M26="Yes",$M26="Owner"),$C26*Cost!$B$6,0) -> 0 | S26: =$R26*$Q26 -> 0 | T26: — | V26: =IF($M26="Owner",$R26,IF($M26<>"Yes",0,MAX(IF(LEFT($T26,7)="Passive",$R26+MAX(Cost!$B$8,ROUNDUP(Cost!$B$7*$R26,0)),$R26+Cost!$B$9),N($U26)))) -> 0 | W26: =$V26*$Q26 -> 0 | Y26: Copper pads only — exclude from the JLCPCB BOM/CPL; pin 1 = N2_J201_3V3 via the DNF R241 (never power the board from the probe) | Z26: ,J201, | AA26: =IF($Z26="",0,LEN($Z26)-LEN(SUBSTITUTE($Z26,",",""))-1) -> 1 | AB26: =IF(OR($M26="Yes",$M26="Owner"),IF(COUNTIFS($H$4:$H26,$H26,$M$4:$M26,"Yes")+COUNTIFS($H$4:$H26,$H26,$M$4:$M26,"Owner")=1,1,0),0) -> 0
A27: 2 USB audio bridge (CH32V307 + AGRV2K CPLD + clocks) | B27: J202 | C27: 1 | D27: Pads: CPLD 2-wire Compact-JTAG (J-Link / AGM DAP-Link) | E27: — | F27: 5 SMD pads | G27: — | H27: PCB pads (no component) | I27: — | J27: — | K27: PCB copper | L27: — | M27: Pads | O27: 0 | P27: 0 | Q27: 0 | R27: =IF(OR($M27="Yes",$M27="Owner"),$C27*Cost!$B$6,0) -> 0 | S27: =$R27*$Q27 -> 0 | T27: — | V27: =IF($M27="Owner",$R27,IF($M27<>"Yes",0,MAX(IF(LEFT($T27,7)="Passive",$R27+MAX(Cost!$B$8,ROUNDUP(Cost!$B$7*$R27,0)),$R27+Cost!$B$9),N($U27)))) -> 0 | W27: =$V27*$Q27 -> 0 | Y27: Copper pads only — exclude from the JLCPCB BOM/CPL; 3V3D sense only | Z27: ,J202, | AA27: =IF($Z27="",0,LEN($Z27)-LEN(SUBSTITUTE($Z27,",",""))-1) -> 1 | AB27: =IF(OR($M27="Yes",$M27="Owner"),IF(COUNTIFS($H$4:$H27,$H27,$M$4:$M27,"Yes")+COUNTIFS($H$4:$H27,$H27,$M$4:$M27,"Owner")=1,1,0),0) -> 0
A28: 2 USB audio bridge (CH32V307 + AGRV2K CPLD + clocks) | B28: Q207 | C28: 1 | D28: N-MOSFET, open-drain DAC_RESETB driver (on = DAC reset; gate PA8 + R240 pull-up to 3V3M) | E28: AO3400A | F28: SOT-23 | G28: 30 V, VGS ±12 V, VGS(th) 0.65-1.45 V, RDS(on) ≤ 48 mΩ at 2.5 V | H28: AOS AO3400A | I28: C20917 | J28: Basic | K28: JLCPCB library | L28: JLCPCB Basic (same part as Q502-Q506, Q616, Q617) | M28: Yes | O28: 3 | P28: 0 | Q28: 0.0524 | R28: =IF(OR($M28="Yes",$M28="Owner"),$C28*Cost!$B$6,0) -> 5 | S28: =$R28*$Q28 -> 0.262 | T28: Other: +1 | V28: =IF($M28="Owner",$R28,IF($M28<>"Yes",0,MAX(IF(LEFT($T28,7)="Passive",$R28+MAX(Cost!$B$8,ROUNDUP(Cost!$B$7*$R28,0)),$R28+Cost!$B$9),N($U28)))) -> 6 | W28: =$V28*$Q28 -> 0.3144 | X28: https://www.aosmd.com/res/datasheets/AO3400A.pdf | Y28: New; replaces R233; pins 1 G, 2 S, 3 D (as Q502–Q506) | Z28: ,Q207, | AA28: =IF($Z28="",0,LEN($Z28)-LEN(SUBSTITUTE($Z28,",",""))-1) -> 1 | AB28: =IF(OR($M28="Yes",$M28="Owner"),IF(COUNTIFS($H$4:$H28,$H28,$M$4:$M28,"Yes")+COUNTIFS($H$4:$H28,$H28,$M$4:$M28,"Owner")=1,1,0),0) -> 1
A29: 2 USB audio bridge (CH32V307 + AGRV2K CPLD + clocks) | B29: R201, R202, R207, R208, R212, R213, R216-R218, R227, R231, R232, R234, R236, R238, R239 | C29: 16 | D29: 10 k: pull-ups/downs (NRST, BOOT0, BOOT1, I²C SCL/SDA, osc enables, mux inputs, MCLK_EN, MCLK, CPLD_NRST, MCLK_PERMIT, JTMS, JTCK) and the AVCC_EN series R236 | E29: 10 kΩ | F29: 0402 | G29: 1 % | H29: UNI-ROYAL 0402WGF1002TCE | I29: C25744 | J29: Basic | K29: JLCPCB library | L29: JLCPCB Basic | M29: Yes | O29: 2 | P29: 0 | Q29: 0.002 | R29: =IF(OR($M29="Yes",$M29="Owner"),$C29*Cost!$B$6,0) -> 80 | S29: =$R29*$Q29 -> 0.16 | T29: Passive: +5 %, min +2 | V29: =IF($M29="Owner",$R29,IF($M29<>"Yes",0,MAX(IF(LEFT($T29,7)="Passive",$R29+MAX(Cost!$B$8,ROUNDUP(Cost!$B$7*$R29,0)),$R29+Cost!$B$9),N($U29)))) -> 84 | W29: =$V29*$Q29 -> 0.168 | X29: https://www.lcsc.com/product-detail/C25744.html | Y29: R212/R213/R218 changed from 2.2 k; R216/R217 now fitted; R227, R231, R232, R234, R236, R238, R239 new; R207/R208 changed to 10 k (I²C at 100 kHz) | Z29: ,R201,R202,R207,R208,R212,R213,R216,R217,R218,R227,R231,R232,R234,R236,R238,R239, | AA29: =IF($Z29="",0,LEN($Z29)-LEN(SUBSTITUTE($Z29,",",""))-1) -> 16 | AB29: =IF(OR($M29="Yes",$M29="Owner"),IF(COUNTIFS($H$4:$H29,$H29,$M$4:$M29,"Yes")+COUNTIFS($H$4:$H29,$H29,$M$4:$M29,"Owner")=1,1,0),0) -> 0 | AC29: UNI-ROYAL | AD29: =MID($H29,18,4) -> 1002 | AE29: =LEFT($AD29,3)*IF(ISNUMBER(--RIGHT($AD29,1)),10^RIGHT($AD29,1),10^(0-FIND(RIGHT($AD29,1),"JKLM"))) -> 10000 | AF29: {=LEFT($E29,FIND(" ",$E29)-1)*IFERROR(INDEX({1000,1000000,0.000000000001,0.000000001,0.000001},MATCH(MID($E29,FIND(" ",$E29)+1,1),{"k","M","p","n","µ"},0)),1)} -> 10000 | AG29: =IF(AND(RIGHT($E29,1)="Ω",ABS($AF29-$AE29)<=Checks!$C$6*$AE29),"OK","CHECK") -> OK
A30: 2 USB audio bridge (CH32V307 + AGRV2K CPLD + clocks) | B30: R203-R206, R210, R211, R215, R224, R225 | C30: 9 | D30: Series source terminations (MCLK, I²S, osc→mux, mux→CPLD, link) | E30: 33 Ω | F30: 0402 | G30: 1 %, 62.5 mW | H30: UNI-ROYAL 0402WGF330JTCE | I30: C25105 | J30: Basic | K30: JLCPCB library | L30: JLCPCB Basic | M30: Yes | O30: 2 | P30: 0 | Q30: 0.002 | R30: =IF(OR($M30="Yes",$M30="Owner"),$C30*Cost!$B$6,0) -> 45 | S30: =$R30*$Q30 -> 0.09 | T30: Passive: +5 %, min +2 | V30: =IF($M30="Owner",$R30,IF($M30<>"Yes",0,MAX(IF(LEFT($T30,7)="Passive",$R30+MAX(Cost!$B$8,ROUNDUP(Cost!$B$7*$R30,0)),$R30+Cost!$B$9),N($U30)))) -> 48 | W30: =$V30*$Q30 -> 0.096 | X30: https://www.lcsc.com/product-detail/C25105.html | Y30: R215 now fitted | Z30: ,R203,R204,R205,R206,R210,R211,R215,R224,R225, | AA30: =IF($Z30="",0,LEN($Z30)-LEN(SUBSTITUTE($Z30,",",""))-1) -> 9 | AB30: =IF(OR($M30="Yes",$M30="Owner"),IF(COUNTIFS($H$4:$H30,$H30,$M$4:$M30,"Yes")+COUNTIFS($H$4:$H30,$H30,$M$4:$M30,"Owner")=1,1,0),0) -> 1 | AC30: UNI-ROYAL | AD30: =MID($H30,18,4) -> 330J | AE30: =LEFT($AD30,3)*IF(ISNUMBER(--RIGHT($AD30,1)),10^RIGHT($AD30,1),10^(0-FIND(RIGHT($AD30,1),"JKLM"))) -> 33 | AF30: {=LEFT($E30,FIND(" ",$E30)-1)*IFERROR(INDEX({1000,1000000,0.000000000001,0.000000001,0.000001},MATCH(MID($E30,FIND(" ",$E30)+1,1),{"k","M","p","n","µ"},0)),1)} -> 33 | AG30: =IF(AND(RIGHT($E30,1)="Ω",ABS($AF30-$AE30)<=Checks!$C$6*$AE30),"OK","CHECK") -> OK
A31: 2 USB audio bridge (CH32V307 + AGRV2K CPLD + clocks) | B31: R228-R230, R242-R246 | C31: 8 | D31: 330 Ω: I²S capture taps to MCU I²S2 (CPLD side); ADC pin injection limiters PC0-PC4 | E31: 330 Ω | F31: 0402 | G31: 1 %, 62.5 mW | H31: UNI-ROYAL 0402WGF3300TCE | I31: C25104 | J31: Basic | K31: JLCPCB library | L31: JLCPCB Basic | M31: Yes | O31: 2 | P31: 0 | Q31: 0.002 | R31: =IF(OR($M31="Yes",$M31="Owner"),$C31*Cost!$B$6,0) -> 40 | S31: =$R31*$Q31 -> 0.08 | T31: Passive: +5 %, min +2 | V31: =IF($M31="Owner",$R31,IF($M31<>"Yes",0,MAX(IF(LEFT($T31,7)="Passive",$R31+MAX(Cost!$B$8,ROUNDUP(Cost!$B$7*$R31,0)),$R31+Cost!$B$9),N($U31)))) -> 42 | W31: =$V31*$Q31 -> 0.084 | X31: https://www.lcsc.com/product-detail/C25104.html | Y31: R242–R246 new (at the MCU pins); LCSC C25104, JLCPCB Basic | Z31: ,R228,R229,R230,R242,R243,R244,R245,R246, | AA31: =IF($Z31="",0,LEN($Z31)-LEN(SUBSTITUTE($Z31,",",""))-1) -> 8 | AB31: =IF(OR($M31="Yes",$M31="Owner"),IF(COUNTIFS($H$4:$H31,$H31,$M$4:$M31,"Yes")+COUNTIFS($H$4:$H31,$H31,$M$4:$M31,"Owner")=1,1,0),0) -> 1 | AC31: UNI-ROYAL | AD31: =MID($H31,18,4) -> 3300 | AE31: =LEFT($AD31,3)*IF(ISNUMBER(--RIGHT($AD31,1)),10^RIGHT($AD31,1),10^(0-FIND(RIGHT($AD31,1),"JKLM"))) -> 330 | AF31: {=LEFT($E31,FIND(" ",$E31)-1)*IFERROR(INDEX({1000,1000000,0.000000000001,0.000000001,0.000001},MATCH(MID($E31,FIND(" ",$E31)+1,1),{"k","M","p","n","µ"},0)),1)} -> 330 | AG31: =IF(AND(RIGHT($E31,1)="Ω",ABS($AF31-$AE31)<=Checks!$C$6*$AE31),"OK","CHECK") -> OK
A32: 2 USB audio bridge (CH32V307 + AGRV2K CPLD + clocks) | B32: R235, R240 | C32: 2 | D32: 100 k: pull-down at U206 Y (X201 INH / PB1 readback / Q616 gate via R645); Q207 gate pull-up to 3V3M | E32: 100 kΩ | F32: 0402 | G32: 1 % | H32: UNI-ROYAL 0402WGF1003TCE | I32: C25741 | J32: Basic | K32: JLCPCB library | L32: JLCPCB Basic | M32: Yes | O32: 2 | P32: 0 | Q32: 0.002 | R32: =IF(OR($M32="Yes",$M32="Owner"),$C32*Cost!$B$6,0) -> 10 | S32: =$R32*$Q32 -> 0.02 | T32: Passive: +5 %, min +2 | V32: =IF($M32="Owner",$R32,IF($M32<>"Yes",0,MAX(IF(LEFT($T32,7)="Passive",$R32+MAX(Cost!$B$8,ROUNDUP(Cost!$B$7*$R32,0)),$R32+Cost!$B$9),N($U32)))) -> 12 | W32: =$V32*$Q32 -> 0.024 | X32: https://www.lcsc.com/product-detail/C25741.html | Y32: R235 and R240 new; same part as R646/R648 | Z32: ,R235,R240, | AA32: =IF($Z32="",0,LEN($Z32)-LEN(SUBSTITUTE($Z32,",",""))-1) -> 2 | AB32: =IF(OR($M32="Yes",$M32="Owner"),IF(COUNTIFS($H$4:$H32,$H32,$M$4:$M32,"Yes")+COUNTIFS($H$4:$H32,$H32,$M$4:$M32,"Owner")=1,1,0),0) -> 0 | AC32: UNI-ROYAL | AD32: =MID($H32,18,4) -> 1003 | AE32: =LEFT($AD32,3)*IF(ISNUMBER(--RIGHT($AD32,1)),10^RIGHT($AD32,1),10^(0-FIND(RIGHT($AD32,1),"JKLM"))) -> 100000 | AF32: {=LEFT($E32,FIND(" ",$E32)-1)*IFERROR(INDEX({1000,1000000,0.000000000001,0.000000001,0.000001},MATCH(MID($E32,FIND(" ",$E32)+1,1),{"k","M","p","n","µ"},0)),1)} -> 100000 | AG32: =IF(AND(RIGHT($E32,1)="Ω",ABS($AF32-$AE32)<=Checks!$C$6*$AE32),"OK","CHECK") -> OK
A33: 2 USB audio bridge (CH32V307 + AGRV2K CPLD + clocks) | B33: R237 | C33: 1 | D33: AUD_EN series resistor from MCU PC10 | E33: 4.7 kΩ | F33: 0402 | G33: 1 % | H33: UNI-ROYAL 0402WGF4701TCE | I33: C25900 | J33: Basic | K33: JLCPCB library | L33: JLCPCB Basic | M33: Yes | O33: 2 | P33: 0 | Q33: 0.002 | R33: =IF(OR($M33="Yes",$M33="Owner"),$C33*Cost!$B$6,0) -> 5 | S33: =$R33*$Q33 -> 0.01 | T33: Passive: +5 %, min +2 | V33: =IF($M33="Owner",$R33,IF($M33<>"Yes",0,MAX(IF(LEFT($T33,7)="Passive",$R33+MAX(Cost!$B$8,ROUNDUP(Cost!$B$7*$R33,0)),$R33+Cost!$B$9),N($U33)))) -> 7 | W33: =$V33*$Q33 -> 0.014 | X33: https://www.lcsc.com/product-detail/C25900.html | Y33: New (lets the 3V3A-good supervisor override the MCU); LCSC number to be confirmed at order | Z33: ,R237, | AA33: =IF($Z33="",0,LEN($Z33)-LEN(SUBSTITUTE($Z33,",",""))-1) -> 1 | AB33: =IF(OR($M33="Yes",$M33="Owner"),IF(COUNTIFS($H$4:$H33,$H33,$M$4:$M33,"Yes")+COUNTIFS($H$4:$H33,$H33,$M$4:$M33,"Owner")=1,1,0),0) -> 1 | AC33: UNI-ROYAL | AD33: =MID($H33,18,4) -> 4701 | AE33: =LEFT($AD33,3)*IF(ISNUMBER(--RIGHT($AD33,1)),10^RIGHT($AD33,1),10^(0-FIND(RIGHT($AD33,1),"JKLM"))) -> 4700 | AF33: {=LEFT($E33,FIND(" ",$E33)-1)*IFERROR(INDEX({1000,1000000,0.000000000001,0.000000001,0.000001},MATCH(MID($E33,FIND(" ",$E33)+1,1),{"k","M","p","n","µ"},0)),1)} -> 4700 | AG33: =IF(AND(RIGHT($E33,1)="Ω",ABS($AF33-$AE33)<=Checks!$C$6*$AE33),"OK","CHECK") -> OK
A34: 2 USB audio bridge (CH32V307 + AGRV2K CPLD + clocks) | B34: R241 | C34: 1 | D34: J201 pin 1 link to 3V3M (DNF: WCH-LinkE 3V3 is a power output) | E34: 0 Ω | F34: 0402 | G34: jumper | H34: UNI-ROYAL 0402WGF0000TCE | I34: C17168 | J34: Basic | K34: — (DNF) | L34: JLCPCB Basic | M34: No | O34: 2 | P34: 0 | Q34: 0.002 | R34: =IF(OR($M34="Yes",$M34="Owner"),$C34*Cost!$B$6,0) -> 0 | S34: =$R34*$Q34 -> 0 | T34: — | V34: =IF($M34="Owner",$R34,IF($M34<>"Yes",0,MAX(IF(LEFT($T34,7)="Passive",$R34+MAX(Cost!$B$8,ROUNDUP(Cost!$B$7*$R34,0)),$R34+Cost!$B$9),N($U34)))) -> 0 | W34: =$V34*$Q34 -> 0 | X34: https://www.lcsc.com/product-detail/C17168.html | Y34: New DNF link; net N2_J201_3V3 | Z34: ,R241, | AA34: =IF($Z34="",0,LEN($Z34)-LEN(SUBSTITUTE($Z34,",",""))-1) -> 1 | AB34: =IF(OR($M34="Yes",$M34="Owner"),IF(COUNTIFS($H$4:$H34,$H34,$M$4:$M34,"Yes")+COUNTIFS($H$4:$H34,$H34,$M$4:$M34,"Owner")=1,1,0),0) -> 0 | AC34: UNI-ROYAL | AD34: =MID($H34,18,4) -> 0000 | AE34: =LEFT($AD34,3)*IF(ISNUMBER(--RIGHT($AD34,1)),10^RIGHT($AD34,1),10^(0-FIND(RIGHT($AD34,1),"JKLM"))) -> 0 | AF34: {=LEFT($E34,FIND(" ",$E34)-1)*IFERROR(INDEX({1000,1000000,0.000000000001,0.000000001,0.000001},MATCH(MID($E34,FIND(" ",$E34)+1,1),{"k","M","p","n","µ"},0)),1)} -> 0 | AG34: =IF(AND(RIGHT($E34,1)="Ω",ABS($AF34-$AE34)<=Checks!$C$6*$AE34),"OK","CHECK") -> OK
A35: 2 USB audio bridge (CH32V307 + AGRV2K CPLD + clocks) | B35: U201 | C35: 1 | D35: MCU, RISC-V V4F 144 MHz, USB2.0 HS PHY, own UAC2 firmware | E35: CH32V307RCT6 | F35: LQFP-64M 10 × 10 | G35: 3.3 V, -40…85 °C | H35: WCH CH32V307RCT6 | I35: C2988083 | J35: Extended | K35: JLCPCB library | L35: JLCPCB 364 / LCSC 193 (Sep 2026): thin stock, single source — pre-order 6 (5 boards + 1) | M35: Yes | O35: 64 | P35: 0 | Q35: 3.47 | R35: =IF(OR($M35="Yes",$M35="Owner"),$C35*Cost!$B$6,0) -> 5 | S35: =$R35*$Q35 -> 17.35 | T35: Other: +1 | V35: =IF($M35="Owner",$R35,IF($M35<>"Yes",0,MAX(IF(LEFT($T35,7)="Passive",$R35+MAX(Cost!$B$8,ROUNDUP(Cost!$B$7*$R35,0)),$R35+Cost!$B$9),N($U35)))) -> 6 | W35: =$V35*$Q35 -> 20.82 | X35: https://www.wch-ic.com/downloads/CH32V307DS0_PDF.html | Y35: MSL 3 (bake) | Z35: ,U201, | AA35: =IF($Z35="",0,LEN($Z35)-LEN(SUBSTITUTE($Z35,",",""))-1) -> 1 | AB35: =IF(OR($M35="Yes",$M35="Owner"),IF(COUNTIFS($H$4:$H35,$H35,$M$4:$M35,"Yes")+COUNTIFS($H$4:$H35,$H35,$M$4:$M35,"Owner")=1,1,0),0) -> 1
A36: 2 USB audio bridge (CH32V307 + AGRV2K CPLD + clocks) | B36: U202 | C36: 1 | D36: CPLD 2K LUT (AG32 silicon): SPI link, FIFO, I²S master, osc/mux/MCLK enables | E36: AGRV2KQ32 | F36: QFN-32 4 × 4, EP 2.7 | G36: 3.3 V, TJ -40…85 °C | H36: AGM AGRV2KQ32 | I36: C18208899 | J36: Extended | K36: JLCPCB library | L36: LCSC 980 (Sep 2026): thin stock, single source — pre-order 6 (5 boards + 1) | M36: Yes | N36: Yes | O36: 33 | P36: 0 | Q36: 1.6503 | R36: =IF(OR($M36="Yes",$M36="Owner"),$C36*Cost!$B$6,0) -> 5 | S36: =$R36*$Q36 -> 8.2515 | T36: Other: +1 | V36: =IF($M36="Owner",$R36,IF($M36<>"Yes",0,MAX(IF(LEFT($T36,7)="Passive",$R36+MAX(Cost!$B$8,ROUNDUP(Cost!$B$7*$R36,0)),$R36+Cost!$B$9),N($U36)))) -> 6 | W36: =$V36*$Q36 -> 9.9018 | X36: https://www.ag32mcu.com/wp-content/uploads/2026/02/AGRV2K_Rev_3_0.pdf | Y36: Programmed via J202 (J-Link / AGM DAP-Link); AGM ships AGRV2K parts marked as the AG32VF303 of the same package (order remark); exposed-pad size and net checked at gate G-3; X-ray | Z36: ,U202, | AA36: =IF($Z36="",0,LEN($Z36)-LEN(SUBSTITUTE($Z36,",",""))-1) -> 1 | AB36: =IF(OR($M36="Yes",$M36="Owner"),IF(COUNTIFS($H$4:$H36,$H36,$M$4:$M36,"Yes")+COUNTIFS($H$4:$H36,$H36,$M$4:$M36,"Owner")=1,1,0),0) -> 1
A37: 2 USB audio bridge (CH32V307 + AGRV2K CPLD + clocks) | B37: U205 | C37: 1 | D37: 2:1 clock mux (family select), now fitted | E37: 74LVC1G157 | F37: SOT-363 (TSSOP6) | G37: 1.65-5.5 V, IOFF | H37: Nexperia 74LVC1G157GW,125 | I37: C135822 | J37: Extended | K37: JLCPCB library | L37: LCSC stock | M37: Yes | O37: 6 | P37: 0 | Q37: 0.2106 | R37: =IF(OR($M37="Yes",$M37="Owner"),$C37*Cost!$B$6,0) -> 5 | S37: =$R37*$Q37 -> 1.053 | T37: Other: +1 | V37: =IF($M37="Owner",$R37,IF($M37<>"Yes",0,MAX(IF(LEFT($T37,7)="Passive",$R37+MAX(Cost!$B$8,ROUNDUP(Cost!$B$7*$R37,0)),$R37+Cost!$B$9),N($U37)))) -> 6 | W37: =$V37*$Q37 -> 1.2636 | X37: https://assets.nexperia.com/documents/data-sheet/74LVC1G157.pdf | Y37: S = OSC44_EN; S = L → I0 (X202) | Z37: ,U205, | AA37: =IF($Z37="",0,LEN($Z37)-LEN(SUBSTITUTE($Z37,",",""))-1) -> 1 | AB37: =IF(OR($M37="Yes",$M37="Owner"),IF(COUNTIFS($H$4:$H37,$H37,$M$4:$M37,"Yes")+COUNTIFS($H$4:$H37,$H37,$M$4:$M37,"Owner")=1,1,0),0) -> 1
A38: 2 USB audio bridge (CH32V307 + AGRV2K CPLD + clocks) | B38: U206 | C38: 1 | D38: 3-input AND: X201 E/D = MCLK_EN AND AVCC_EN AND MCLK_PERMIT (hardware MCLK stop) | E38: 74LVC1G11 | F38: SOT-363 (TSSOP6) | G38: 1.65-5.5 V, IOFF, inputs 5.5 V tolerant, Schmitt action, tpd ≤ 4.9 ns | H38: Nexperia 74LVC1G11GW-Q100H | I38: C548242 | J38: Extended | K38: JLCPCB library | L38: LCSC 3,690 (Sep 2026) | M38: Yes | O38: 6 | P38: 0 | Q38: 0.0768 | R38: =IF(OR($M38="Yes",$M38="Owner"),$C38*Cost!$B$6,0) -> 5 | S38: =$R38*$Q38 -> 0.384 | T38: Other: +1 | V38: =IF($M38="Owner",$R38,IF($M38<>"Yes",0,MAX(IF(LEFT($T38,7)="Passive",$R38+MAX(Cost!$B$8,ROUNDUP(Cost!$B$7*$R38,0)),$R38+Cost!$B$9),N($U38)))) -> 6 | W38: =$V38*$Q38 -> 0.4608 | X38: https://assets.nexperia.com/documents/data-sheet/74LVC1G11.pdf | Y38: Was 74LVC1G08GW (C12512, SOT353 5-pin); 6-pin SOT363-2 footprint: 1 A, 2 GND, 3 B, 4 Y, 5 VCC, 6 C; input B = N2_AVCC_EN_G; VOH ≥ VCC − 0.1 V vs Kyocera VIH 0.7 VCC; Y also feeds R645 → Q616 | Z38: ,U206, | AA38: =IF($Z38="",0,LEN($Z38)-LEN(SUBSTITUTE($Z38,",",""))-1) -> 1 | AB38: =IF(OR($M38="Yes",$M38="Owner"),IF(COUNTIFS($H$4:$H38,$H38,$M$4:$M38,"Yes")+COUNTIFS($H$4:$H38,$H38,$M$4:$M38,"Owner")=1,1,0),0) -> 1
A39: 2 USB audio bridge (CH32V307 + AGRV2K CPLD + clocks) | B39: U208 | C39: 1 | D39: Triple buffer, Ioff (partial power-down), 3V3M → 3V3D domain crossing of LINK_SCK/LINK_MOSI/LINK_FRAME, placed at U202 | E39: 74LVC3G34 | F39: VSSOP-8 0.5 mm (SOT765-1, DC) | G39: 1.65–5.5 V, Ioff ±10 µA (VCC = 0, VI/VO 5.5 V), inputs 5.5 V tolerant, tpd 1.4–4.1 ns (3.3 V ± 0.3 V, −40…85 °C), ICC ≤ 10 µA, MSL 1 260 °C | H39: TI SN74LVC3G34DCUR | I39: C130024 | J39: Extended | K39: JLCPCB library | L39: LCSC 550 (25 Sep 2026), min/multiple 5 — pre-order 10 | M39: Yes | O39: 8 | P39: 0 | Q39: 0.2012 | R39: =IF(OR($M39="Yes",$M39="Owner"),$C39*Cost!$B$6,0) -> 5 | S39: =$R39*$Q39 -> 1.006 | T39: Other: +1 | U39: 10 | V39: =IF($M39="Owner",$R39,IF($M39<>"Yes",0,MAX(IF(LEFT($T39,7)="Passive",$R39+MAX(Cost!$B$8,ROUNDUP(Cost!$B$7*$R39,0)),$R39+Cost!$B$9),N($U39)))) -> 10 | W39: =$V39*$Q39 -> 2.012 | X39: https://assets.nexperia.com/documents/data-sheet/74LVC3G34.pdf | Y39: Cost patch: replaces the Nexperia 74LVC3G34DC,125 (C548774, US$ 0.7647) — same DCU pinout 1 1A, 2 3Y, 3 2A, 4 GND, 5 2Y, 6 3A, 7 1Y, 8 VCC (TI datasheet pin table); the Nexperia part is the approved alternate | Z39: ,U208, | AA39: =IF($Z39="",0,LEN($Z39)-LEN(SUBSTITUTE($Z39,",",""))-1) -> 1 | AB39: =IF(OR($M39="Yes",$M39="Owner"),IF(COUNTIFS($H$4:$H39,$H39,$M$4:$M39,"Yes")+COUNTIFS($H$4:$H39,$H39,$M$4:$M39,"Owner")=1,1,0),0) -> 1
A40: 2 USB audio bridge (CH32V307 + AGRV2K CPLD + clocks) | B40: X201 | C40: 1 | D40: Oscillator 80 MHz CMOS SPXO (crystal), stand-by pin 1 (oscillation stop) - DAC MCLK only | E40: 80.000 MHz | F40: 2.5 × 2.0 mm 4-pad, plain 2520 land (no 3225 pads) | G40: ±50 ppm (-40…85 °C incl. initial/temp/supply/load/1-yr aging), ICC ≤ 8.0 mA loaded 15 pF (2.8-3.63 V, over temp), stand-by ≤ 5 µA, SYM 45-55 %, tr/tf ≤ 4.5 ns (10-90 %), t_dis ≤ 200 ns, enable/start-up ≤ 2 ms (spec; 3 ms catalogue), VIH ≥ 0.7 VCC, VIL ≤ 0.3 VCC, abs max 4.0 V, reflow 260 °C ×2, MSL 1 | H40: Kyocera KC2520K80.0000C1GE00 | I40: C1988889 | J40: Extended | K40: Global sourcing | L40: LCSC C1988889 not stocked → JLCPCB global sourcing: DigiKey 2,964 (Aug 2026), Mouser 1,375 (+10,000 on order) | M40: Yes | N40: Yes | O40: 4 | P40: 0 | Q40: 1.39 | R40: =IF(OR($M40="Yes",$M40="Owner"),$C40*Cost!$B$6,0) -> 5 | S40: =$R40*$Q40 -> 6.95 | T40: Other: +1 | V40: =IF($M40="Owner",$R40,IF($M40<>"Yes",0,MAX(IF(LEFT($T40,7)="Passive",$R40+MAX(Cost!$B$8,ROUNDUP(Cost!$B$7*$R40,0)),$R40+Cost!$B$9),N($U40)))) -> 6 | W40: =$V40*$Q40 -> 8.34 | X40: https://ele.kyocera.com/assets/products/crystal-device/specification/KC2520K80.0000C1GE00_e.pdf | Y40: Replaces the obsolete Epson SG-210STF 75 MHz (25 Sep 2026); conditional second source NDK NSC5338D-80M (bring-up checks of disable time and edges; 12.7 mA budget; 2520 land; no R509 change); TXC 7X-80.000MBE-T withdrawn; SCTF SX3M80 (C5179978, 3225) not approved and has no land; stand-by driven by U206 | Z40: ,X201, | AA40: =IF($Z40="",0,LEN($Z40)-LEN(SUBSTITUTE($Z40,",",""))-1) -> 1 | AB40: =IF(OR($M40="Yes",$M40="Owner"),IF(COUNTIFS($H$4:$H40,$H40,$M$4:$M40,"Yes")+COUNTIFS($H$4:$H40,$H40,$M$4:$M40,"Owner")=1,1,0),0) -> 1
...

Sheet Purchasing list
A1: Purchasing list — JLCPCB order (one line per part number) and the two owner orders
