Workbook

Sheet Summary
A1: USB DAC + Balanced Headphone Amplifier — Parts List v0.4
A2: Diego Yang · 24 Sep 2026 · after the fifth review round · companion to Design Specification v0.6 and Schematic Design Notes v0.5 · supersedes Parts List v0.3 (kept unchanged) · 80 MHz MCLK, OPA2210 I/V op-amps, break-before-make family oscillators, overload latch, VREF clamp
A4: 5-board sample run — cost gate
A5: Key figure | B5: Value | C5: Unit | D5: Basis
A6: Parts (LCSC tier matching the run quantity) | B6: =Cost!F43 -> 4401.228 | C6: NTD | D6: ="US$ "&TEXT(Cost!E43,"#,##0.00")&"; includes the US$"&TEXT(Cost!B8,"0.00")&" minimum per purchasing line for parts under US$"&TEXT(Cost!B9,"0.00") -> US$ 138.84; includes the US$0.10 minimum per purchasing line for parts under US$0.05
A7: Bare 4-layer PCBs (estimate) | B7: =Cost!F44 -> 317 | C7: NTD | D7: ="US$ "&TEXT(Cost!E44,"#,##0.00")&" for "&TEXT(Cost!B6,"0")&" boards" -> US$ 10.00 for 5 boards
A8: JLCPCB Economic PCBA fees | B8: =Cost!F45 -> 3517.5588 | C8: NTD | D8: ="US$ "&TEXT(Cost!E45,"#,##0.00")&"; itemised on the Cost sheet" -> US$ 110.96; itemised on the Cost sheet
A9: Total, 5-board run | B9: =Cost!F46 -> 8235.7868 | C9: NTD | D9: ="US$ "&TEXT(Cost!E46,"#,##0.00")&" at "&TEXT(Cost!B5,"0.0")&" NTD per US$" -> US$ 259.80 at 31.7 NTD per US$
A10: Per board | B10: =Cost!F47 -> 1647.1574 | C10: NTD | D10: ="US$ "&TEXT(Cost!E47,"#,##0.00")&" per board — the cost-gate figure" -> US$ 51.96 per board — the cost-gate figure
A11: Target per board | B11: =Cost!F48 -> 1500 | C11: NTD | D11: =TEXT(Cost!B10*Cost!B6,"#,##0")&" NTD for "&TEXT(Cost!B6,"0")&" boards; WARNING above; incl. bare PCBs and assembly fees; excl. shipping, import tax, programmers, enclosure, proof-of-concept hardware and a possible assembly-fixture fee" -> 7,500 NTD for 5 boards; WARNING above; incl. bare PCBs and assembly fees; excl. shipping, import tax, programmers, enclosure, proof-of-concept hardware and a possible assembly-fixture fee
A12: Ceiling per board (hard order gate) | B12: =Cost!F49 -> 1700 | C12: NTD | D12: ="Ceiling "&TEXT(Cost!B11,"#,##0")&" NTD per board, set when the third oscillator was added; on 24 Sep 2026 the owner confirmed the budget is flexible as long as it does not surge; the actual JLCPCB quote from the real BOM/CPL files must pass the ceiling before ordering; FAIL above" -> Ceiling 1,700 NTD per board, set when the third oscillator was added; on 24 Sep 2026 the owner confirmed the budget is flexible as long as it does not surge; the actual JLCPCB quote from the real BOM/CPL files must pass the ceiling before ordering; FAIL above
A13: Margin to the target | B13: =Cost!F50 -> -147.15736 | C13: NTD per board | D13: =Cost!G50 -> 147 NTD over the target (9.8%)
A14: Margin to the ceiling | B14: =Cost!F51 -> 52.84264 | C14: NTD per board | D14: =Cost!G51 -> 53 NTD under the ceiling
A15: Cost-gate status | B15: =Cost!F52 -> WARNING | D15: =Cost!G52 -> PASS ≤ 1,500 NTD per board (target); WARNING ≤ 1,700 (ceiling, hard order gate); FAIL > 1,700
A16: Without the conservative fee items | B16: =Cost!F58 -> 1549.7116 | C16: NTD per board | D16: ="through-hole Extended fee "&TEXT(Cost!F56,"+0.0;-0.0")&" NTD and X-ray of the "&TEXT(Cost!B23,"0")&" oscillators "&IF(Cost!B23=0,"+0.0",TEXT(Cost!F57/Cost!B23,"+0.0;-0.0"))&" NTD each, per board, all counted above; the JLCPCB quote after layout decides" -> through-hole Extended fee -19.5 NTD and X-ray of the 3 oscillators -26.0 NTD each, per board, all counted above; the JLCPCB quote after layout decides
A17: Self-checks | B17: =Checks!F32 -> ALL OK — target WARNING | D17: ="Checks sheet: counts, LCSC / class rule, cross-sheet totals, the "&TEXT(Checks!B23,"#,##0")&" NTD result and the gate rule" -> Checks sheet: counts, LCSC / class rule, cross-sheet totals, the 1,647 NTD result and the gate rule
A19: Counts
A20: Count | B20: Value | C20: Unit | D20: Basis
A21: BOM lines | B21: =COUNTA('Parts list'!$B$4:$B$133) -> 130 | C21: lines | D21: every component of every circuit, one part per line
A22: Fitted lines | B22: =Cost!B14 -> 122 | C22: lines | D22: ="Fit = Yes, including the bare-PCB row; DNF: "&TEXT(COUNTIF('Parts list'!$K$4:$K$133,"DNF"),"0")&" lines (U205, R215, R703, J703)" -> Fit = Yes, including the bare-PCB row; DNF: 4 lines (U205, R215, R703, J703)
A23: Purchase lines | B23: =COUNTA('Purchasing list'!$C$4:$C$51) -> 48 | C23: lines | D23: one per LCSC number
A24: SMT-placed parts per board | B24: =Cost!B15 -> 231 | C24: parts | D24: ="plus "&TEXT(Cost!B16,"0")&" through-hole part (4.4 mm jack J701)" -> plus 1 through-hole part (4.4 mm jack J701)
A25: Extended part types | B25: =Cost!B17 -> 19 | C25: types | D25: ="US$"&TEXT(Cost!C35,"0.00")&" each on the sample run; includes the through-hole jack and X202 (class assumed Extended)" -> US$3.07 each on the sample run; includes the through-hole jack and X202 (class assumed Extended)
A26: Basic part types | B26: =Cost!B18 -> 29 | C26: types | D26: no per-type fee; every class is taken from its JLCPCB part page or the JLCPCB basic-parts list, except X202, whose class is not shown on its JLCPCB page (assumed Extended)
A27: SMT joints per board | B27: =Cost!B20 -> 690 | C27: joints | D27: Qty × SMT joints per part, fitted lines
A28: Through-hole joints per board | B28: =Cost!B21 -> 7 | C28: joints | D28: 4.4 mm jack, hand-soldered
A29: Leadless (X-ray) parts per board | B29: =Cost!B22 -> 8 | C29: parts | D29: CPLD, ES9018K2M, 2 × OPA1622, LM27762, three oscillators (80 / 24.576 / 22.5792 MHz)
A31: Reference only — 100-unit build
A32: Key figure | B32: Value | C32: Unit | D32: Basis
A33: Total per board, 100-unit build | B33: =Cost!F79 -> 798.52934 | C33: NTD | D33: ="JLCPCB Standard PCBA, parts at the 100-board tier; US$ "&TEXT(Cost!E79,"#,##0.00")&" per board — not the budget basis" -> JLCPCB Standard PCBA, parts at the 100-board tier; US$ 25.19 per board — not the budget basis
A35: Parts cost per board by block (sample-run tier prices)
A36: Block | B36: US$ per board | C36: NTD per board | D36: Main cost items
A37: 1 USB-C input and sensing | B37: {=SUMPRODUCT(('Parts list'!$A$4:$A$133=$A37)*('Parts list'!$K$4:$K$133="Yes")*('Parts list'!$B$4:$B$133<>"PCB")*'Parts list'!$C$4:$C$133*'Parts list'!$O$4:$O$133)} -> 0.3064 | C37: =B37*Cost!$B$5 -> 9.71288 | D37: SHOU HAN USB-C receptacle, USBLC6-2SC6 ESD array, CC / VBUS sensing resistors
A38: 2 USB audio bridge (CH32V307 + CPLD) | B38: {=SUMPRODUCT(('Parts list'!$A$4:$A$133=$A38)*('Parts list'!$K$4:$K$133="Yes")*('Parts list'!$B$4:$B$133<>"PCB")*'Parts list'!$C$4:$C$133*'Parts list'!$O$4:$O$133)} -> 7.3751 | C38: =B38*Cost!$B$5 -> 233.79067 | D38: CH32V307RCT6, AGRV2KQ32 CPLD, three oscillators, 8 MHz 5032 crystal
A39: 3 DAC (ES9018K2M) and its supplies | B39: {=SUMPRODUCT(('Parts list'!$A$4:$A$133=$A39)*('Parts list'!$K$4:$K$133="Yes")*('Parts list'!$B$4:$B$133<>"PCB")*'Parts list'!$C$4:$C$133*'Parts list'!$O$4:$O$133)} -> 3.8169 | C39: =B39*Cost!$B$5 -> 120.99573 | D39: ES9018K2M, LP5907-3.3, ME6216A13M3G 1.3 V LDO
A40: 4 I/V converters and output legs | B40: {=SUMPRODUCT(('Parts list'!$A$4:$A$133=$A40)*('Parts list'!$K$4:$K$133="Yes")*('Parts list'!$B$4:$B$133<>"PCB")*'Parts list'!$C$4:$C$133*'Parts list'!$O$4:$O$133)} -> 6.3712 | C40: =B40*Cost!$B$5 -> 201.96704 | D40: 2 × OPA2210 I/V converters, 2 × OPA1622, 16 × 2.00 kΩ 0.1 % resistors
A41: 5 Power: domains, current limit and ±3.8 V rails | B41: {=SUMPRODUCT(('Parts list'!$A$4:$A$133=$A41)*('Parts list'!$K$4:$K$133="Yes")*('Parts list'!$B$4:$B$133<>"PCB")*'Parts list'!$C$4:$C$133*'Parts list'!$O$4:$O$133)} -> 2.0087 | C41: =B41*Cost!$B$5 -> 63.67579 | D41: TPS2553 current limit, LM27762 +3.78 V / −3.72 V, 2 × ME6211C33
A42: 6 Protection and control | B42: {=SUMPRODUCT(('Parts list'!$A$4:$A$133=$A42)*('Parts list'!$K$4:$K$133="Yes")*('Parts list'!$B$4:$B$133<>"PCB")*'Parts list'!$C$4:$C$133*'Parts list'!$O$4:$O$133)} -> 0.4444 | C42: =B42*Cost!$B$5 -> 14.08748 | D42: LM393 window comparator, ten 2N7002 fault latch (Q601–Q610), BAV99 diode-OR
A43: 7 Outputs, indicators, test, board | B43: {=SUMPRODUCT(('Parts list'!$A$4:$A$133=$A43)*('Parts list'!$K$4:$K$133="Yes")*('Parts list'!$B$4:$B$133<>"PCB")*'Parts list'!$C$4:$C$133*'Parts list'!$O$4:$O$133)} -> 7.2655 | C43: =B43*Cost!$B$5 -> 230.31635 | D43: ="4.4 mm jack J701 ("&TEXT(SUMIFS('Parts list'!$O$4:$O$133,'Parts list'!$B$4:$B$133,"J701")*Cost!$B$5,"#,##0")&" NTD), 3.5 mm jack, ESD diodes, LEDs" -> 4.4 mm jack J701 (218 NTD), 3.5 mm jack, ESD diodes, LEDs
A44: Minimum-spend allowance (purchasing lines under US$0.05) | B44: =Cost!B26/Cost!B6 -> 0.1798 | C44: =B44*Cost!$B$5 -> 5.69966 | D44: ="US$"&TEXT(Cost!B8,"0.00")&" minimum per purchasing line, spread over "&TEXT(Cost!B6,"0")&" boards" -> US$0.10 minimum per purchasing line, spread over 5 boards
...

Sheet Parts list
A1: Parts list — every BOM line, grouped by block
A2: One part per line; every fitted part has an LCSC number; every line’s JLCPCB class is taken from its JLCPCB part page or the JLCPCB basic-parts list, except X202, whose class is not shown on its JLCPCB page (assumed Extended). Unit prices in US$ at the LCSC tier matching the sample-run quantity (the OPA2210 at its JLCPCB part-page price, see its note) and at the 100-board tier (reference). Line costs here are before the US$0.10 minimum, which is applied per purchasing line on the Purchasing list. Helper columns V–W count distinct part types by LCSC number.
A3: Block | B3: Designators | C3: Qty per board | D3: Description | E3: Value | F3: Package | G3: Rating / tolerance | H3: Part number (MPN) | I3: LCSC no. | J3: JLCPCB library type | K3: Fit | L3: Leadless (X-ray) | M3: SMT joints per part | N3: Through-hole joints per part | O3: Unit price US$ (sample-run tier) | P3: Unit price US$ (100-board tier) | Q3: Price basis | R3: Qty for 5-board run | S3: Line cost US$, 5-board run (before the minimum) | T3: Line cost US$, 100-board run (reference) | U3: Notes | V3: Part-type key (helper) | W3: New part type (helper)
A4: 1 USB-C input and sensing | B4: J101 | C4: 1 | D4: USB-C receptacle, 16-pin, USB 2.0 (data + 5 V), sink | E4: — | F4: SMD, right angle | G4: 5 V, 3 A | H4: SHOU HAN TYPE-C 16PIN 2MD(073) | I4: C2765186 | J4: Extended | K4: Yes | M4: 20 | N4: 0 | O4: 0.1 | P4: 0.0604 | Q4: Quote | R4: =IF($K4="Yes",$C4*Cost!$B$6,0) -> 5 | S4: =IF($K4="Yes",$C4*Cost!$B$6*$O4,0) -> 0.5 | T4: =IF($K4="Yes",$C4*Cost!$B$7*$P4,0) -> 6.04 | V4: =IF(AND($K4="Yes",$B4<>"PCB",LEFT($I4,1)="C"),$I4,"") -> C2765186 | W4: =IF($V4="",0,IF(COUNTIF($V$4:$V4,$V4)=1,1,0)) -> 1
A5: 1 USB-C input and sensing | B5: R101, R102 | C5: 2 | D5: CC1/CC2 pull-down Rd (USB-C sink) | E5: 5.1 kΩ | F5: 0402 | G5: 1 % | H5: UNI-ROYAL 0402WGF5101TCE | I5: C25905 | J5: Basic | K5: Yes | M5: 2 | N5: 0 | O5: 0.002 | P5: 0.0005 | Q5: Quote | R5: =IF($K5="Yes",$C5*Cost!$B$6,0) -> 10 | S5: =IF($K5="Yes",$C5*Cost!$B$6*$O5,0) -> 0.02 | T5: =IF($K5="Yes",$C5*Cost!$B$7*$P5,0) -> 0.1 | V5: =IF(AND($K5="Yes",$B5<>"PCB",LEFT($I5,1)="C"),$I5,"") -> C25905 | W5: =IF($V5="",0,IF(COUNTIF($V$4:$V5,$V5)=1,1,0)) -> 1
A6: 1 USB-C input and sensing | B6: R103, R104 | C6: 2 | D6: CC1/CC2 → MCU ADC series (reads the Type-C current advertisement; does not load CC) | E6: 10 kΩ | F6: 0402 | G6: 1 % | H6: UNI-ROYAL 0402WGF1002TCE | I6: C25744 | J6: Basic | K6: Yes | M6: 2 | N6: 0 | O6: 0.002 | P6: 0.0005 | Q6: Quote | R6: =IF($K6="Yes",$C6*Cost!$B$6,0) -> 10 | S6: =IF($K6="Yes",$C6*Cost!$B$6*$O6,0) -> 0.02 | T6: =IF($K6="Yes",$C6*Cost!$B$7*$P6,0) -> 0.1 | V6: =IF(AND($K6="Yes",$B6<>"PCB",LEFT($I6,1)="C"),$I6,"") -> C25744 | W6: =IF($V6="",0,IF(COUNTIF($V$4:$V6,$V6)=1,1,0)) -> 1
A7: 1 USB-C input and sensing | B7: R105 | C7: 1 | D7: VBUS sense divider, top (→ MCU ADC with analog watchdog) | E7: 100 kΩ | F7: 0402 | G7: 1 % | H7: UNI-ROYAL 0402WGF1003TCE | I7: C25741 | J7: Basic | K7: Yes | M7: 2 | N7: 0 | O7: 0.002 | P7: 0.0005 | Q7: Quote | R7: =IF($K7="Yes",$C7*Cost!$B$6,0) -> 5 | S7: =IF($K7="Yes",$C7*Cost!$B$6*$O7,0) -> 0.01 | T7: =IF($K7="Yes",$C7*Cost!$B$7*$P7,0) -> 0.05 | V7: =IF(AND($K7="Yes",$B7<>"PCB",LEFT($I7,1)="C"),$I7,"") -> C25741 | W7: =IF($V7="",0,IF(COUNTIF($V$4:$V7,$V7)=1,1,0)) -> 1
A8: 1 USB-C input and sensing | B8: R106 | C8: 1 | D8: VBUS sense divider, bottom (5.0 V → 1.60 V) | E8: 47 kΩ | F8: 0402 | G8: 1 % | H8: UNI-ROYAL 0402WGF4702TCE | I8: C25792 | J8: Basic | K8: Yes | M8: 2 | N8: 0 | O8: 0.002 | P8: 0.0005 | Q8: Quote | R8: =IF($K8="Yes",$C8*Cost!$B$6,0) -> 5 | S8: =IF($K8="Yes",$C8*Cost!$B$6*$O8,0) -> 0.01 | T8: =IF($K8="Yes",$C8*Cost!$B$7*$P8,0) -> 0.05 | V8: =IF(AND($K8="Yes",$B8<>"PCB",LEFT($I8,1)="C"),$I8,"") -> C25792 | W8: =IF($V8="",0,IF(COUNTIF($V$4:$V8,$V8)=1,1,0)) -> 1
A9: 1 USB-C input and sensing | B9: R107 | C9: 1 | D9: Shield to GND bleed | E9: 1 MΩ | F9: 0402 | G9: 1 % | H9: UNI-ROYAL 0402WGF1004TCE | I9: C26083 | J9: Basic | K9: Yes | M9: 2 | N9: 0 | O9: 0.002 | P9: 0.0005 | Q9: Quote | R9: =IF($K9="Yes",$C9*Cost!$B$6,0) -> 5 | S9: =IF($K9="Yes",$C9*Cost!$B$6*$O9,0) -> 0.01 | T9: =IF($K9="Yes",$C9*Cost!$B$7*$P9,0) -> 0.05 | V9: =IF(AND($K9="Yes",$B9<>"PCB",LEFT($I9,1)="C"),$I9,"") -> C26083 | W9: =IF($V9="",0,IF(COUNTIF($V$4:$V9,$V9)=1,1,0)) -> 1
A10: 1 USB-C input and sensing | B10: C101 | C10: 1 | D10: Shield to GND (RF) | E10: 4.7 nF | F10: 0402 | G10: 50 V X7R | H10: FH 0402B472K500NT | I10: C1538 | J10: Basic | K10: Yes | M10: 2 | N10: 0 | O10: 0.002 | P10: 0.0006 | Q10: Quote | R10: =IF($K10="Yes",$C10*Cost!$B$6,0) -> 5 | S10: =IF($K10="Yes",$C10*Cost!$B$6*$O10,0) -> 0.01 | T10: =IF($K10="Yes",$C10*Cost!$B$7*$P10,0) -> 0.06 | V10: =IF(AND($K10="Yes",$B10<>"PCB",LEFT($I10,1)="C"),$I10,"") -> C1538 | W10: =IF($V10="",0,IF(COUNTIF($V$4:$V10,$V10)=1,1,0)) -> 1
A11: 1 USB-C input and sensing | B11: U101 | C11: 1 | D11: ESD array, D+, D−, VBUS | E11: — | F11: SOT-23-6 | G11: 5.25 V, 3.5 pF | H11: ST USBLC6-2SC6 | I11: C7519 | J11: Extended | K11: Yes | M11: 6 | N11: 0 | O11: 0.1844 | P11: 0.1439 | Q11: Quote | R11: =IF($K11="Yes",$C11*Cost!$B$6,0) -> 5 | S11: =IF($K11="Yes",$C11*Cost!$B$6*$O11,0) -> 0.922 | T11: =IF($K11="Yes",$C11*Cost!$B$7*$P11,0) -> 14.39 | V11: =IF(AND($K11="Yes",$B11<>"PCB",LEFT($I11,1)="C"),$I11,"") -> C7519 | W11: =IF($V11="",0,IF(COUNTIF($V$4:$V11,$V11)=1,1,0)) -> 1
A12: 1 USB-C input and sensing | B12: C102 | C12: 1 | D12: VBUS at the connector (VBUS capacitance before any switch: 5 × 1 µF) | E12: 1 µF | F12: 0603 | G12: 25 V X5R | H12: Samsung CL10A105KB8NNNC | I12: C15849 | J12: Basic | K12: Yes | M12: 2 | N12: 0 | O12: 0.006 | P12: 0.0022 | Q12: Quote | R12: =IF($K12="Yes",$C12*Cost!$B$6,0) -> 5 | S12: =IF($K12="Yes",$C12*Cost!$B$6*$O12,0) -> 0.03 | T12: =IF($K12="Yes",$C12*Cost!$B$7*$P12,0) -> 0.22 | V12: =IF(AND($K12="Yes",$B12<>"PCB",LEFT($I12,1)="C"),$I12,"") -> C15849 | W12: =IF($V12="",0,IF(COUNTIF($V$4:$V12,$V12)=1,1,0)) -> 1
A13: 2 USB audio bridge (CH32V307 + CPLD) | B13: U201 | C13: 1 | D13: MCU, RISC-V, USB 2.0 High-Speed with built-in PHY; own USB Audio Class 2.0 firmware | E13: — | F13: LQFP-64 10 × 10 mm | G13: 144 MHz, 3.3 V | H13: WCH CH32V307RCT6 | I13: C2988083 | J13: Extended | K13: Yes | M13: 64 | N13: 0 | O13: 3.45 | P13: 2.33 | Q13: Quote | R13: =IF($K13="Yes",$C13*Cost!$B$6,0) -> 5 | S13: =IF($K13="Yes",$C13*Cost!$B$6*$O13,0) -> 17.25 | T13: =IF($K13="Yes",$C13*Cost!$B$7*$P13,0) -> 233 | U13: LCSC stock 119: reserve before ordering | V13: =IF(AND($K13="Yes",$B13<>"PCB",LEFT($I13,1)="C"),$I13,"") -> C2988083 | W13: =IF($V13="",0,IF(COUNTIF($V$4:$V13,$V13)=1,1,0)) -> 1
A14: 2 USB audio bridge (CH32V307 + CPLD) | B14: Y201 | C14: 1 | D14: Crystal, CH32V307 HSE 8 MHz (firmware: HSE ÷ 2 = 4 MHz USB HS PLL reference) | E14: 8 MHz | F14: 5.0 × 3.2 mm, 2-pad | G14: ±10 ppm, CL 20 pF | H14: YXC X50328MSB2GI | I14: C115962 | J14: Basic | K14: Yes | M14: 2 | N14: 0 | O14: 0.2452 | P14: 0.2 | Q14: Quote | R14: =IF($K14="Yes",$C14*Cost!$B$6,0) -> 5 | S14: =IF($K14="Yes",$C14*Cost!$B$6*$O14,0) -> 1.226 | T14: =IF($K14="Yes",$C14*Cost!$B$7*$P14,0) -> 20 | U14: No Basic 3.2 × 2.5 mm 8 MHz crystal exists; 5032 used | V14: =IF(AND($K14="Yes",$B14<>"PCB",LEFT($I14,1)="C"),$I14,"") -> C115962 | W14: =IF($V14="",0,IF(COUNTIF($V$4:$V14,$V14)=1,1,0)) -> 1
A15: 2 USB audio bridge (CH32V307 + CPLD) | B15: C201, C202 | C15: 2 | D15: Crystal load capacitors (CL 20 pF crystal: 2 × (20 − ≈3.5 pF stray) ≈ 33 pF) | E15: 33 pF | F15: 0402 | G15: 50 V C0G | H15: FH 0402CG330J500NT | I15: C1562 | J15: Basic | K15: Yes | M15: 2 | N15: 0 | O15: 0.002 | P15: 0.0006 | Q15: Quote | R15: =IF($K15="Yes",$C15*Cost!$B$6,0) -> 10 | S15: =IF($K15="Yes",$C15*Cost!$B$6*$O15,0) -> 0.02 | T15: =IF($K15="Yes",$C15*Cost!$B$7*$P15,0) -> 0.12 | V15: =IF(AND($K15="Yes",$B15<>"PCB",LEFT($I15,1)="C"),$I15,"") -> C1562 | W15: =IF($V15="",0,IF(COUNTIF($V$4:$V15,$V15)=1,1,0)) -> 1
A16: 2 USB audio bridge (CH32V307 + CPLD) | B16: C203–C210 | C16: 8 | D16: CH32V307 VDD/VDDA/VIO decoupling, one per supply pin | E16: 100 nF | F16: 0402 | G16: 16 V X7R | H16: Samsung CL05B104KO5NNNC | I16: C1525 | J16: Basic | K16: Yes | M16: 2 | N16: 0 | O16: 0.003 | P16: 0.0011 | Q16: Quote | R16: =IF($K16="Yes",$C16*Cost!$B$6,0) -> 40 | S16: =IF($K16="Yes",$C16*Cost!$B$6*$O16,0) -> 0.12 | T16: =IF($K16="Yes",$C16*Cost!$B$7*$P16,0) -> 0.88 | V16: =IF(AND($K16="Yes",$B16<>"PCB",LEFT($I16,1)="C"),$I16,"") -> C1525 | W16: =IF($V16="",0,IF(COUNTIF($V$4:$V16,$V16)=1,1,0)) -> 1
A17: 2 USB audio bridge (CH32V307 + CPLD) | B17: C211 | C17: 1 | D17: CH32V307 3V3M bulk (2.2 µF keeps the attach inrush charge ≈ 38 µC) | E17: 2.2 µF | F17: 0402 | G17: 6.3 V X5R | H17: Samsung CL05A225MQ5NSNC | I17: C12530 | J17: Basic | K17: Yes | M17: 2 | N17: 0 | O17: 0.005 | P17: 0.0019 | Q17: Quote | R17: =IF($K17="Yes",$C17*Cost!$B$6,0) -> 5 | S17: =IF($K17="Yes",$C17*Cost!$B$6*$O17,0) -> 0.025 | T17: =IF($K17="Yes",$C17*Cost!$B$7*$P17,0) -> 0.19 | V17: =IF(AND($K17="Yes",$B17<>"PCB",LEFT($I17,1)="C"),$I17,"") -> C12530 | W17: =IF($V17="",0,IF(COUNTIF($V$4:$V17,$V17)=1,1,0)) -> 1
A18: 2 USB audio bridge (CH32V307 + CPLD) | B18: R201 | C18: 1 | D18: NRST pull-up | E18: 10 kΩ | F18: 0402 | G18: 1 % | H18: UNI-ROYAL 0402WGF1002TCE | I18: C25744 | J18: Basic | K18: Yes | M18: 2 | N18: 0 | O18: 0.002 | P18: 0.0005 | Q18: Quote | R18: =IF($K18="Yes",$C18*Cost!$B$6,0) -> 5 | S18: =IF($K18="Yes",$C18*Cost!$B$6*$O18,0) -> 0.01 | T18: =IF($K18="Yes",$C18*Cost!$B$7*$P18,0) -> 0.05 | V18: =IF(AND($K18="Yes",$B18<>"PCB",LEFT($I18,1)="C"),$I18,"") -> C25744 | W18: =IF($V18="",0,IF(COUNTIF($V$4:$V18,$V18)=1,1,0)) -> 0
A19: 2 USB audio bridge (CH32V307 + CPLD) | B19: C212 | C19: 1 | D19: NRST filter | E19: 100 nF | F19: 0402 | G19: 16 V X7R | H19: Samsung CL05B104KO5NNNC | I19: C1525 | J19: Basic | K19: Yes | M19: 2 | N19: 0 | O19: 0.003 | P19: 0.0011 | Q19: Quote | R19: =IF($K19="Yes",$C19*Cost!$B$6,0) -> 5 | S19: =IF($K19="Yes",$C19*Cost!$B$6*$O19,0) -> 0.015 | T19: =IF($K19="Yes",$C19*Cost!$B$7*$P19,0) -> 0.11 | V19: =IF(AND($K19="Yes",$B19<>"PCB",LEFT($I19,1)="C"),$I19,"") -> C1525 | W19: =IF($V19="",0,IF(COUNTIF($V$4:$V19,$V19)=1,1,0)) -> 0
A20: 2 USB audio bridge (CH32V307 + CPLD) | B20: R202 | C20: 1 | D20: BOOT0 pull-down | E20: 10 kΩ | F20: 0402 | G20: 1 % | H20: UNI-ROYAL 0402WGF1002TCE | I20: C25744 | J20: Basic | K20: Yes | M20: 2 | N20: 0 | O20: 0.002 | P20: 0.0005 | Q20: Quote | R20: =IF($K20="Yes",$C20*Cost!$B$6,0) -> 5 | S20: =IF($K20="Yes",$C20*Cost!$B$6*$O20,0) -> 0.01 | T20: =IF($K20="Yes",$C20*Cost!$B$7*$P20,0) -> 0.05 | V20: =IF(AND($K20="Yes",$B20<>"PCB",LEFT($I20,1)="C"),$I20,"") -> C25744 | W20: =IF($V20="",0,IF(COUNTIF($V$4:$V20,$V20)=1,1,0)) -> 0
A21: 2 USB audio bridge (CH32V307 + CPLD) | B21: U202 | C21: 1 | D21: CPLD, 2K LUT: FIFO and I²S master; 80 MHz system clock; PLL ×2 on the selected family oscillator (45.1584 / 49.152 MHz), exact integer division to BCLK/LRCLK for all 8 rates; drives the two oscillator enables (break-before-make) | E21: — | F21: QFN-32 4 × 4 mm | G21: 3.3 V | H21: AGM AGRV2KQ32 | I21: C18208899 | J21: Extended | K21: Yes | L21: Yes | M21: 33 | N21: 0 | O21: 1.6503 | P21: 1.11 | Q21: Quote | R21: =IF($K21="Yes",$C21*Cost!$B$6,0) -> 5 | S21: =IF($K21="Yes",$C21*Cost!$B$6*$O21,0) -> 8.2515 | T21: =IF($K21="Yes",$C21*Cost!$B$7*$P21,0) -> 111 | U21: LCSC stock 980 | V21: =IF(AND($K21="Yes",$B21<>"PCB",LEFT($I21,1)="C"),$I21,"") -> C18208899 | W21: =IF($V21="",0,IF(COUNTIF($V$4:$V21,$V21)=1,1,0)) -> 1
A22: 2 USB audio bridge (CH32V307 + CPLD) | B22: C213–C216 | C22: 4 | D22: CPLD decoupling | E22: 100 nF | F22: 0402 | G22: 16 V X7R | H22: Samsung CL05B104KO5NNNC | I22: C1525 | J22: Basic | K22: Yes | M22: 2 | N22: 0 | O22: 0.003 | P22: 0.0011 | Q22: Quote | R22: =IF($K22="Yes",$C22*Cost!$B$6,0) -> 20 | S22: =IF($K22="Yes",$C22*Cost!$B$6*$O22,0) -> 0.06 | T22: =IF($K22="Yes",$C22*Cost!$B$7*$P22,0) -> 0.44 | V22: =IF(AND($K22="Yes",$B22<>"PCB",LEFT($I22,1)="C"),$I22,"") -> C1525 | W22: =IF($V22="",0,IF(COUNTIF($V$4:$V22,$V22)=1,1,0)) -> 0
A23: 2 USB audio bridge (CH32V307 + CPLD) | B23: X201 | C23: 1 | D23: Oscillator, 80 MHz 3.3 V CMOS: DAC MCLK (asynchronous mode; 208 × 384 kHz > 192 × FSR; 12.5 ns cycle, ≥ 5.6 ns pulse width at 45:55) and the CPLD system clock; tri-state pin 1 tied to 3V3D | E23: 80 MHz | F23: 3.2 × 2.5 mm, 4-pad | G23: ±20 ppm tol., ±30 ppm stab., 40 mA max, duty 45–55 % | H23: SCTF SX3M80.000B20F30TNN | I23: C5179978 | J23: Extended | K23: Yes | L23: Yes | M23: 4 | N23: 0 | O23: 0.8916 | P23: 0.7211 | Q23: Quote | R23: =IF($K23="Yes",$C23*Cost!$B$6,0) -> 5 | S23: =IF($K23="Yes",$C23*Cost!$B$6*$O23,0) -> 4.458 | T23: =IF($K23="Yes",$C23*Cost!$B$7*$P23,0) -> 72.11 | U23: Replaces the 100 MHz part, which sat at the ES9018K2M 10 ns minimum MCLK cycle; LCSC stock 2,503 | V23: =IF(AND($K23="Yes",$B23<>"PCB",LEFT($I23,1)="C"),$I23,"") -> C5179978 | W23: =IF($V23="",0,IF(COUNTIF($V$4:$V23,$V23)=1,1,0)) -> 1
A24: 2 USB audio bridge (CH32V307 + CPLD) | B24: X202 | C24: 1 | D24: Oscillator, 24.576 MHz 3.3 V CMOS, tri-state enable on pin 1: 48 kHz rate family (OSC48_EN; off by default through R212; shared node into the CPLD PLL, ×2 = 49.152 MHz) | E24: 24.576 MHz | F24: 3.2 × 2.5 mm, 4-pad | G24: ±10 ppm tol., ±20 ppm stab., 1.8–3.3 V | H24: YXC OT322524.576MJBA4SL | I24: C2831388 | J24: Extended | K24: Yes | L24: Yes | M24: 4 | N24: 0 | O24: 0.5075 | P24: 0.2907 | Q24: Quote | R24: =IF($K24="Yes",$C24*Cost!$B$6,0) -> 5 | S24: =IF($K24="Yes",$C24*Cost!$B$6*$O24,0) -> 2.5375 | T24: =IF($K24="Yes",$C24*Cost!$B$7*$P24,0) -> 29.07 | U24: Class assumed Extended (not shown on the JLCPCB page); LCSC stock 1,755; JLCPCB page notes an assembly fixture may be needed (check the quote) | V24: =IF(AND($K24="Yes",$B24<>"PCB",LEFT($I24,1)="C"),$I24,"") -> C2831388 | W24: =IF($V24="",0,IF(COUNTIF($V$4:$V24,$V24)=1,1,0)) -> 1
A25: 2 USB audio bridge (CH32V307 + CPLD) | B25: X203 | C25: 1 | D25: Oscillator, 22.5792 MHz 1.62–3.63 V CMOS, tri-state pin 1 (SCTF 2CM datasheet: enabled when high or open, disabled when low; start-up ≤ 5 ms): 44.1 kHz rate family (OSC44_EN; off by default through R213; shared node into the CPLD PLL, ×2 = 45.1584 MHz) | E25: 22.5792 MHz | F25: 2.5 × 2.0 mm, 4-pad | G25: ±20 ppm tol., ±30 ppm stab., 10 mA max | H25: SCTF SX2M22.5792M20F30TNN | I25: C5452663 | J25: Extended | K25: Yes | L25: Yes | M25: 4 | N25: 0 | O25: 0.5455 | P25: 0.3085 | Q25: Quote | R25: =IF($K25="Yes",$C25*Cost!$B$6,0) -> 5 | S25: =IF($K25="Yes",$C25*Cost!$B$6*$O25,0) -> 2.7275 | T25: =IF($K25="Yes",$C25*Cost!$B$7*$P25,0) -> 30.85 | U25: JLCPCB class Extended (part page); LCSC stock 1,426; datasheet gives no disable time or disabled-output leakage: measured on the proof-of-concept board | V25: =IF(AND($K25="Yes",$B25<>"PCB",LEFT($I25,1)="C"),$I25,"") -> C5452663 | W25: =IF($V25="",0,IF(COUNTIF($V$4:$V25,$V25)=1,1,0)) -> 1
A26: 2 USB audio bridge (CH32V307 + CPLD) | B26: C217–C219 | C26: 3 | D26: Oscillator VDD decoupling (X201, X202, X203) | E26: 100 nF | F26: 0402 | G26: 16 V X7R | H26: Samsung CL05B104KO5NNNC | I26: C1525 | J26: Basic | K26: Yes | M26: 2 | N26: 0 | O26: 0.003 | P26: 0.0011 | Q26: Quote | R26: =IF($K26="Yes",$C26*Cost!$B$6,0) -> 15 | S26: =IF($K26="Yes",$C26*Cost!$B$6*$O26,0) -> 0.045 | T26: =IF($K26="Yes",$C26*Cost!$B$7*$P26,0) -> 0.33 | V26: =IF(AND($K26="Yes",$B26<>"PCB",LEFT($I26,1)="C"),$I26,"") -> C1525 | W26: =IF($V26="",0,IF(COUNTIF($V$4:$V26,$V26)=1,1,0)) -> 0
A27: 2 USB audio bridge (CH32V307 + CPLD) | B27: R212, R213 | C27: 2 | D27: Oscillator enable pull-downs, OSC48_EN (X202) and OSC44_EN (X203): both family oscillators stay off until the CPLD drives one enable (overrides the oscillators’ internal enable pull-ups and any CPLD weak pull-up ≥ 5.1 kΩ) | E27: 2.2 kΩ | F27: 0402 | G27: 1 % | H27: UNI-ROYAL 0402WGF2201TCE | I27: C25879 | J27: Basic | K27: Yes | M27: 2 | N27: 0 | O27: 0.002 | P27: 0.0005 | Q27: Quote | R27: =IF($K27="Yes",$C27*Cost!$B$6,0) -> 10 | S27: =IF($K27="Yes",$C27*Cost!$B$6*$O27,0) -> 0.02 | T27: =IF($K27="Yes",$C27*Cost!$B$7*$P27,0) -> 0.1 | V27: =IF(AND($K27="Yes",$B27<>"PCB",LEFT($I27,1)="C"),$I27,"") -> C25879 | W27: =IF($V27="",0,IF(COUNTIF($V$4:$V27,$V27)=1,1,0)) -> 1
A28: 2 USB audio bridge (CH32V307 + CPLD) | B28: R214 | C28: 1 | D28: Shared family-clock node pull-down (defined low while both family oscillators are off) | E28: 10 kΩ | F28: 0402 | G28: 1 % | H28: UNI-ROYAL 0402WGF1002TCE | I28: C25744 | J28: Basic | K28: Yes | M28: 2 | N28: 0 | O28: 0.002 | P28: 0.0005 | Q28: Quote | R28: =IF($K28="Yes",$C28*Cost!$B$6,0) -> 5 | S28: =IF($K28="Yes",$C28*Cost!$B$6*$O28,0) -> 0.01 | T28: =IF($K28="Yes",$C28*Cost!$B$7*$P28,0) -> 0.05 | V28: =IF(AND($K28="Yes",$B28<>"PCB",LEFT($I28,1)="C"),$I28,"") -> C25744 | W28: =IF($V28="",0,IF(COUNTIF($V$4:$V28,$V28)=1,1,0)) -> 0
A29: 2 USB audio bridge (CH32V307 + CPLD) | B29: U205 | C29: 1 | D29: DNF fallback: 2:1 logic mux in front of the CPLD PLL input (fit U205 + R215 and remove R210/R211); select = OSC44_EN | E29: — | F29: SOT-363 (SC-88) | G29: 1.65–5.5 V | H29: Nexperia 74LVC1G157GW,125 | I29: C135822 | J29: Extended | K29: DNF | M29: 6 | N29: 0 | O29: 0.2106 | P29: 0.1643 | Q29: Quote | R29: =IF($K29="Yes",$C29*Cost!$B$6,0) -> 0 | S29: =IF($K29="Yes",$C29*Cost!$B$6*$O29,0) -> 0 | T29: =IF($K29="Yes",$C29*Cost!$B$7*$P29,0) -> 0 | V29: =IF(AND($K29="Yes",$B29<>"PCB",LEFT($I29,1)="C"),$I29,"") | W29: =IF($V29="",0,IF(COUNTIF($V$4:$V29,$V29)=1,1,0)) -> 0
A30: 2 USB audio bridge (CH32V307 + CPLD) | B30: R215 | C30: 1 | D30: DNF: series termination, mux output to the CPLD PLL input (fitted with U205) | E30: 33 Ω | F30: 0402 | G30: 1 % | H30: UNI-ROYAL 0402WGF330JTCE | I30: C25105 | J30: Basic | K30: DNF | M30: 2 | N30: 0 | O30: 0.002 | P30: 0.0005 | Q30: Quote | R30: =IF($K30="Yes",$C30*Cost!$B$6,0) -> 0 | S30: =IF($K30="Yes",$C30*Cost!$B$6*$O30,0) -> 0 | T30: =IF($K30="Yes",$C30*Cost!$B$7*$P30,0) -> 0 | V30: =IF(AND($K30="Yes",$B30<>"PCB",LEFT($I30,1)="C"),$I30,"") | W30: =IF($V30="",0,IF(COUNTIF($V$4:$V30,$V30)=1,1,0)) -> 0
A31: 2 USB audio bridge (CH32V307 + CPLD) | B31: R203–R206 | C31: 4 | D31: Series termination: MCLK to the DAC, BCLK, LRCLK, SDATA toward the DAC | E31: 33 Ω | F31: 0402 | G31: 1 % | H31: UNI-ROYAL 0402WGF330JTCE | I31: C25105 | J31: Basic | K31: Yes | M31: 2 | N31: 0 | O31: 0.002 | P31: 0.0005 | Q31: Quote | R31: =IF($K31="Yes",$C31*Cost!$B$6,0) -> 20 | S31: =IF($K31="Yes",$C31*Cost!$B$6*$O31,0) -> 0.04 | T31: =IF($K31="Yes",$C31*Cost!$B$7*$P31,0) -> 0.2 | V31: =IF(AND($K31="Yes",$B31<>"PCB",LEFT($I31,1)="C"),$I31,"") -> C25105 | W31: =IF($V31="",0,IF(COUNTIF($V$4:$V31,$V31)=1,1,0)) -> 1
A32: 2 USB audio bridge (CH32V307 + CPLD) | B32: R209 | C32: 1 | D32: Series termination: MCLK branch to the CPLD clock input | E32: 33 Ω | F32: 0402 | G32: 1 % | H32: UNI-ROYAL 0402WGF330JTCE | I32: C25105 | J32: Basic | K32: Yes | M32: 2 | N32: 0 | O32: 0.002 | P32: 0.0005 | Q32: Quote | R32: =IF($K32="Yes",$C32*Cost!$B$6,0) -> 5 | S32: =IF($K32="Yes",$C32*Cost!$B$6*$O32,0) -> 0.01 | T32: =IF($K32="Yes",$C32*Cost!$B$7*$P32,0) -> 0.05 | V32: =IF(AND($K32="Yes",$B32<>"PCB",LEFT($I32,1)="C"),$I32,"") -> C25105 | W32: =IF($V32="",0,IF(COUNTIF($V$4:$V32,$V32)=1,1,0)) -> 0
A33: 2 USB audio bridge (CH32V307 + CPLD) | B33: R210, R211 | C33: 2 | D33: Series termination: X202 and X203 outputs into the shared node at the CPLD PLL clock input | E33: 33 Ω | F33: 0402 | G33: 1 % | H33: UNI-ROYAL 0402WGF330JTCE | I33: C25105 | J33: Basic | K33: Yes | M33: 2 | N33: 0 | O33: 0.002 | P33: 0.0005 | Q33: Quote | R33: =IF($K33="Yes",$C33*Cost!$B$6,0) -> 10 | S33: =IF($K33="Yes",$C33*Cost!$B$6*$O33,0) -> 0.02 | T33: =IF($K33="Yes",$C33*Cost!$B$7*$P33,0) -> 0.1 | V33: =IF(AND($K33="Yes",$B33<>"PCB",LEFT($I33,1)="C"),$I33,"") -> C25105 | W33: =IF($V33="",0,IF(COUNTIF($V$4:$V33,$V33)=1,1,0)) -> 0
A34: 2 USB audio bridge (CH32V307 + CPLD) | B34: R207, R208 | C34: 2 | D34: I²C SCL/SDA pull-ups to 3V3D (off with the DAC domain: no back-powering) | E34: 2.2 kΩ | F34: 0402 | G34: 1 % | H34: UNI-ROYAL 0402WGF2201TCE | I34: C25879 | J34: Basic | K34: Yes | M34: 2 | N34: 0 | O34: 0.002 | P34: 0.0005 | Q34: Quote | R34: =IF($K34="Yes",$C34*Cost!$B$6,0) -> 10 | S34: =IF($K34="Yes",$C34*Cost!$B$6*$O34,0) -> 0.02 | T34: =IF($K34="Yes",$C34*Cost!$B$7*$P34,0) -> 0.1 | V34: =IF(AND($K34="Yes",$B34<>"PCB",LEFT($I34,1)="C"),$I34,"") -> C25879 | W34: =IF($V34="",0,IF(COUNTIF($V$4:$V34,$V34)=1,1,0)) -> 0
A35: 2 USB audio bridge (CH32V307 + CPLD) | B35: J201 | C35: 1 | D35: Pads, CH32V307 2-wire debug (WCH-LinkE): 3V3, SWDIO, SWCLK, GND | E35: — | F35: Pads | G35: — | H35: No part | I35: — | J35: — | K35: No part | M35: 0 | N35: 0 | O35: 0 | P35: 0 | Q35: Estimate | R35: =IF($K35="Yes",$C35*Cost!$B$6,0) -> 0 | S35: =IF($K35="Yes",$C35*Cost!$B$6*$O35,0) -> 0 | T35: =IF($K35="Yes",$C35*Cost!$B$7*$P35,0) -> 0 | V35: =IF(AND($K35="Yes",$B35<>"PCB",LEFT($I35,1)="C"),$I35,"") | W35: =IF($V35="",0,IF(COUNTIF($V$4:$V35,$V35)=1,1,0)) -> 0
A36: 2 USB audio bridge (CH32V307 + CPLD) | B36: J202 | C36: 1 | D36: Pads, CPLD JTAG: 3V3, TCK, TMS, TDI, TDO, GND | E36: — | F36: Pads | G36: — | H36: No part | I36: — | J36: — | K36: No part | M36: 0 | N36: 0 | O36: 0 | P36: 0 | Q36: Estimate | R36: =IF($K36="Yes",$C36*Cost!$B$6,0) -> 0 | S36: =IF($K36="Yes",$C36*Cost!$B$6*$O36,0) -> 0 | T36: =IF($K36="Yes",$C36*Cost!$B$7*$P36,0) -> 0 | V36: =IF(AND($K36="Yes",$B36<>"PCB",LEFT($I36,1)="C"),$I36,"") | W36: =IF($V36="",0,IF(COUNTIF($V$4:$V36,$V36)=1,1,0)) -> 0
A37: 3 DAC (ES9018K2M) and its supplies | B37: U301 | C37: 1 | D37: DAC, 32-bit, PCM to 384 kHz, I²C; asynchronous (DPLL/jitter eliminator) mode; differential current-mode outputs | E37: — | F37: QFN-28 5 × 5 mm | G37: DNR 127 dB-A, THD+N −120 dB (datasheet, current mode) | H37: ESS ES9018K2M | I37: C2688377 | J37: Extended | K37: Yes | L37: Yes | M37: 29 | N37: 0 | O37: 3.4678 | P37: 2.28 | Q37: Quote | R37: =IF($K37="Yes",$C37*Cost!$B$6,0) -> 5 | S37: =IF($K37="Yes",$C37*Cost!$B$6*$O37,0) -> 17.339 | T37: =IF($K37="Yes",$C37*Cost!$B$7*$P37,0) -> 228 | U37: LCSC stock 724 | V37: =IF(AND($K37="Yes",$B37<>"PCB",LEFT($I37,1)="C"),$I37,"") -> C2688377 | W37: =IF($V37="",0,IF(COUNTIF($V$4:$V37,$V37)=1,1,0)) -> 1
A38: 3 DAC (ES9018K2M) and its supplies | B38: U302 | C38: 1 | D38: LDO, quiet 3.3 V for VCCA, AVCC_L, AVCC_R and VREF (3V3A), EN = AVCC_EN | E38: 3.3 V, 250 mA | F38: SOT-23-5 | G38: 6.5 µVrms, ±2 % | H38: TI LP5907MFX-3.3/NOPB | I38: C80670 | J38: Extended | K38: Yes | M38: 5 | N38: 0 | O38: 0.2104 | P38: 0.14 | Q38: Quote | R38: =IF($K38="Yes",$C38*Cost!$B$6,0) -> 5 | S38: =IF($K38="Yes",$C38*Cost!$B$6*$O38,0) -> 1.052 | T38: =IF($K38="Yes",$C38*Cost!$B$7*$P38,0) -> 14 | V38: =IF(AND($K38="Yes",$B38<>"PCB",LEFT($I38,1)="C"),$I38,"") -> C80670 | W38: =IF($V38="",0,IF(COUNTIF($V$4:$V38,$V38)=1,1,0)) -> 1
A39: 3 DAC (ES9018K2M) and its supplies | B39: C301 | C39: 1 | D39: LP5907 input (part of the 5 µF VBUS budget) | E39: 1 µF | F39: 0603 | G39: 25 V X5R | H39: Samsung CL10A105KB8NNNC | I39: C15849 | J39: Basic | K39: Yes | M39: 2 | N39: 0 | O39: 0.006 | P39: 0.0022 | Q39: Quote | R39: =IF($K39="Yes",$C39*Cost!$B$6,0) -> 5 | S39: =IF($K39="Yes",$C39*Cost!$B$6*$O39,0) -> 0.03 | T39: =IF($K39="Yes",$C39*Cost!$B$7*$P39,0) -> 0.22 | V39: =IF(AND($K39="Yes",$B39<>"PCB",LEFT($I39,1)="C"),$I39,"") -> C15849 | W39: =IF($V39="",0,IF(COUNTIF($V$4:$V39,$V39)=1,1,0)) -> 0
A40: 3 DAC (ES9018K2M) and its supplies | B40: C302 | C40: 1 | D40: LP5907 output (LP5907 total output capacitance 5.7 µF ≤ 10 µF) | E40: 1 µF | F40: 0603 | G40: 25 V X5R | H40: Samsung CL10A105KB8NNNC | I40: C15849 | J40: Basic | K40: Yes | M40: 2 | N40: 0 | O40: 0.006 | P40: 0.0022 | Q40: Quote | R40: =IF($K40="Yes",$C40*Cost!$B$6,0) -> 5 | S40: =IF($K40="Yes",$C40*Cost!$B$6*$O40,0) -> 0.03 | T40: =IF($K40="Yes",$C40*Cost!$B$7*$P40,0) -> 0.22 | V40: =IF(AND($K40="Yes",$B40<>"PCB",LEFT($I40,1)="C"),$I40,"") -> C15849 | W40: =IF($V40="",0,IF(COUNTIF($V$4:$V40,$V40)=1,1,0)) -> 0
...

Sheet Purchasing list
A1: Purchasing list — one line per LCSC number (fitted parts)
A2: Qty per board is summed from the Parts list by LCSC number. Line cost = qty for the run × sample-run-tier price, with a US$0.10 minimum per line for parts under US$0.05 (inputs on the Cost sheet); the Cost sheet takes the parts cost from this list. The bare PCBs are costed on the Cost sheet.
A3: Item | B3: Part type | C3: Part number (MPN) | D3: Value | E3: Package | F3: Rating / tolerance | G3: LCSC no. | H3: JLCPCB library type | I3: Designators | J3: Qty per board | K3: Qty for 5-board run | L3: Unit price US$ (sample-run tier) | M3: Unit price US$ (100-board tier) | N3: Leadless (X-ray) | O3: Minimum applies (< US$0.05) | P3: Line cost US$, 5-board run (incl. minimum) | Q3: Ext. per board US$ (100-board tier)
A4: 1 | B4: Connector | C4: G-Switch GT-3321667P-01 | D4: — | E4: Through-hole | F4: Gold-plated | G4: C2762984 | H4: Extended | I4: J701 | J4: =SUMIFS('Parts list'!$C$4:$C$133,'Parts list'!$I$4:$I$133,$G4,'Parts list'!$K$4:$K$133,"Yes") -> 1 | K4: =$J4*Cost!$B$6 -> 5 | L4: 6.8656 | M4: 4.7574 | O4: =IF(AND($L4>0,$L4<Cost!$B$9),"Yes","") | P4: =IF($O4="Yes",MAX($K4*$L4,Cost!$B$8),$K4*$L4) -> 34.328 | Q4: =$J4*$M4 -> 4.7574
A5: 2 | B5: IC | C5: TI OPA1622IDRCR | D5: — | E5: VSON-10 3 × 3 mm | F5: Isc +145/−130 mA typ; thermal pad to V− | G5: C2876559 | H5: Extended | I5: U401, U402 | J5: =SUMIFS('Parts list'!$C$4:$C$133,'Parts list'!$I$4:$I$133,$G5,'Parts list'!$K$4:$K$133,"Yes") -> 2 | K5: =$J5*Cost!$B$6 -> 10 | L5: 1.7871 | M5: 1.6912 | N5: Yes | O5: =IF(AND($L5>0,$L5<Cost!$B$9),"Yes","") | P5: =IF($O5="Yes",MAX($K5*$L5,Cost!$B$8),$K5*$L5) -> 17.871 | Q5: =$J5*$M5 -> 3.3824
A6: 3 | B6: IC | C6: ESS ES9018K2M | D6: — | E6: QFN-28 5 × 5 mm | F6: DNR 127 dB-A, THD+N −120 dB (datasheet, current mode) | G6: C2688377 | H6: Extended | I6: U301 | J6: =SUMIFS('Parts list'!$C$4:$C$133,'Parts list'!$I$4:$I$133,$G6,'Parts list'!$K$4:$K$133,"Yes") -> 1 | K6: =$J6*Cost!$B$6 -> 5 | L6: 3.4678 | M6: 2.28 | N6: Yes | O6: =IF(AND($L6>0,$L6<Cost!$B$9),"Yes","") | P6: =IF($O6="Yes",MAX($K6*$L6,Cost!$B$8),$K6*$L6) -> 17.339 | Q6: =$J6*$M6 -> 2.28
A7: 4 | B7: IC | C7: WCH CH32V307RCT6 | D7: — | E7: LQFP-64 10 × 10 mm | F7: 144 MHz, 3.3 V | G7: C2988083 | H7: Extended | I7: U201 | J7: =SUMIFS('Parts list'!$C$4:$C$133,'Parts list'!$I$4:$I$133,$G7,'Parts list'!$K$4:$K$133,"Yes") -> 1 | K7: =$J7*Cost!$B$6 -> 5 | L7: 3.45 | M7: 2.33 | O7: =IF(AND($L7>0,$L7<Cost!$B$9),"Yes","") | P7: =IF($O7="Yes",MAX($K7*$L7,Cost!$B$8),$K7*$L7) -> 17.25 | Q7: =$J7*$M7 -> 2.33
A8: 5 | B8: IC | C8: TI OPA2210IDR | D8: — | E8: SOIC-8 | F8: Vos ±35 µV max, 2.2 nV/√Hz, 18 MHz, CM (V−)+1.5 V to (V+)−1.5 V, 2.5 mA/ch max | G8: C1849415 | H8: Extended | I8: U403, U404 | J8: =SUMIFS('Parts list'!$C$4:$C$133,'Parts list'!$I$4:$I$133,$G8,'Parts list'!$K$4:$K$133,"Yes") -> 2 | K8: =$J8*Cost!$B$6 -> 10 | L8: 1.0035 | M8: 0.753 | O8: =IF(AND($L8>0,$L8<Cost!$B$9),"Yes","") | P8: =IF($O8="Yes",MAX($K8*$L8,Cost!$B$8),$K8*$L8) -> 10.035 | Q8: =$J8*$M8 -> 1.506
A9: 6 | B9: IC | C9: AGM AGRV2KQ32 | D9: — | E9: QFN-32 4 × 4 mm | F9: 3.3 V | G9: C18208899 | H9: Extended | I9: U202 | J9: =SUMIFS('Parts list'!$C$4:$C$133,'Parts list'!$I$4:$I$133,$G9,'Parts list'!$K$4:$K$133,"Yes") -> 1 | K9: =$J9*Cost!$B$6 -> 5 | L9: 1.6503 | M9: 1.11 | N9: Yes | O9: =IF(AND($L9>0,$L9<Cost!$B$9),"Yes","") | P9: =IF($O9="Yes",MAX($K9*$L9,Cost!$B$8),$K9*$L9) -> 8.2515 | Q9: =$J9*$M9 -> 1.11
A10: 7 | B10: IC | C10: TI LM27762DSSR | D10: ±3.8 V | E10: WSON-12 2 × 3 mm | F10: ±250 mA, 2 MHz | G10: C473398 | H10: Extended | I10: U501 | J10: =SUMIFS('Parts list'!$C$4:$C$133,'Parts list'!$I$4:$I$133,$G10,'Parts list'!$K$4:$K$133,"Yes") -> 1 | K10: =$J10*Cost!$B$6 -> 5 | L10: 1.1014 | M10: 0.75 | N10: Yes | O10: =IF(AND($L10>0,$L10<Cost!$B$9),"Yes","") | P10: =IF($O10="Yes",MAX($K10*$L10,Cost!$B$8),$K10*$L10) -> 5.507 | Q10: =$J10*$M10 -> 0.75
A11: 8 | B11: Oscillator | C11: SCTF SX3M80.000B20F30TNN | D11: 80 MHz | E11: 3.2 × 2.5 mm, 4-pad | F11: ±20 ppm tol., ±30 ppm stab., 40 mA max, duty 45–55 % | G11: C5179978 | H11: Extended | I11: X201 | J11: =SUMIFS('Parts list'!$C$4:$C$133,'Parts list'!$I$4:$I$133,$G11,'Parts list'!$K$4:$K$133,"Yes") -> 1 | K11: =$J11*Cost!$B$6 -> 5 | L11: 0.8916 | M11: 0.7211 | N11: Yes | O11: =IF(AND($L11>0,$L11<Cost!$B$9),"Yes","") | P11: =IF($O11="Yes",MAX($K11*$L11,Cost!$B$8),$K11*$L11) -> 4.458 | Q11: =$J11*$M11 -> 0.7211
A12: 9 | B12: IC | C12: TI TPS2553DBVR | D12: — | E12: SOT-23-6 | F12: 0.075–1.7 A adjustable, 85 mΩ, soft start | G12: C55266 | H12: Extended | I12: U503 | J12: =SUMIFS('Parts list'!$C$4:$C$133,'Parts list'!$I$4:$I$133,$G12,'Parts list'!$K$4:$K$133,"Yes") -> 1 | K12: =$J12*Cost!$B$6 -> 5 | L12: 0.5966 | M12: 0.3262 | O12: =IF(AND($L12>0,$L12<Cost!$B$9),"Yes","") | P12: =IF($O12="Yes",MAX($K12*$L12,Cost!$B$8),$K12*$L12) -> 2.983 | Q12: =$J12*$M12 -> 0.3262
A13: 10 | B13: Oscillator | C13: SCTF SX2M22.5792M20F30TNN | D13: 22.5792 MHz | E13: 2.5 × 2.0 mm, 4-pad | F13: ±20 ppm tol., ±30 ppm stab., 10 mA max | G13: C5452663 | H13: Extended | I13: X203 | J13: =SUMIFS('Parts list'!$C$4:$C$133,'Parts list'!$I$4:$I$133,$G13,'Parts list'!$K$4:$K$133,"Yes") -> 1 | K13: =$J13*Cost!$B$6 -> 5 | L13: 0.5455 | M13: 0.3085 | N13: Yes | O13: =IF(AND($L13>0,$L13<Cost!$B$9),"Yes","") | P13: =IF($O13="Yes",MAX($K13*$L13,Cost!$B$8),$K13*$L13) -> 2.7275 | Q13: =$J13*$M13 -> 0.3085
A14: 11 | B14: Resistor | C14: YAGEO RT0603BRD072KL | D14: 2.00 kΩ | E14: 0603 | F14: 0.1 %, 25 ppm thin film | G14: C728588 | H14: Extended | I14: R401–R416 | J14: =SUMIFS('Parts list'!$C$4:$C$133,'Parts list'!$I$4:$I$133,$G14,'Parts list'!$K$4:$K$133,"Yes") -> 16 | K14: =$J14*Cost!$B$6 -> 80 | L14: 0.034 | M14: 0.025 | O14: =IF(AND($L14>0,$L14<Cost!$B$9),"Yes","") -> Yes | P14: =IF($O14="Yes",MAX($K14*$L14,Cost!$B$8),$K14*$L14) -> 2.72 | Q14: =$J14*$M14 -> 0.4
A15: 12 | B15: Oscillator | C15: YXC OT322524.576MJBA4SL | D15: 24.576 MHz | E15: 3.2 × 2.5 mm, 4-pad | F15: ±10 ppm tol., ±20 ppm stab., 1.8–3.3 V | G15: C2831388 | H15: Extended | I15: X202 | J15: =SUMIFS('Parts list'!$C$4:$C$133,'Parts list'!$I$4:$I$133,$G15,'Parts list'!$K$4:$K$133,"Yes") -> 1 | K15: =$J15*Cost!$B$6 -> 5 | L15: 0.5075 | M15: 0.2907 | N15: Yes | O15: =IF(AND($L15>0,$L15<Cost!$B$9),"Yes","") | P15: =IF($O15="Yes",MAX($K15*$L15,Cost!$B$8),$K15*$L15) -> 2.5375 | Q15: =$J15*$M15 -> 0.2907
A16: 13 | B16: Connector | C16: HRO PJ-332A-6A | D16: — | E16: SMD | F16: Gold-plated, 1 A | G16: C2848643 | H16: Extended | I16: J702 | J16: =SUMIFS('Parts list'!$C$4:$C$133,'Parts list'!$I$4:$I$133,$G16,'Parts list'!$K$4:$K$133,"Yes") -> 1 | K16: =$J16*Cost!$B$6 -> 5 | L16: 0.2921 | M16: 0.2326 | O16: =IF(AND($L16>0,$L16<Cost!$B$9),"Yes","") | P16: =IF($O16="Yes",MAX($K16*$L16,Cost!$B$8),$K16*$L16) -> 1.4605 | Q16: =$J16*$M16 -> 0.2326
A17: 14 | B17: Crystal | C17: YXC X50328MSB2GI | D17: 8 MHz | E17: 5.0 × 3.2 mm, 2-pad | F17: ±10 ppm, CL 20 pF | G17: C115962 | H17: Basic | I17: Y201 | J17: =SUMIFS('Parts list'!$C$4:$C$133,'Parts list'!$I$4:$I$133,$G17,'Parts list'!$K$4:$K$133,"Yes") -> 1 | K17: =$J17*Cost!$B$6 -> 5 | L17: 0.2452 | M17: 0.2 | O17: =IF(AND($L17>0,$L17<Cost!$B$9),"Yes","") | P17: =IF($O17="Yes",MAX($K17*$L17,Cost!$B$8),$K17*$L17) -> 1.226 | Q17: =$J17*$M17 -> 0.2
A18: 15 | B18: IC | C18: TI LP5907MFX-3.3/NOPB | D18: 3.3 V, 250 mA | E18: SOT-23-5 | F18: 6.5 µVrms, ±2 % | G18: C80670 | H18: Extended | I18: U302 | J18: =SUMIFS('Parts list'!$C$4:$C$133,'Parts list'!$I$4:$I$133,$G18,'Parts list'!$K$4:$K$133,"Yes") -> 1 | K18: =$J18*Cost!$B$6 -> 5 | L18: 0.2104 | M18: 0.14 | O18: =IF(AND($L18>0,$L18<Cost!$B$9),"Yes","") | P18: =IF($O18="Yes",MAX($K18*$L18,Cost!$B$8),$K18*$L18) -> 1.052 | Q18: =$J18*$M18 -> 0.14
A19: 16 | B19: IC | C19: ST USBLC6-2SC6 | D19: — | E19: SOT-23-6 | F19: 5.25 V, 3.5 pF | G19: C7519 | H19: Extended | I19: U101 | J19: =SUMIFS('Parts list'!$C$4:$C$133,'Parts list'!$I$4:$I$133,$G19,'Parts list'!$K$4:$K$133,"Yes") -> 1 | K19: =$J19*Cost!$B$6 -> 5 | L19: 0.1844 | M19: 0.1439 | O19: =IF(AND($L19>0,$L19<Cost!$B$9),"Yes","") | P19: =IF($O19="Yes",MAX($K19*$L19,Cost!$B$8),$K19*$L19) -> 0.922 | Q19: =$J19*$M19 -> 0.1439
A20: 17 | B20: N-MOSFET | C20: JSCJ 2N7002 | D20: 2N7002 | E20: SOT-23 | F20: 60 V | G20: C8545 | H20: Basic | I20: Q501; Q601–Q610 | J20: =SUMIFS('Parts list'!$C$4:$C$133,'Parts list'!$I$4:$I$133,$G20,'Parts list'!$K$4:$K$133,"Yes") -> 11 | K20: =$J20*Cost!$B$6 -> 55 | L20: 0.0164 | M20: 0.01 | O20: =IF(AND($L20>0,$L20<Cost!$B$9),"Yes","") -> Yes | P20: =IF($O20="Yes",MAX($K20*$L20,Cost!$B$8),$K20*$L20) -> 0.902 | Q20: =$J20*$M20 -> 0.11
A21: 18 | B21: Capacitor | C21: Samsung CL21A106KAYNNNE | D21: 10 µF | E21: 0805 | F21: 25 V X5R | G21: C15850 | H21: Basic | I21: C413–C416; C507; C509; C510; C511 | J21: =SUMIFS('Parts list'!$C$4:$C$133,'Parts list'!$I$4:$I$133,$G21,'Parts list'!$K$4:$K$133,"Yes") -> 8 | K21: =$J21*Cost!$B$6 -> 40 | L21: 0.02 | M21: 0.0077 | O21: =IF(AND($L21>0,$L21<Cost!$B$9),"Yes","") -> Yes | P21: =IF($O21="Yes",MAX($K21*$L21,Cost!$B$8),$K21*$L21) -> 0.8 | Q21: =$J21*$M21 -> 0.0616
A22: 19 | B22: IC | C22: Microne ME6211C33M5G-N | D22: 3.3 V, 500 mA | E22: SOT-23-5 | F22: ±2 %, 100 mV at 100 mA | G22: C82942 | H22: Extended | I22: U502; U504 | J22: =SUMIFS('Parts list'!$C$4:$C$133,'Parts list'!$I$4:$I$133,$G22,'Parts list'!$K$4:$K$133,"Yes") -> 2 | K22: =$J22*Cost!$B$6 -> 10 | L22: 0.0603 | M22: 0.049 | O22: =IF(AND($L22>0,$L22<Cost!$B$9),"Yes","") | P22: =IF($O22="Yes",MAX($K22*$L22,Cost!$B$8),$K22*$L22) -> 0.603 | Q22: =$J22*$M22 -> 0.098
A23: 20 | B23: Connector | C23: SHOU HAN TYPE-C 16PIN 2MD(073) | D23: — | E23: SMD, right angle | F23: 5 V, 3 A | G23: C2765186 | H23: Extended | I23: J101 | J23: =SUMIFS('Parts list'!$C$4:$C$133,'Parts list'!$I$4:$I$133,$G23,'Parts list'!$K$4:$K$133,"Yes") -> 1 | K23: =$J23*Cost!$B$6 -> 5 | L23: 0.1 | M23: 0.0604 | O23: =IF(AND($L23>0,$L23<Cost!$B$9),"Yes","") | P23: =IF($O23="Yes",MAX($K23*$L23,Cost!$B$8),$K23*$L23) -> 0.5 | Q23: =$J23*$M23 -> 0.0604
A24: 21 | B24: Capacitor | C24: Samsung CL05B104KO5NNNC | D24: 100 nF | E24: 0402 | F24: 16 V X7R | G24: C1525 | H24: Basic | I24: C203–C210; C212; C213–C216; C217–C219; C305–C309; C421; C422; C423–C426; C409–C412; C605; C606 | J24: =SUMIFS('Parts list'!$C$4:$C$133,'Parts list'!$I$4:$I$133,$G24,'Parts list'!$K$4:$K$133,"Yes") -> 33 | K24: =$J24*Cost!$B$6 -> 165 | L24: 0.003 | M24: 0.0011 | O24: =IF(AND($L24>0,$L24<Cost!$B$9),"Yes","") -> Yes | P24: =IF($O24="Yes",MAX($K24*$L24,Cost!$B$8),$K24*$L24) -> 0.495 | Q24: =$J24*$M24 -> 0.0363
A25: 22 | B25: Capacitor | C25: Samsung CL10A105KB8NNNC | D25: 1 µF | E25: 0603 | F25: 25 V X5R | G25: C15849 | H25: Basic | I25: C102; C301; C302; C311; C312; C501; C502; C503; C504; C505; C506; C508; C601–C604 | J25: =SUMIFS('Parts list'!$C$4:$C$133,'Parts list'!$I$4:$I$133,$G25,'Parts list'!$K$4:$K$133,"Yes") -> 16 | K25: =$J25*Cost!$B$6 -> 80 | L25: 0.006 | M25: 0.0022 | O25: =IF(AND($L25>0,$L25<Cost!$B$9),"Yes","") -> Yes | P25: =IF($O25="Yes",MAX($K25*$L25,Cost!$B$8),$K25*$L25) -> 0.48 | Q25: =$J25*$M25 -> 0.0352
A26: 23 | B26: IC | C26: onsemi LM393DR2G | D26: — | E26: SOIC-8 | F26: 2–36 V | G26: C7955 | H26: Basic | I26: U601 | J26: =SUMIFS('Parts list'!$C$4:$C$133,'Parts list'!$I$4:$I$133,$G26,'Parts list'!$K$4:$K$133,"Yes") -> 1 | K26: =$J26*Cost!$B$6 -> 5 | L26: 0.09 | M26: 0.0564 | O26: =IF(AND($L26>0,$L26<Cost!$B$9),"Yes","") | P26: =IF($O26="Yes",MAX($K26*$L26,Cost!$B$8),$K26*$L26) -> 0.45 | Q26: =$J26*$M26 -> 0.0564
A27: 24 | B27: Diode | C27: Nexperia BAV99,215 | D27: BAV99 | E27: SOT-23 | F27: 100 V | G27: C2500 | H27: Basic | I27: D601–D604 | J27: =SUMIFS('Parts list'!$C$4:$C$133,'Parts list'!$I$4:$I$133,$G27,'Parts list'!$K$4:$K$133,"Yes") -> 4 | K27: =$J27*Cost!$B$6 -> 20 | L27: 0.0211 | M27: 0.0159 | O27: =IF(AND($L27>0,$L27<Cost!$B$9),"Yes","") -> Yes | P27: =IF($O27="Yes",MAX($K27*$L27,Cost!$B$8),$K27*$L27) -> 0.422 | Q27: =$J27*$M27 -> 0.0636
... A51: 48 | B51: Capacitor | C51: FH 0402B472K500NT | D51: 4.7 nF | E51: 0402 | F51: 50 V X7R | G51: C1538 | H51: Basic | I51: C101 | J51: =SUMIFS('Parts list'!$C$4:$C$133,'Parts list'!$I$4:$I$133,$G51,'Parts list'!$K$4:$K$133,"Yes") -> 1 | K51: =$J51*Cost!$B$6 -> 5 | L51: 0.002 | M51: 0.0006 | O51: =IF(AND($L51>0,$L51<Cost!$B$9),"Yes","") -> Yes | P51: =IF($O51="Yes",MAX($K51*$L51,Cost!$B$8),$K51*$L51) -> 0.1 | Q51: =$J51*$M51 -> 0.0006
B53: Total, all purchase lines | J53: =SUM(J4:J51) -> 232 | K53: =SUM(K4:K51) -> 1160 | O53: =COUNTIF(O4:O51,"Yes") -> 29 | P53: =SUM(P4:P51) -> 138.84 | Q53: =SUM(Q4:Q51) -> 19.6486

Sheet Cost
A1: Cost — 5-board sample run (JLCPCB Economic PCBA) and 100-unit reference
A2: Parts List v0.4 (24 Sep 2026, after the fifth review round) · parts at the LCSC tier matching the run quantity (100-board tier for the reference); OPA2210 at its JLCPCB part-page price · JLCPCB PCBA fee schedules · blue on yellow = input · every NTD figure uses the exchange rate in B5 · planning estimate until the JLCPCB quote after layout
A4: Inputs | B4: Value | C4: Unit | G4: Note
A5: Exchange rate | B5: 31.7 | C5: NTD per US$ | G5: fixed for the cost gate; applies to every NTD figure
A6: Boards in the sample run | B6: 5 | C6: boards | G6: JLCPCB Economic PCBA (one side, 2–50 boards)
A7: Boards in the reference build | B7: 100 | C7: boards | G7: JLCPCB Standard PCBA — reference only, not the budget basis
A8: Minimum line cost per purchasing line | B8: 0.1 | C8: US$ | G8: applied to purchasing lines whose unit price is below B9 (attrition / minimum-quantity allowance)
A9: Minimum applies below this unit price | B9: 0.05 | C9: US$ | G9: Purchasing list: line = MAX(qty × price, B8) when 0 < price < B9
A10: Cost target per board, 5-board run | B10: 1500 | C10: NTD | G10: ="WARNING above; = "&TEXT(B10*B6,"#,##0")&" NTD for "&TEXT(B6,"0")&" boards incl. bare PCBs and assembly fees; excl. shipping, import tax, programmers, enclosure, proof-of-concept hardware and a possible assembly-fixture fee" -> WARNING above; = 7,500 NTD for 5 boards incl. bare PCBs and assembly fees; excl. shipping, import tax, programmers, enclosure, proof-of-concept hardware and a possible assembly-fixture fee
A11: Ceiling per board, 5-board run (hard order gate) | B11: 1700 | C11: NTD | G11: Ceiling 1,700 NTD per board, set when the third oscillator was added; on 24 Sep 2026 the owner confirmed the budget is flexible as long as it does not surge; the actual JLCPCB quote from the real BOM/CPL files must pass the ceiling before ordering; FAIL above
A13: Board data (linked from the Parts list and Purchasing list) | B13: Value | C13: Unit | G13: Source
A14: Fitted BOM lines | B14: =COUNTIF('Parts list'!$K$4:$K$133,"Yes") -> 122 | C14: lines | G14: Parts list: Fit = Yes (includes the bare-PCB row)
A15: SMT-placed parts per board | B15: =SUMIFS('Parts list'!$C$4:$C$133,'Parts list'!$K$4:$K$133,"Yes",'Parts list'!$M$4:$M$133,">0",'Parts list'!$B$4:$B$133,"<>PCB") -> 231 | C15: parts | G15: Parts list: Qty where Fit = Yes and SMT joints per part > 0
A16: Through-hole parts per board | B16: =SUMIFS('Parts list'!$C$4:$C$133,'Parts list'!$K$4:$K$133,"Yes",'Parts list'!$N$4:$N$133,">0") -> 1 | C16: parts | G16: Parts list: through-hole joints per part > 0 (4.4 mm jack J701)
A17: Extended part types (incl. through-hole) | B17: =SUMIFS('Parts list'!$W$4:$W$133,'Parts list'!$J$4:$J$133,"Extended") -> 19 | C17: types | G17: Parts list helper W: distinct LCSC numbers, class Extended — every fitted Extended type, incl. the through-hole jack
A18: Basic part types | B18: =SUMIFS('Parts list'!$W$4:$W$133,'Parts list'!$J$4:$J$133,"Basic") -> 29 | C18: types | G18: Parts list helper W: distinct LCSC numbers, class Basic
A19: All part types | B19: =B17+B18 -> 48 | C19: types | G19: Extended + Basic (feeder loading on the 100-unit reference)
A20: SMT joints per board | B20: {=SUMPRODUCT(('Parts list'!$K$4:$K$133="Yes")*('Parts list'!$B$4:$B$133<>"PCB")*'Parts list'!$C$4:$C$133*'Parts list'!$M$4:$M$133)} -> 690 | C20: joints | G20: Parts list: Qty × SMT joints per part where Fit = Yes
A21: Through-hole joints per board | B21: {=SUMPRODUCT(('Parts list'!$K$4:$K$133="Yes")*'Parts list'!$C$4:$C$133*'Parts list'!$N$4:$N$133)} -> 7 | C21: joints | G21: Parts list: Qty × through-hole joints per part where Fit = Yes
A22: Leadless parts per board (X-ray) | B22: =SUMIFS('Parts list'!$C$4:$C$133,'Parts list'!$K$4:$K$133,"Yes",'Parts list'!$L$4:$L$133,"Yes") -> 8 | C22: parts | G22: Parts list: Leadless (X-ray) = Yes — CPLD, ES9018K2M, 2 × OPA1622, LM27762, three oscillators (80 / 24.576 / 22.5792 MHz)
A23: of which oscillators | B23: =SUMIFS('Parts list'!$C$4:$C$133,'Parts list'!$K$4:$K$133,"Yes",'Parts list'!$L$4:$L$133,"Yes",'Parts list'!$D$4:$D$133,"Oscillator*") -> 3 | C23: parts | G23: X201, X202 and X203 — counted conservatively (see levers)
A24: Extended through-hole part types | B24: =SUMIFS('Parts list'!$W$4:$W$133,'Parts list'!$J$4:$J$133,"Extended",'Parts list'!$N$4:$N$133,">0") -> 1 | C24: types | G24: J701 — Extended fee counted conservatively (see levers)
A25: Parts, 5-board run (incl. minimum) | B25: =SUM('Purchasing list'!$P$4:$P$51) -> 138.84 | C25: US$ | G25: Purchasing list: line costs, incl. the US$0.10 minimum for parts under US$0.05
A26: of which minimum-spend uplift | B26: =B25-SUMIFS('Parts list'!$S$4:$S$133,'Parts list'!$B$4:$B$133,"<>PCB") -> 0.899 | C26: US$ | G26: Purchasing list total minus the Parts list line costs before the minimum
A27: Bare 4-layer PCBs, 5-board run (estimate) | B27: =SUMIFS('Parts list'!$S$4:$S$133,'Parts list'!$B$4:$B$133,"PCB") -> 10 | C27: US$ | G27: Parts list: PCB row, qty × boards × unit price
A28: Parts per board, 100-board tier (bare PCB excluded) | B28: =SUMIFS('Parts list'!$T$4:$T$133,'Parts list'!$B$4:$B$133,"<>PCB")/$B$7 -> 19.6486 | C28: US$ | G28: Parts list: Line cost 100-board run ÷ boards
A29: Bare PCB per board, 100-board tier (estimate) | B29: =SUMIFS('Parts list'!$T$4:$T$133,'Parts list'!$B$4:$B$133,"PCB")/$B$7 -> 0.8 | C29: US$ | G29: Parts list: PCB row
A31: ="5-board sample run — "&TEXT($B$6,"0")&" boards, JLCPCB Economic PCBA" -> 5-board sample run — 5 boards, JLCPCB Economic PCBA
A32: PCBA fee (per order) | B32: Quantity | C32: Rate US$ | D32: Fixed US$ | E32: US$ | F32: NTD | G32: Basis
A33: Setup | D33: 8.18 | E33: =B33*C33+D33 -> 8.18 | F33: =E33*$B$5 -> 259.306 | G33: fixed fee per order
A34: Stencil | D34: 1.53 | E34: =B34*C34+D34 -> 1.53 | F34: =E34*$B$5 -> 48.501 | G34: fixed fee per order
A35: Extended part types | B35: =B17 -> 19 | C35: 3.07 | E35: =B35*C35+D35 -> 58.33 | F35: =E35*$B$5 -> 1849.061 | G35: =TEXT(B35,"0")&" fitted Extended part types × US$"&TEXT(C35,"0.00")&", incl. the through-hole 4.4 mm jack (counted conservatively)" -> 19 fitted Extended part types × US$3.07, incl. the through-hole 4.4 mm jack (counted conservatively)
A36: SMT joints | B36: =B20*$B$6 -> 3450 | C36: 0.0016 | E36: =B36*C36+D36 -> 5.52 | F36: =E36*$B$5 -> 174.984 | G36: =TEXT(B20,"#,##0")&" joints per board × "&TEXT($B$6,"0")&" boards" -> 690 joints per board × 5 boards
A37: X-ray (leadless parts) | B37: =B22*$B$6 -> 40 | C37: 0.82 | E37: =B37*C37+D37 -> 32.8 | F37: =E37*$B$5 -> 1039.76 | G37: =TEXT(B22,"0")&" leadless parts per board × "&TEXT($B$6,"0")&" boards (11–50-part tier); includes the "&TEXT(B23,"0")&" oscillators (counted conservatively)" -> 8 leadless parts per board × 5 boards (11–50-part tier); includes the 3 oscillators (counted conservatively)
A38: Through-hole joints | B38: =B21*$B$6 -> 35 | C38: 0.0164 | D38: 3.58 | E38: =IF(B38=0,0,B38*C38+D38) -> 4.154 | F38: =E38*$B$5 -> 131.6818 | G38: ="4.4 mm jack: "&TEXT(B21,"0")&" joints per board × "&TEXT($B$6,"0")&" boards, plus the hand-soldering fee per order" -> 4.4 mm jack: 7 joints per board × 5 boards, plus the hand-soldering fee per order
A39: Confirm Parts Placement | D39: 0.45 | E39: =B39*C39+D39 -> 0.45 | F39: =E39*$B$5 -> 14.265 | G39: fixed fee per order
A40: PCBA fees, total per order | E40: =SUM(E33:E39) -> 110.964 | F40: =E40*$B$5 -> 3517.5588
A42: 5-board run total | E42: US$ | F42: NTD | G42: Basis
A43: Parts (LCSC tier matching the run quantity) | E43: =B25 -> 138.84 | F43: =E43*$B$5 -> 4401.228 | G43: Purchasing list, incl. the minimum per line for parts under US$0.05
A44: Bare 4-layer PCBs (estimate) | E44: =B27 -> 10 | F44: =E44*$B$5 -> 317 | G44: =TEXT($B$6,"0")&" boards; Parts list PCB row" -> 5 boards; Parts list PCB row
...

Sheet Notes & open items
A1: Notes & open items
A2: Parts List v0.4 · Diego Yang · 24 Sep 2026 · companion to Design Specification v0.6 and Schematic Design Notes v0.5 · Parts List v0.3 is kept unchanged as history
A4: About this list
A5: 1 | B5: ="Covers every component of every circuit: "&TEXT(COUNTA('Parts list'!$B$4:$B$133),"0")&" BOM lines ("&TEXT(Cost!B14,"0")&" fitted, "&TEXT(COUNTIF('Parts list'!$K$4:$K$133,"DNF"),"0")&" DNF), "&TEXT(Cost!B15,"0")&" SMT-placed parts and "&TEXT(Cost!B16,"0")&" through-hole part (4.4 mm jack) per board; "&TEXT(COUNTA('Purchasing list'!$C$4:$C$51),"0")&" purchasing lines." -> Covers every component of every circuit: 130 BOM lines (122 fitted, 4 DNF), 231 SMT-placed parts and 1 through-hole part (4.4 mm jack) per board; 48 purchasing lines.
A6: 2 | B6: Designators are grouped by block: 1xx USB-C input and sensing, 2xx USB audio bridge, 3xx DAC and its supplies, 4xx I/V converters and output legs, 5xx power domains, current limit and rails, 6xx protection and control, 7xx outputs, indicators, test and board.
A7: 3 | B7: Fit: Yes = placed on every board; DNF = footprint only (U205 clock mux and R215, the fallback for the shared family-clock node; R703 and the J703 I²S test header); No part = copper only (J201 / J202 debug pads, TP701–TP729 test pads, 4 mounting holes and 3 fiducials).
A8: 4 | B8: One part per line. Every fitted part has an LCSC number and a JLCPCB class verified on the JLCPCB part page or the JLCPCB basic-parts list — except X202 (24.576 MHz oscillator), whose class is not shown on its part page and is assumed Extended (conservative); the Purchasing list has one line per LCSC number and quantities summed from the Parts list.
A9: 5 | B9: Legend: Quote = listing price at the tier matching the run quantity (LCSC; the OPA2210 line uses its JLCPCB part-page price, see its note); Estimate = planning price (bare PCB, DNF header); blue on yellow = input on the Cost sheet; Parts list columns V–W are helpers that count distinct part types by LCSC number.
A11: Change log
A12: 1 | B12: 24 Sep 2026 — Parts List v0.3 after the fourth review round (reviews R4-A, R4-B and R4-C of Spec v0.4 / Notes v0.3 / Parts List v0.2). Parts List v0.2 stays unchanged as history.
A13: 2 | B13: 24 Sep 2026 — Current limit: TI TPS2553DBVR (C55266) current-limited switch feeds the LM27762 (Default 0.157–0.213 A, High 0.393–0.498 A); RILIM from Basic values 100 kΩ + 47 kΩ, High limit via 2N7002 + 100 kΩ.
A14: 3 | B14: 24 Sep 2026 — Power domains: second ME6211C33M5G-N (U504, switched 3V3D domain with CE) added beside the always-on 3V3M ME6211; LP5907 EN and TPS2553 EN switch the audio domains.
A15: 4 | B15: 24 Sep 2026 — Clock: one 100 MHz oscillator YXC OT3225100MJBA4SL (C4353707) replaces the two audio oscillators (22.5792 / 24.576 MHz); the ES9018K2M runs in its asynchronous (DPLL) mode.
A16: 5 | B16: 24 Sep 2026 — I/V op-amp: TI OPA2197IDR (C139363, Vos ±0.25 mV max) replaces the OPA1678 (±2 mV max).
A17: 6 | B17: 24 Sep 2026 — 1.3 V DVDD: Microne ME6216A13M3G (C236662, fixed, ±1 %, ceramic-stable) replaces the AMS1117-ADJ, fed from the switched 3V3D domain.
A18: 7 | B18: 24 Sep 2026 — Ferrite: Murata BLM18PG121SN1D (C14709, Basic, 2 A, 50 mΩ) in the 5V_ANA path; Sunlord GZ1608D601TF (C1002, 200 mA / 450 mΩ) only on the DAC DVCC branch (≈ 14 mA).
A19: 8 | B19: 24 Sep 2026 — Protection: all-2N7002 fault latch (Q601–Q609, JSCJ 2N7002 C8545) with PGOOD hardware kill and ≈ 60 ms set-path blanking; the MMBT3904 / MMBT3906 transistors are gone.
A20: 9 | B20: 24 Sep 2026 — Basic value combinations instead of Extended values: 100 k + 47 k (TPS2553 RILIM, DC-detect filter), 1 k ∥ 5.1 k = 836 Ω (I/V feedback), 15 k + 1 k (VREF divider), 2 × 330 pF C0G (I/V feedback capacitor), 100 k + 100 k + 15 k / 10 k (LM27762 feedback).
A21: 10 | B21: 24 Sep 2026 — Other part changes: Basic 5032 8 MHz crystal YXC X50328MSB2GI (C115962); GOODWORK LESD5D5.0CT1G ESD diodes (C41399463); SHOU HAN TYPE-C 16-pin receptacle (C2765186); 0805 green status LED KT-0805G (C2297, Basic).
A22: 11 | B22: 24 Sep 2026 — Design context: headphone rails ±3.78 V (was ±4.5 V); output calibrated to 1.75 Vrms per leg; parts list rebuilt one part per line with an LCSC number and a verified class on every fitted line.
A23: 12 | B23: 24 Sep 2026 — Cost: 1,536 NTD per board (v0.2) → 1,540 NTD per board (US$242.95 = 7,702 NTD for 5 boards); gate WARNING, 10 NTD under the approved ceiling of 1,550 NTD at the time. Verified prices are mostly lower; new parts and three more Extended types are counted.
... A28: 17 | B28: 24 Sep 2026 — v0.4 (fifth review round): MCLK oscillator 80 MHz (SCTF SX3M80.000B20F30TNN) replaces 100 MHz; I/V op-amp OPA2210IDR replaces OPA2197IDR; both family-oscillator enables 2.2 kΩ pull-downs, node pull-down R214, DNF mux U205/R215; overload latch parts Q610 and D606; VREF clamp D401 and C421 100 nF; R518 5.1 kΩ (−3.722 V rail); DNF R703 for the test-header MCLK monitor; 29 test pads; cost 1,666 → 1,647 NTD per board
A29: Pricing rules
A30: 1 | B30: Price tier: the LCSC tier that matches the run quantity — 1+ tier for one-per-board ICs (5 pieces), 10+ tier for two-per-board parts (10 pieces). The Parts list column "Unit price US$ (sample-run tier)" already holds that price. Exception: the OPA2210 (U403, U404) is priced at its JLCPCB part page (10+ US$1.0035), because the PCBA order is charged at JLCPCB prices; LCSC lists US$2.67 at 10+.
A31: 2 | B31: ="Minimum: US$"&TEXT(Cost!B8,"0.00")&" per purchasing line for parts under US$"&TEXT(Cost!B9,"0.00")&" (attrition / minimum-quantity allowance): line cost = MAX(qty for the run × unit price, US$"&TEXT(Cost!B8,"0.00")&"). It applies to "&TEXT('Purchasing list'!O53,"0")&" of the "&TEXT(COUNTA('Purchasing list'!$C$4:$C$51),"0")&" purchasing lines and adds US$"&TEXT(Cost!B26,"0.00")&" to the run." -> Minimum: US$0.10 per purchasing line for parts under US$0.05 (attrition / minimum-quantity allowance): line cost = MAX(qty for the run × unit price, US$0.10). It applies to 29 of the 48 purchasing lines and adds US$0.90 to the run.
A32: 3 | B32: ="Exchange rate: "&TEXT(Cost!B5,"0.0")&" NTD per US$, fixed for the cost gate; the single input cell Cost!B5 drives every NTD figure." -> Exchange rate: 31.7 NTD per US$, fixed for the cost gate; the single input cell Cost!B5 drives every NTD figure.
