Workbook

Sheet Summary
A1: USB DAC + Balanced Headphone Amplifier — Parts List v0.1 (draft)
A2: Diego Yang · 23 Sep 2026 · companion to Schematic Design Notes v0.2 and Design Specification v0.3
A4: Key figures
A5: Key figure | B5: Value | C5: Unit | D5: Basis
A6: Placed parts per production board | B6: =Cost!B14 -> 273 | C6: parts | D6: Fit = Yes; bare PCB excluded
A7: Placed parts per prototype board | B7: =Cost!B15 -> 274 | C7: parts | D7: adds the J201 JTAG header
A8: Distinct part numbers | B8: =COUNTA('Purchasing list'!$C$4:$C$87) -> 84 | C8: part numbers | D8: one row each in the Purchasing list
A9: Leadless (X-ray) parts per board | B9: =Cost!B20 -> 7 | C9: parts | D9: XU316, 2 oscillators, 4 × OPA1622
A10: SMT joints per production board | B10: =Cost!B18 -> 826 | C10: joints | D10: Qty × SMT joints per part, fitted lines
A11: Parts cost per board | B11: =Cost!B12 -> 40.6195 | C11: US$ | D11: 100-board tier; bare PCB excluded
A12: Parts cost per board | B12: =Cost!B12*Cost!B5 -> 1287.6381 | C12: NTD | D12: ="at "&TEXT(Cost!B5,"0.0")&" NTD per US$" -> at 31.7 NTD per US$
A13: ="Total cost per board at "&TEXT(Cost!B6,"#,##0")&" units" -> Total cost per board at 100 units | B13: =Cost!F42 -> 1478.7701 | C13: NTD | D13: parts + bare PCB + JLCPCB Standard PCBA fees
A14: Cost limit per board | B14: =Cost!F43 -> 1500 | C14: NTD | D14: input on the Cost sheet
A15: Margin to the limit | B15: =Cost!F44 -> 21.22987 | C15: NTD | D15: =IF(B15>=0,"within the limit","over the limit") -> within the limit
A16: ="Prototype order total, "&TEXT(Cost!B7,"0")&" boards" -> Prototype order total, 5 boards | B16: =Cost!F61 -> 15894.443 | C16: NTD | D16: ="≈ "&TEXT(Cost!F62,"#,##0")&" NTD per board; JLCPCB Economic PCBA" -> ≈ 3,179 NTD per board; JLCPCB Economic PCBA
A18: Parts cost by block (fitted lines; bare PCB excluded)
A19: Block | B19: Placed parts | C19: Parts cost US$ | D19: Parts cost NTD | E19: of which quoted NTD
A20: 1 USB data port + digital power | B20: =SUMIFS('[1]Parts list'!$C$4:$C$159,'[1]Parts list'!$A$4:$A$159,$A20,'[1]Parts list'!$K$4:$K$159,"Yes",'[1]Parts list'!$B$4:$B$159,"<>PCB") -> 22 | C20: =SUMIFS('[1]Parts list'!$P$4:$P$159,'[1]Parts list'!$A$4:$A$159,$A20,'[1]Parts list'!$B$4:$B$159,"<>PCB") -> 0.8765 | D20: =C20*Cost!$B$5 -> 27.78505 | E20: =SUMIFS('[1]Parts list'!$P$4:$P$159,'[1]Parts list'!$A$4:$A$159,$A20,'[1]Parts list'!$O$4:$O$159,"Quote",'[1]Parts list'!$B$4:$B$159,"<>PCB")*Cost!$B$5 -> 24.52946
A21: 2 USB audio processor (XU316) | B21: =SUMIFS('[1]Parts list'!$C$4:$C$159,'[1]Parts list'!$A$4:$A$159,$A21,'[1]Parts list'!$K$4:$K$159,"Yes",'[1]Parts list'!$B$4:$B$159,"<>PCB") -> 28 | C21: =SUMIFS('[1]Parts list'!$P$4:$P$159,'[1]Parts list'!$A$4:$A$159,$A21,'[1]Parts list'!$B$4:$B$159,"<>PCB") -> 10.5111 | D21: =C21*Cost!$B$5 -> 333.20187 | E21: =SUMIFS('[1]Parts list'!$P$4:$P$159,'[1]Parts list'!$A$4:$A$159,$A21,'[1]Parts list'!$O$4:$O$159,"Quote",'[1]Parts list'!$B$4:$B$159,"<>PCB")*Cost!$B$5 -> 331.78488
A22: 3 Clocks | B22: =SUMIFS('[1]Parts list'!$C$4:$C$159,'[1]Parts list'!$A$4:$A$159,$A22,'[1]Parts list'!$K$4:$K$159,"Yes",'[1]Parts list'!$B$4:$B$159,"<>PCB") -> 12 | C22: =SUMIFS('[1]Parts list'!$P$4:$P$159,'[1]Parts list'!$A$4:$A$159,$A22,'[1]Parts list'!$B$4:$B$159,"<>PCB") -> 1.7938 | D22: =C22*Cost!$B$5 -> 56.86346 | E22: =SUMIFS('[1]Parts list'!$P$4:$P$159,'[1]Parts list'!$A$4:$A$159,$A22,'[1]Parts list'!$O$4:$O$159,"Quote",'[1]Parts list'!$B$4:$B$159,"<>PCB")*Cost!$B$5 -> 56.48306
A23: 4 DAC (AK4493SEQ) | B23: =SUMIFS('[1]Parts list'!$C$4:$C$159,'[1]Parts list'!$A$4:$A$159,$A23,'[1]Parts list'!$K$4:$K$159,"Yes",'[1]Parts list'!$B$4:$B$159,"<>PCB") -> 29 | C23: =SUMIFS('[1]Parts list'!$P$4:$P$159,'[1]Parts list'!$A$4:$A$159,$A23,'[1]Parts list'!$B$4:$B$159,"<>PCB") -> 6.2703 | D23: =C23*Cost!$B$5 -> 198.76851 | E23: =SUMIFS('[1]Parts list'!$P$4:$P$159,'[1]Parts list'!$A$4:$A$159,$A23,'[1]Parts list'!$O$4:$O$159,"Quote",'[1]Parts list'!$B$4:$B$159,"<>PCB")*Cost!$B$5 -> 192.736
A24: 5 DAC interface + stage 1 | B24: =SUMIFS('[1]Parts list'!$C$4:$C$159,'[1]Parts list'!$A$4:$A$159,$A24,'[1]Parts list'!$K$4:$K$159,"Yes",'[1]Parts list'!$B$4:$B$159,"<>PCB") -> 31 | C24: =SUMIFS('[1]Parts list'!$P$4:$P$159,'[1]Parts list'!$A$4:$A$159,$A24,'[1]Parts list'!$B$4:$B$159,"<>PCB") -> 1.5296 | D24: =C24*Cost!$B$5 -> 48.48832 | E24: =SUMIFS('[1]Parts list'!$P$4:$P$159,'[1]Parts list'!$A$4:$A$159,$A24,'[1]Parts list'!$O$4:$O$159,"Quote",'[1]Parts list'!$B$4:$B$159,"<>PCB")*Cost!$B$5 -> 27.78822
A25: 6 Output stage (4 legs) + gain switch | B25: =SUMIFS('[1]Parts list'!$C$4:$C$159,'[1]Parts list'!$A$4:$A$159,$A25,'[1]Parts list'!$K$4:$K$159,"Yes",'[1]Parts list'!$B$4:$B$159,"<>PCB") -> 53 | C25: =SUMIFS('[1]Parts list'!$P$4:$P$159,'[1]Parts list'!$A$4:$A$159,$A25,'[1]Parts list'!$B$4:$B$159,"<>PCB") -> 9.0548 | D25: =C25*Cost!$B$5 -> 287.03716 | E25: =SUMIFS('[1]Parts list'!$P$4:$P$159,'[1]Parts list'!$A$4:$A$159,$A25,'[1]Parts list'!$O$4:$O$159,"Quote",'[1]Parts list'!$B$4:$B$159,"<>PCB")*Cost!$B$5 -> 270.6863
A26: 7 Protection, relays, amplifier enable | B26: =SUMIFS('[1]Parts list'!$C$4:$C$159,'[1]Parts list'!$A$4:$A$159,$A26,'[1]Parts list'!$K$4:$K$159,"Yes",'[1]Parts list'!$B$4:$B$159,"<>PCB") -> 40 | C26: =SUMIFS('[1]Parts list'!$P$4:$P$159,'[1]Parts list'!$A$4:$A$159,$A26,'[1]Parts list'!$B$4:$B$159,"<>PCB") -> 2.6916 | D26: =C26*Cost!$B$5 -> 85.32372 | E26: =SUMIFS('[1]Parts list'!$P$4:$P$159,'[1]Parts list'!$A$4:$A$159,$A26,'[1]Parts list'!$O$4:$O$159,"Quote",'[1]Parts list'!$B$4:$B$159,"<>PCB")*Cost!$B$5 -> 82.25833
A27: 8 PD input + analog power | B27: =SUMIFS('[1]Parts list'!$C$4:$C$159,'[1]Parts list'!$A$4:$A$159,$A27,'[1]Parts list'!$K$4:$K$159,"Yes",'[1]Parts list'!$B$4:$B$159,"<>PCB") -> 48 | C27: =SUMIFS('[1]Parts list'!$P$4:$P$159,'[1]Parts list'!$A$4:$A$159,$A27,'[1]Parts list'!$B$4:$B$159,"<>PCB") -> 3.3406 | D27: =C27*Cost!$B$5 -> 105.89702 | E27: =SUMIFS('[1]Parts list'!$P$4:$P$159,'[1]Parts list'!$A$4:$A$159,$A27,'[1]Parts list'!$O$4:$O$159,"Quote",'[1]Parts list'!$B$4:$B$159,"<>PCB")*Cost!$B$5 -> 91.21041
A28: 9 Outputs, indicators, test, board | B28: =SUMIFS('[1]Parts list'!$C$4:$C$159,'[1]Parts list'!$A$4:$A$159,$A28,'[1]Parts list'!$K$4:$K$159,"Yes",'[1]Parts list'!$B$4:$B$159,"<>PCB") -> 10 | C28: =SUMIFS('[1]Parts list'!$P$4:$P$159,'[1]Parts list'!$A$4:$A$159,$A28,'[1]Parts list'!$B$4:$B$159,"<>PCB") -> 4.5512 | D28: =C28*Cost!$B$5 -> 144.27304 | E28: =SUMIFS('[1]Parts list'!$P$4:$P$159,'[1]Parts list'!$A$4:$A$159,$A28,'[1]Parts list'!$O$4:$O$159,"Quote",'[1]Parts list'!$B$4:$B$159,"<>PCB")*Cost!$B$5 -> 143.76584
A29: Total | B29: =SUM(B20:B28) -> 273 | C29: =SUM(C20:C28) -> 40.6195 | D29: =SUM(D20:D28) -> 1287.6381 | E29: =SUM(E20:E28) -> 1221.2425
A31: Legend
A32: Term | B32: Meaning
A33: Quote | B33: Distributor price at the 100-board tier (LCSC, JLCPCB, Digi-Key, Mouser listings, Aug–Sep 2026)
A34: Estimate | B34: Planning price for generic passives and small discretes
A35: Fit: Yes | B35: Fitted on every board (production and prototypes)
A36: Fit: DNF | B36: Do not fit: the footprint is on the board, the part is not placed
A37: Fit: Prototypes only | B37: Fitted on the prototype boards only (J201 xSYS2 JTAG header; production boards use the TC2030 pads)
A38: Fit: No part | B38: Copper-only feature (test pads, TC2030 debug footprint, mounting holes, fiducials)
A39: Colour code | B39: Parts list: grey rows = DNF / No part, amber row = Prototypes only. Cost sheet: blue on yellow = input, green = linked from the Parts list / Purchasing list.

Sheet Purchasing list
A1: Purchasing list — fitted parts merged by part number / specification
A2: One row per distinct part number; generic passives are merged by value, package and rating. Order quantities use the board counts on the Cost sheet.
A3: Item | B3: Part type | C3: Part number (MPN) | D3: Value | E3: Package | F3: Rating / tolerance | G3: Source / LCSC no. | H3: JLCPCB library type | I3: Designators | J3: Qty per production board | K3: Extra qty per prototype board (prototype-only parts) | L3: Unit price US$ (100-board tier) | M3: Price basis | N3: Leadless (X-ray) | O3: Qty for 5 prototypes | P3: Qty for 100 boards | Q3: Ext. per board US$
A4: 1 | B4: Buck converter | C4: TI TLV62569DBVR | D4: 0.9 V, 2 A | E4: SOT-23-5 | F4: 2.5–5.5 V in, 1.5 MHz | G4: LCSC C141836 | H4: Extended | I4: U102 | J4: 1 | K4: 0 | L4: 0.0632 | M4: Quote | O4: =($J4+$K4)*Cost!$B$7 -> 5 | P4: =$J4*Cost!$B$6 -> 100 | Q4: =$J4*$L4 -> 0.0632
A5: 2 | B5: Buck converter used as inverting buck-boost → −14.7 V | C5: TI LMR33630ADDAR | D5: 3 A | E5: HSOIC-8 | F5: 3.8–36 V, 400 kHz | G5: LCSC C841384 | H5: Extended | I5: U802 | J5: 1 | K5: 0 | L5: 0.4642 | M5: Quote | O5: =($J5+$K5)*Cost!$B$7 -> 5 | P5: =$J5*Cost!$B$6 -> 100 | Q5: =$J5*$L5 -> 0.4642
A6: 3 | B6: Comparator | C6: TI LM339DR | D6: — | E6: SOIC-14 | F6: ±1 to ±18 V | G6: LCSC C7948 | H6: Extended | I6: U701 | J6: 1 | K6: 0 | L6: 0.1358 | M6: Quote | O6: =($J6+$K6)*Cost!$B$7 -> 5 | P6: =$J6*Cost!$B$6 -> 100 | Q6: =$J6*$L6 -> 0.1358
A7: 4 | B7: Crystal | C7: YXC X322524MOB4SI | D7: 24 MHz | E7: 3.2 × 2.5 mm | F7: 12 pF, ±10 ppm, ESR 50 Ω | G7: LCSC C70590 | H7: Extended | I7: Y201 | J7: 1 | K7: 0 | L7: 0.0759 | M7: Quote | O7: =($J7+$K7)*Cost!$B$7 -> 5 | P7: =$J7*Cost!$B$6 -> 100 | Q7: =$J7*$L7 -> 0.0759
A8: 5 | B8: DAC | C8: AKM AK4493SEQ | D8: — | E8: LQFP-48 | F8: THD+N −115 dB typ | G8: Mouser (JLCPCB global sourcing) | H8: Global sourcing | I8: U401 | J8: 1 | K8: 0 | L8: 6.08 | M8: Quote | O8: =($J8+$K8)*Cost!$B$7 -> 5 | P8: =$J8*Cost!$B$6 -> 100 | Q8: =$J8*$L8 -> 6.08
A9: 6 | B9: Ferrite bead | C9: Murata BLM18KG601SN1D | D9: 600 Ω | E9: 0603 | F9: 1.3 A, 0.15 Ω | G9: LCSC C85833 | H9: Extended | I9: FB201; FB301; FB801; FB802 | J9: 4 | K9: 0 | L9: 0.0258 | M9: Quote | O9: =($J9+$K9)*Cost!$B$7 -> 20 | P9: =$J9*Cost!$B$6 -> 400 | Q9: =$J9*$L9 -> 0.1032
A10: 7 | B10: Inductor | C10: Sunlord SWPA3015S2R2MT | D10: 2.2 µH | E10: 3 × 3 mm | F10: 2 A | G10: JLCPCB C43389 | H10: Extended | I10: L101 | J10: 1 | K10: 0 | L10: 0.06 | M10: Quote | O10: =($J10+$K10)*Cost!$B$7 -> 5 | P10: =$J10*Cost!$B$6 -> 100 | Q10: =$J10*$L10 -> 0.06
A11: 8 | B11: Inductor | C11: Sunlord SWPA6045S220MT | D11: 22 µH | E11: 6 × 6 mm | F11: Isat 2.2 A | G11: JLCPCB C83454 | H11: Extended | I11: L801 | J11: 1 | K11: 0 | L11: 0.11 | M11: Quote | O11: =($J11+$K11)*Cost!$B$7 -> 5 | P11: =$J11*Cost!$B$6 -> 100 | Q11: =$J11*$L11 -> 0.11
A12: 9 | B12: Jack | C12: HRO PJ-332A-6A | D12: — | E12: SMD | F12: Gold-plated, 1 A | G12: LCSC C2848643 | H12: Extended | I12: J902 | J12: 1 | K12: 0 | L12: 0.2326 | M12: Quote | O12: =($J12+$K12)*Cost!$B$7 -> 5 | P12: =$J12*Cost!$B$6 -> 100 | Q12: =$J12*$L12 -> 0.2326
A13: 10 | B13: Jack | C13: G-Switch GT-3321667P-01 | D13: — | E13: Through-hole | F13: Gold-plated, 0.5 A | G13: LCSC C2762984 | H13: Extended | I13: J901 | J13: 1 | K13: 0 | L13: 4.2768 | M13: Quote | O13: =($J13+$K13)*Cost!$B$7 -> 5 | P13: =$J13*Cost!$B$6 -> 100 | Q13: =$J13*$L13 -> 4.2768
A14: 11 | B14: LDO | C14: ST LM317D2T-TR | D14: +12.0 V | E14: D2PAK | F14: 1.5 A | G14: LCSC C91673 | H14: Extended | I14: U804 | J14: 1 | K14: 0 | L14: 0.3133 | M14: Quote | O14: =($J14+$K14)*Cost!$B$7 -> 5 | P14: =$J14*Cost!$B$6 -> 100 | Q14: =$J14*$L14 -> 0.3133
A15: 12 | B15: LDO | C15: onsemi LM337BD2TR4G | D15: −12.0 V | E15: D2PAK | F15: 1.5 A | G15: LCSC C154567 | H15: Extended | I15: U803 | J15: 1 | K15: 0 | L15: 0.3693 | M15: Quote | O15: =($J15+$K15)*Cost!$B$7 -> 5 | P15: =$J15*Cost!$B$6 -> 100 | Q15: =$J15*$L15 -> 0.3693
... A20: 17 | B20: Op-amp | C20: TI OPA1612AIDR | D20: — | E20: SOIC-8 | F20: 1.1 nV/√Hz | G20: LCSC | H20: Extended | I20: U501 | J20: 1 | K20: 0 | L20: 0.8766 | M20: Quote | O20: =($J20+$K20)*Cost!$B$7 -> 5 | P20: =$J20*Cost!$B$6 -> 100 | Q20: =$J20*$L20 -> 0.8766
A21: 18 | B21: Op-amp | C21: TI OPA1622IDRCR | D21: — | E21: VSON-10 3 × 3 mm | F21: ±145/130 mA; thermal pad to V− | G21: LCSC C2876559 | H21: Extended | I21: U601–U604 | J21: 4 | K21: 0 | L21: 2.1108 | M21: Quote | N21: Yes | O21: =($J21+$K21)*Cost!$B$7 -> 20 | P21: =$J21*Cost!$B$6 -> 400 | Q21: =$J21*$L21 -> 8.4432
A22: 19 | B22: Oscillator | C22: Kyocera KC2520Z22.5792C1KX00 | D22: 22.5792 MHz | E22: 2.5 × 2.0 mm | F22: 1.71–3.63 V, ±20 ppm | G22: Digi-Key (JLCPCB global sourcing) | H22: Global sourcing | I22: X301 | J22: 1 | K22: 0 | L22: 0.873 | M22: Quote | N22: Yes | O22: =($J22+$K22)*Cost!$B$7 -> 5 | P22: =$J22*Cost!$B$6 -> 100 | Q22: =$J22*$L22 -> 0.873
A23: 20 | B23: Oscillator | C23: Kyocera KC2520Z24.5760C1KX00 | D23: 24.576 MHz | E23: 2.5 × 2.0 mm | F23: 1.71–3.63 V, ±20 ppm | G23: Digi-Key (JLCPCB global sourcing) | H23: Global sourcing | I23: X302 | J23: 1 | K23: 0 | L23: 0.883 | M23: Quote | N23: Yes | O23: =($J23+$K23)*Cost!$B$7 -> 5 | P23: =$J23*Cost!$B$6 -> 100 | Q23: =$J23*$L23 -> 0.883
A24: 21 | B24: QSPI boot flash | C24: Winbond W25Q32JWSSIQ TR | D24: 32 Mbit | E24: SOIC-8 208 mil | F24: 1.7–1.95 V | G24: LCSC C2456252 | H24: Extended | I24: U202 | J24: 1 | K24: 0 | L24: 1.1588 | M24: Quote | O24: =($J24+$K24)*Cost!$B$7 -> 5 | P24: =$J24*Cost!$B$6 -> 100 | Q24: =$J24*$L24 -> 1.1588
A25: 22 | B25: Relay | C25: Hongfa HFD4/12-SR | D25: — | E25: SMD 10 × 6.5 mm | F25: 1.028 kΩ coil, gold-plated AgNi | G25: LCSC C44212 | H25: Extended | I25: K701, K702 | J25: 2 | K25: 0 | L25: 1.2231 | M25: Quote | O25: =($J25+$K25)*Cost!$B$7 -> 10 | P25: =$J25*Cost!$B$6 -> 200 | Q25: =$J25*$L25 -> 2.4462
A26: 23 | B26: Slide switch | C26: G-Switch MS-22D28-G020 | D26: DPDT | E26: SMD | F26: — | G26: LCSC C963205 | H26: Extended | I26: SW601 | J26: 1 | K26: 0 | L26: 0.0958 | M26: Quote | O26: =($J26+$K26)*Cost!$B$7 -> 5 | P26: =$J26*Cost!$B$6 -> 100 | Q26: =$J26*$L26 -> 0.0958
A27: 24 | B27: TVS diode | C27: Littelfuse SMAJ18A | D27: SMAJ18A | E27: SMA | F27: 18 V standoff, 29.2 V clamp | G27: JLCPCB C148219 | H27: Extended | I27: D801 | J27: 1 | K27: 0 | L27: 0.12 | M27: Quote | O27: =($J27+$K27)*Cost!$B$7 -> 5 | P27: =$J27*Cost!$B$6 -> 100 | Q27: =$J27*$L27 -> 0.12
A28: 25 | B28: USB ESD array | C28: ST USBLC6-2SC6 | D28: — | E28: SOT-23-6 | F28: 2-line, 5.25 V | G28: LCSC C7519 | H28: Extended | I28: U101 | J28: 1 | K28: 0 | L28: 0.13 | M28: Quote | O28: =($J28+$K28)*Cost!$B$7 -> 5 | P28: =$J28*Cost!$B$6 -> 100 | Q28: =$J28*$L28 -> 0.13
A29: 26 | B29: USB PD sink controller | C29: WCH CH224A | D29: — | E29: ESSOP-10 | F29: PD 3.2 | G29: LCSC C42459160 | H29: Extended | I29: U801 | J29: 1 | K29: 0 | L29: 0.2727 | M29: Quote | O29: =($J29+$K29)*Cost!$B$7 -> 5 | P29: =$J29*Cost!$B$6 -> 100 | Q29: =$J29*$L29 -> 0.2727
A30: 27 | B30: USB audio processor | C30: XMOS XU316-1024-QF60A-C24 | D30: — | E30: QFN-60 7 × 7 mm, 0.4 mm | F30: xcore.ai, 16 cores | G30: Digi-Key (JLCPCB global sourcing) | H30: Global sourcing | I30: U201 | J30: 1 | K30: 0 | L30: 9.2059 | M30: Quote | N30: Yes | O30: =($J30+$K30)*Cost!$B$7 -> 5 | P30: =$J30*Cost!$B$6 -> 100 | Q30: =$J30*$L30 -> 9.2059
A31: 28 | B31: USB-C receptacle | C31: HRO TYPE-C-31-M-12 | D31: — | E31: SMD | F31: 20 V, 5 A | G31: LCSC C165948 | H31: Extended | I31: J101; J801 | J31: 2 | K31: 0 | L31: 0.129 | M31: Quote | O31: =($J31+$K31)*Cost!$B$7 -> 10 | P31: =$J31*Cost!$B$6 -> 200 | Q31: =$J31*$L31 -> 0.258
A32: 29 | B32: Capacitor | C32: Generic (match a JLCPCB Basic part) | D32: 1 µF | E32: 0402 | F32: 10 V X5R | G32: Assign | H32: Basic (likely) | I32: C108–C111; C217; C301; C405 | J32: 7 | K32: 0 | L32: 0.003 | M32: Estimate | O32: =($J32+$K32)*Cost!$B$7 -> 35 | P32: =$J32*Cost!$B$6 -> 700 | Q32: =$J32*$L32 -> 0.021
A33: 30 | B33: Capacitor | C33: Generic (match a JLCPCB Basic part) | D33: 10 nF | E33: 0402 | F33: 50 V X7R | G33: Assign | H33: Basic (likely) | I33: C822, C823 | J33: 2 | K33: 0 | L33: 0.0015 | M33: Estimate | O33: =($J33+$K33)*Cost!$B$7 -> 10 | P33: =$J33*Cost!$B$6 -> 200 | Q33: =$J33*$L33 -> 0.003
A34: 31 | B34: Capacitor | C34: Generic (match a JLCPCB Basic part) | D34: 100 nF | E34: 0402 | F34: 16 V X7R | G34: Assign | H34: Basic (likely) | I34: C107; C201–C208; C210–C213; C215, C216; C220; C302, C303; C401, C403, C406; C808 | J34: 22 | K34: 0 | L34: 0.0015 | M34: Estimate | O34: =($J34+$K34)*Cost!$B$7 -> 110 | P34: =$J34*Cost!$B$6 -> 2200 | Q34: =$J34*$L34 -> 0.033
A35: 32 | B35: Capacitor | C35: Generic (match a JLCPCB Basic part) | D35: 22 pF | E35: 0402 | F35: 50 V C0G | G35: Assign | H35: Basic (likely) | I35: C218, C219; C603, C604 | J35: 4 | K35: 0 | L35: 0.0015 | M35: Estimate | O35: =($J35+$K35)*Cost!$B$7 -> 20 | P35: =$J35*Cost!$B$6 -> 400 | Q35: =$J35*$L35 -> 0.006
A36: 33 | B36: Capacitor | C36: Generic (match a JLCPCB Basic part) | D36: 1 µF | E36: 0603 | F36: 25 V X7R | G36: Assign | H36: Basic (likely) | I36: C703–C706; C809 | J36: 5 | K36: 0 | L36: 0.005 | M36: Estimate | O36: =($J36+$K36)*Cost!$B$7 -> 25 | P36: =$J36*Cost!$B$6 -> 500 | Q36: =$J36*$L36 -> 0.025
A37: 34 | B37: Capacitor | C37: Generic (Extended part expected) | D37: 1 µF | E37: 0603 | F37: 50 V X7R | G37: Assign | H37: Extended | I37: C802 | J37: 1 | K37: 0 | L37: 0.008 | M37: Estimate | O37: =($J37+$K37)*Cost!$B$7 -> 5 | P37: =$J37*Cost!$B$6 -> 100 | Q37: =$J37*$L37 -> 0.008
A38: 35 | B38: Capacitor | C38: Generic (match a JLCPCB Basic part) | D38: 10 µF | E38: 0603 | F38: 10 V X5R | G38: Assign | H38: Basic (likely) | I38: C104; C209; C214; C402, C404 | J38: 5 | K38: 0 | L38: 0.006 | M38: Estimate | O38: =($J38+$K38)*Cost!$B$7 -> 25 | P38: =$J38*Cost!$B$6 -> 500 | Q38: =$J38*$L38 -> 0.03
A39: 36 | B39: Capacitor | C39: Generic (match a JLCPCB Basic part) | D39: 100 nF | E39: 0603 | F39: 50 V X7R | G39: Assign | H39: Basic (likely) | I39: C407, C409; C411, C413; C511, C512; C605–C612; C701, C702; C707, C708; C709; C807; C814 | J39: 21 | K39: 0 | L39: 0.0025 | M39: Estimate | O39: =($J39+$K39)*Cost!$B$7 -> 105 | P39: =$J39*Cost!$B$6 -> 2100 | Q39: =$J39*$L39 -> 0.0525
A40: 37 | B40: Capacitor | C40: Generic (Extended part expected) | D40: 2.2 nF | E40: 0603 | F40: 50 V C0G | G40: Assign | H40: Extended | I40: C501, C502 | J40: 2 | K40: 0 | L40: 0.004 | M40: Estimate | O40: =($J40+$K40)*Cost!$B$7 -> 10 | P40: =$J40*Cost!$B$6 -> 200 | Q40: =$J40*$L40 -> 0.008
A41: 38 | B41: Capacitor | C41: Generic (Extended part expected) | D41: 33 pF | E41: 0603 | F41: 50 V C0G | G41: Assign | H41: Extended | I41: C601, C602 | J41: 2 | K41: 0 | L41: 0.004 | M41: Estimate | O41: =($J41+$K41)*Cost!$B$7 -> 10 | P41: =$J41*Cost!$B$6 -> 200 | Q41: =$J41*$L41 -> 0.008
A42: 39 | B42: Capacitor | C42: Generic (match a JLCPCB Basic part) | D42: 4.7 nF | E42: 0603 | F42: 50 V X7R | G42: Assign | H42: Basic (likely) | I42: C101; C801 | J42: 2 | K42: 0 | L42: 0.002 | M42: Estimate | O42: =($J42+$K42)*Cost!$B$7 -> 10 | P42: =$J42*Cost!$B$6 -> 200 | Q42: =$J42*$L42 -> 0.004
... A87: 84 | B87: Schottky diode | C87: Generic (match a JLCPCB Basic part) | D87: BAT54 | E87: SOT-23 | F87: 30 V | G87: Assign | H87: Basic (likely) | I87: D705, D706 | J87: 2 | K87: 0 | L87: 0.006 | M87: Estimate | O87: =($J87+$K87)*Cost!$B$7 -> 10 | P87: =$J87*Cost!$B$6 -> 200 | Q87: =$J87*$L87 -> 0.012
B89: Total per board | J89: =SUM(J4:J87) -> 273 | K89: =SUM(K4:K87) -> 1 | O89: =SUM(O4:O87) -> 1370 | P89: =SUM(P4:P87) -> 27300 | Q89: =SUM(Q4:Q87) -> 40.6195
...

Sheet Cost
A1: Cost per board — production and prototype orders
A2: JLCPCB PCBA price list of 8 Sep 2026 · parts at the 100-board tier · blue on yellow = input · green = linked from the Parts list / Purchasing list · black = calculated
A4: Inputs | B4: Value | C4: Unit | G4: Note
A5: Exchange rate | B5: 31.7 | C5: NTD per US$ | G5: applies to every NTD figure
A6: Production boards | B6: 100 | C6: boards | G6: JLCPCB Standard PCBA order
A7: Prototype boards | B7: 5 | C7: boards | G7: JLCPCB Economic PCBA order
A8: Cost limit per production board | B8: 1500 | C8: NTD | G8: per board at the production quantity
A9: Through-hole joints per board | B9: 7 | C9: joints | G9: J901 4.4 mm jack, hand-soldered
A11: Board data (linked from the lists) | B11: Value | C11: Unit | G11: Source
A12: Parts cost per board (bare PCB excluded) | B12: =SUMIFS('[1]Parts list'!$P$4:$P$159,'[1]Parts list'!$B$4:$B$159,"<>PCB") -> 40.6195 | C12: US$ | G12: Parts list: Ext. per board, all lines except the PCB row
A13: Bare 4-layer PCB per board (estimate) | B13: =SUMIFS('[1]Parts list'!$P$4:$P$159,'[1]Parts list'!$B$4:$B$159,"PCB") -> 0.8 | C13: US$ | G13: Parts list: PCB row
A14: Placed parts per production board | B14: =SUMIFS('[1]Parts list'!$C$4:$C$159,'[1]Parts list'!$K$4:$K$159,"Yes",'[1]Parts list'!$B$4:$B$159,"<>PCB") -> 273 | C14: parts | G14: Parts list: Qty per board where Fit = Yes, excluding the PCB row
A15: Placed parts per prototype board | B15: =B14+SUMIFS('[1]Parts list'!$C$4:$C$159,'[1]Parts list'!$K$4:$K$159,"Prototypes only") -> 274 | C15: parts | G15: adds Fit = Prototypes only (J201 JTAG header)
A16: SMT part types, production boards | B16: =COUNTIFS('Purchasing list'!$J$4:$J$87,">0",'Purchasing list'!$E$4:$E$87,"<>Through-hole") -> 82 | C16: types | G16: Purchasing list: fitted on production boards, excluding the through-hole 4.4 mm jack
A17: Extended SMT part types, prototype boards | B17: =COUNTIFS('Purchasing list'!$E$4:$E$87,"<>Through-hole",'Purchasing list'!$H$4:$H$87,"<>Basic",'Purchasing list'!$H$4:$H$87,"<>Basic (likely)") -> 47 | C17: types | G17: Purchasing list: library type other than Basic / Basic (likely), excluding the through-hole jack
A18: SMT joints per production board | B18: {=SUMPRODUCT(('[1]Parts list'!$K$4:$K$159="Yes")*'[1]Parts list'!$C$4:$C$159*'[1]Parts list'!$M$4:$M$159)} -> 826 | C18: joints | G18: Parts list: Qty × SMT joints per part where Fit = Yes
A19: SMT joints per prototype board | B19: {=B18+SUMPRODUCT(('[1]Parts list'!$K$4:$K$159="Prototypes only")*'[1]Parts list'!$C$4:$C$159*'[1]Parts list'!$M$4:$M$159)} -> 836 | C19: joints | G19: adds the J201 JTAG header
A20: Leadless parts per board (X-ray) | B20: =SUMIFS('[1]Parts list'!$C$4:$C$159,'[1]Parts list'!$K$4:$K$159,"Yes",'[1]Parts list'!$L$4:$L$159,"Yes") -> 7 | C20: parts | G20: Parts list: Leadless (X-ray) = Yes
A21: Generic passives and small discretes per board | B21: =SUMIFS('[1]Parts list'!$P$4:$P$159,'[1]Parts list'!$O$4:$O$159,"Estimate",'[1]Parts list'!$B$4:$B$159,"<>PCB")*$B$5 -> 66.39565 | C21: NTD | G21: Parts list: Price basis = Estimate, excluding the PCB row
A22: Check: Purchasing list Ext. total − parts cost | B22: =ROUND('Purchasing list'!$Q$89-B12,2) -> 0 | C22: US$ | G22: should be 0
A23: Check: Purchasing list quantity − placed parts | B23: ='Purchasing list'!$J$89-B14 -> 0 | C23: parts | G23: should be 0
A25: ="Production — "&TEXT($B$6,"#,##0")&" boards, JLCPCB Standard PCBA (price list of 8 Sep 2026)" -> Production — 100 boards, JLCPCB Standard PCBA (price list of 8 Sep 2026)
A26: PCBA fee (per order) | B26: Quantity | C26: Rate US$ | D26: Fixed US$ | E26: US$ | F26: NTD | G26: Basis
A27: Setup (single side) | D27: 25.56 | E27: =B27*C27+D27 -> 25.56 | F27: =E27*$B$5 -> 810.252 | G27: fixed fee per order
A28: Stencil | D28: 8.21 | E28: =B28*C28+D28 -> 8.21 | F28: =E28*$B$5 -> 260.257 | G28: fixed fee per order
A29: Fixtures (100–199 boards) | D29: 41.04 | E29: =B29*C29+D29 -> 41.04 | F29: =E29*$B$5 -> 1300.968 | G29: fixed fee, 100–199-board tier
A30: Feeder loading (part types) | B30: =B16 -> 82 | C30: 1.53 | E30: =B30*C30+D30 -> 125.46 | F30: =E30*$B$5 -> 3977.082 | G30: =TEXT(B30,"0")&" distinct SMT part numbers on production boards (the 4.4 mm jack is through-hole; the JTAG header is prototype-only)" -> 82 distinct SMT part numbers on production boards (the 4.4 mm jack is through-hole; the JTAG header is prototype-only)
A31: SMT joints | B31: =B18*$B$6 -> 82600 | C31: 0.0016 | E31: =B31*C31+D31 -> 132.16 | F31: =E31*$B$5 -> 4189.472 | G31: =TEXT(B18,"#,##0")&" joints per board × "&TEXT($B$6,"#,##0")&" boards" -> 826 joints per board × 100 boards
A32: X-ray (leadless parts) | B32: =B20*$B$6 -> 700 | C32: 0.25 | E32: =B32*C32+D32 -> 175 | F32: =E32*$B$5 -> 5547.5 | G32: =TEXT(B20,"0")&" leadless parts per board × "&TEXT($B$6,"#,##0")&" boards; 501–1,000-part tier" -> 7 leadless parts per board × 100 boards; 501–1,000-part tier
A33: Through-hole joints | B33: =$B$9*$B$6 -> 700 | C33: 0.0164 | D33: 3.58 | E33: =B33*C33+D33 -> 15.06 | F33: =E33*$B$5 -> 477.402 | G33: =TEXT($B$9,"0")&" joints per board × "&TEXT($B$6,"#,##0")&" boards, plus a fixed fee per order" -> 7 joints per board × 100 boards, plus a fixed fee per order
A34: Confirm Parts Placement | D34: 0.45 | E34: =B34*C34+D34 -> 0.45 | F34: =E34*$B$5 -> 14.265 | G34: fixed fee per order
A35: PCBA fees, total per order | E35: =SUM(E27:E34) -> 522.94 | F35: =E35*$B$5 -> 16577.198
A36: PCBA fees per board | E36: =E35/$B$6 -> 5.2294 | F36: =E36*$B$5 -> 165.77198 | G36: ="order total ÷ "&TEXT($B$6,"#,##0")&" boards" -> order total ÷ 100 boards
A38: Cost per production board | E38: US$ | F38: NTD | G38: Basis
A39: Parts | E39: =B12 -> 40.6195 | F39: =E39*$B$5 -> 1287.6381 | G39: Parts list at the 100-board tier (Quote / Estimate)
A40: Bare 4-layer PCB (estimate) | E40: =B13 -> 0.8 | F40: =E40*$B$5 -> 25.36 | G40: Parts list: PCB row
A41: PCBA fees | E41: =E36 -> 5.2294 | F41: =E41*$B$5 -> 165.77198 | G41: JLCPCB Standard PCBA fees spread over the order
A42: Total per board | E42: =SUM(E39:E41) -> 46.6489 | F42: =E42*$B$5 -> 1478.7701 | G42: ="at "&TEXT($B$6,"#,##0")&" boards" -> at 100 boards
A43: Limit per board | F43: =$B$8 -> 1500 | G43: input above
A44: Margin to the limit | F44: =F43-F42 -> 21.22987 | G44: =IF(F44>=0,"within the limit","over the limit") -> within the limit
...

Sheet Notes & open items
A1: Notes & open items
A2: Parts List v0.1 (draft) · companion to Schematic Design Notes v0.2 and Design Specification v0.3
A4: About this list
A5: 1 | B5: Covers every part on the board for Schematic Design Notes v0.2 / Design Specification v0.3: 273 placed parts per production board (274 on prototypes with the JTAG header), 84 distinct part numbers, plus do-not-fit (DNF) footprints and copper-only features.
A6: 2 | B6: Designators are grouped by block (1xx USB data port and digital power … 9xx outputs, indicators and test); KiCad will re-annotate.
A7: 3 | B7: Generic passives get part numbers at the KiCad BOM step, preferring JLCPCB Basic parts; "Basic (likely)" is an expectation to confirm, not a checked listing.
A8: 4 | B8: Values marked "starting value" follow the Schematic Design Notes and must be confirmed in SPICE or the datasheets before layout.
A10: Fit status
A11: 1 | B11: DNF footprints: C105 (0V9 feed-forward); R627–R634 (paralleling Option 2 links); R635–R638 and C623–C626 (output Zobel); U605 + RC (DC servo per channel, values to be sized); C810 (LMR33630 feed-forward); R807 (LMR33630 UVLO divider); J903 (I²S input header, hand-fitted for tests).
A12: 2 | B12: Prototypes only: J201 xSYS2 JTAG header; production boards use the TC2030 pads.
A13: 3 | B13: Copper only (no part): 29 test pads (12 rails, 13 signals, 4 GND), the TC2030 debug footprint, 4 mounting holes and 3 fiducials.
A14: 4 | B14: Paralleling Option 2 also needs a duplicate gain network per leg and a 4-pole gain switch; neither is in this list.
A16: Design details added in this list (beyond the Schematic Design Notes)
A17: 1 | B17: 10 Ω feeds for the AK4493 TVDD and AVDD keep their 10 µF off the LP5907 outputs (≤ 15 mV drop).
A18: 2 | B18: Ferrite + capacitor filters at the LMR33630 input and on the −14.7 V rail before the LM337.
A19: 3 | B19: LM317 / LM337 set with 240 Ω / 2.05 kΩ (±12.0 V), with 10 µF ADJ bypass and protection diodes.
A20: 4 | B20: Boot-flash CS_N pull-up (the XMOS boot timing shows an external pull-up); 22 Ω series resistors on QSPI SCLK, I²S and MCLK.
A21: 5 | B21: Status LEDs switched by MMBT3904 transistors from VBUS_DATA, because the XU316 I/O is 1.8 V only.
A22: 6 | B22: PD-loss hysteresis: 2.2 MΩ from FAULT_N (≈ 80 mV at the comparator, ≈ 0.6 V at VBUS_PD); threshold dividers 100 kΩ / 5.1 kΩ from ±12 V (±0.58 V).
A23: 7 | B23: Data-port VBUS capacitance kept to 2 × 4.7 µF, inside the 1–10 µF USB requirement quoted in the XU316 datasheet.
A25: Open items (close before layout)
A26: 1 | B26: LP5907 output capacitance: 1V8_D carries ≈ 11.6 µF nominal because the XU316 needs ≥ 10 µF VDDIO bulk; confirm whether the LP5907 has an output-capacitance limit, or move 1V8_D to an LDO without one.
A27: 2 | B27: USB PD sink capacitance: ≈ 130 µF sits on VBUS_PD (C803 100 µF for hot-plug damping plus ceramics), while USB Type-C/PD limits the bulk capacitance a sink presents at attach to 10 µF; decide between this and a PG-controlled load switch.
A28: 3 | B28: AMS1117-3.3 headroom: ≈ 1.1 V dropout against 5 V − 3.3 V; check at the lowest expected VBUS.
A29: 4 | B29: KC2520Z standby pin: confirm the logic level (R301/R302 pull-downs assume low = standby) and a high-impedance output in standby.
A30: 5 | B30: LMR33630 in the inverting configuration: feedback reference, feed-forward capacitor, UVLO and EN rating (TI SNVA856 / WEBENCH).
A31: 6 | B31: CH224A: VHV/VBUS wiring, CC pins and PG polarity per the WCH reference design.
A32: 7 | B32: JLCPCB: confirm that global-sourced parts (XU316, AK4493SEQ, oscillators) and the through-hole 4.4 mm jack are accepted for Economic PCBA prototypes, and how exposed-pad SOIC parts are treated for X-ray.
A33: 8 | B33: Consolidation: 82 part types cost ≈ US$125 in feeder fees at 100 boards, and 47 Extended types ≈ US$144 on the prototype order; merging values (e.g., 0.1% 10 kΩ bias resistors to 1%, E96 values to Basic values) cuts both.
